Workbook
Name SegmentaçãodeDados_Categoria: #N/A
Name SegmentaçãodeDados_Categoria1: #N/A
Name SegmentaçãodeDados_Fornecedor: #N/A
Name SegmentaçãodeDados_Mês_Falta: #N/A
Name SegmentaçãodeDados_Unidade: #N/A
Name SegmentaçãodeDados_Unidade1: #N/A

Sheet Planilha1
A1: Mês de referência para faturamento | B1: 45689
A3: Contagem de Contrato | B3: Rótulos de Coluna
A4: Rótulos de Linha | B4: Verzani | C4: Total Geral
A5: Campo Limpo | B5: 5 | C5: 5
A6: Limpeza | B6: 1 | C6: 1
A7: Manutenção | B7: 1 | C7: 1
A8: PMOC | B8: 1 | C8: 1
A9: Portaria | B9: 1 | C9: 1
A10: Vigilância | B10: 1 | C10: 1
A11: Shopping Parque Dom Pedro | B11: 6 | C11: 6
A12: Limpeza | B12: 1 | C12: 1
A13: Manutenção | B13: 1 | C13: 1
A14: PMOC | B14: 1 | C14: 1
A15: Portaria | B15: 1 | C15: 1
A16: Vigilância | B16: 1 | C16: 1
... A20: Total Geral | B20: 12 | C20: 12

Sheet Planilha2

Sheet Planilha4

Sheet Planilha5
A4: Soma de Desconto SLA Mês
A5: -291042.2

Sheet tabShoppingsEmails
A1: Shopping | B1: E-mails consolidados | C1: E-mails teste
A2: Amazonas Shopping | B2: andrezza.gaona@allos.co; karen.lima@allos.co; larissa.enes@allos.co; roberto.filho@allos.co; gregori.saavedra@allos.co; pedro.mendes@allos.co
A3: Shopping da Bahia | B3: leidiane.santos@allos.co; antonio.carvalho@allos.co; jose.azevedo@allos.co; jose.fortes@allos.co; mauricio.cerqueira@allos.co; joeval.souza@allos.co; adolfo.klein@allos.co; adson.santos@allos.co; gilson.souza@allos.co
A4: Bangu Shopping | B4: alex.costa@allos.co; victor.fortunato@allos.co; valeria.grajauskas@allos.co; nathally.santos@allos.co; paulo.assis@allos.co; michele.ramos@allos.co; teste@allos.co
A5: Boulevard Bauru | B5: kelly.bezerrra@boulevardshoppingbauru.com.br; yumi.leite@boulevardshoppingbauru.com.br; murillo.rosa@boulevardshoppingbauru.com.br; fabio.correa@boulevardshoppingbauru.com.br; higor.carneiro@boulevardshoppingbauru.com.br
A6: Boulevard Belém | B6: yugnarley.cintra@allos.co; jose.alfaia@allos.co; joelma.muniz@allos.co; jaqueline.silva@allos.co; alan.rodriguez@allos.co; favacho.junior@allos.co; ana.deoliveira@allos.co
A7: Boulevard BH | B7: carla.costa@allos.co; carla.mairinck@allos.co; davidson.pelolungo@allos.co; mariana.almeida@allos.co; denilson.sanches@allos.co; cassio.costa@allos.co; maressa.oliveira@allos.co
A8: Shopping Campo Grande | B8: wilson.lobo@allos.co; murillo.meyer@allos.co; alexandre.ramos@allos.co; ludimila.machado@allos.co
A9: Shopping Campo Limpo | B9: vania.assis@allos.co; gabriela.queiroz@allos.co; camila.pontes@allos.co; fabio.gurjao@allos.co; silvia.machado@allos.co; ricardo.santos@allos.co; fabio.correa@allos.co
A10: Carioca Shopping | B10: david.souza@allos.co; bruna.wanzeler@allos.co; priscilla.souza@allos.co; julio.spinelli@allos.co; andressa.vieira@allos.co; gd_geop.cariocashopping@allos.co; alessandro.gomes@allos.co
A11: Cariri Shopping | B11: rafaela.portilho@caririshopping.com.br; brenda.brito@caririshopping.com.br; vitoria.silva@caririshopping.com.br; emilly.santos@caririshopping.com.br; ana.andrade@caririshopping.com.br; jesualdo.farias@caririshopping.com.br
A12: Catuaí Shopping Londrina | B12: willian.elsner@allos.co; erminia.wada@allos.co; everton.stock@allos.co; giovani.junior@allos.co; tienne.rezende@allos.co
A13: Catuaí Shopping Maringá | B13: sandra.sakamoto@allos.co; marcelo.mizuta@allos.co; emerson.junior@allos.co; daniela.aldrovande@allos.co; lindomar.freitas@allos.co; jonas.godeny@allos.co elaine.oliveira@allos.co
... A50: Shopping Villa Lobos | B50: renan.mattos@allos.co; rita.silva@allos.co; kathleen.hoveler@allos.co; wellington.novaes@allos.co;alberto.oliveira@allos.co

Sheet Faturamento SP2
A1: Data de Envio | B1: Enviou/Retornou a Medição? | C1: Unidade | D1: Categoria | E1: Fornecedor | F1: HC Organograma | G1: HC Planilha | H1: Dias Faltas | I1: Horas Atrasos | J1: Valor Planilha | K1: Desconto de faltas solicitado pelo fornecedor | L1: Desconto Falta Validado Atlas | M1: Desconto de atrasos solicitado pelo fornecedor | N1: Desconto Atrasos Validado Atlas | O1: Desconto SLA Mês | P1: Desconto SLA Retroativo | Q1: Desconto Equipamentos | R1: Prêmio Assiduidade | S1: Outros descontos | T1: Vai descontar SLA? | U1: Valor mensal final | V1: Taxa de prorrogação do prazo pagamento | W1: Valor mensal com prorrogação do prazo pagamento | X1: Retroativo de dissídio | Y1: Parcela (x/x) | Z1: Mês de referência para faturamento | AA1: Mês de emissão da NF | AB1: Extras Solicitado pelo fornecedor | AC1: Valor extras validado Atlas | AD1: Valor NF Extra | AE1: NF enviada sistema? | AF1: Valor NF | AG1: NF ok? | AH1: SEFIP Enviada Sistema? | AI1: Saving Faltas | AJ1: Saving Extras | AK1: Deduções Totais | AL1: Observações | AM1: E-mail
B2: Sim | C2: Shopping Villagio Caxias | D2: Limpeza | E2: GPS | F2: 25 | G2: 30 | H2: 169 | I2: 0 | J2: =209575.27 -> 209575.27 | K2: 0 | L2: -32713.7 | M2: 0 | N2: 0 | O2: -2095.75 | P2: 0 | Q2: 0 | R2: =208154.6-J2 -> -1420.67 | S2: 0 | T2: Sim | U2: =(J2+L2+Q2+R2+S2+N2)+IF(T2="Sim",O2+P2,0) -> 173345.15 | W2: =IF(J2="","",U2*(1+V2)) -> 173345.15 | Z2: 45658 | AA2: {=IFERROR( IF( _xlfn.XLOOKUP( 1, ( ('Condição de Faturamento'!$A$2:$A$1000 = Tabela1[[#This Row],[Unidade]]) * ('Condição de Faturamento'!$B$2:$B$1000 = Tabela1[[#This Row],[Categoria]]) * ('Condição de Faturamento'!$C$2:$C$1000 = Tabela1[[#This Row],[Fornecedor]]) ), 'Condição de Faturamento'!$D$2:$D$1000 ) = "Emissão no mês da prestação do serviço", Tabela1[[#This Row],[Mês de referência para faturamento]], DATE( YEAR(Tabela1[[#This Row],[Mês de referência para faturamento]]), MONTH(Tabela1[[#This Row],[Mês de referência para faturamento]]) + 1, DAY(Tabela1[[#This Row],[Mês de referência para faturamento]]) ) ), DATE( YEAR(Tabela1[[#This Row],[Mês de referência para faturamento]]), MONTH(Tabela1[[#This Row],[Mês de referência para faturamento]]) + 1, DAY(Tabela1[[#This Row],[Mês de referência para faturamento]]) ) )} -> 45689 | AI2: =K2-L2 -> 32713.7 | AJ2: =AB2-AC2 -> 0 | AK2: =J2-U2 -> 36230.12 | AM2: =_xlfn.XLOOKUP(Tabela1[[#This Row],[Unidade]],tabShoppingsEmails[Shopping],tabShoppingsEmails[E-mails consolidados]) -> patricia.benvenuti@allos.co; ludmila.fachin@allos.co; emerson.silveira@allos.co; bruna.zanella@allos.co; wallace.nascimento@allos.co; juliana.slomp@allos.co
B3: Sim | C3: Shopping Villagio Caxias | D3: Limpeza | E3: GPS | F3: 25 | G3: 30 | H3: 128 | I3: 0 | J3: =209575.27 -> 209575.27 | K3: 0 | L3: -25078.52 | M3: 0 | N3: 0 | O3: -2095.75 | P3: 0 | Q3: 0 | R3: =208509.76-J3 -> -1065.51 | S3: 0 | T3: Sim | U3: =(J3+L3+Q3+R3+S3+N3)+IF(T3="Sim",O3+P3,0) -> 181335.49 | W3: =IF(J3="","",U3*(1+V3)) -> 181335.49 | Z3: 45689 | AA3: {=IFERROR( IF( _xlfn.XLOOKUP( 1, ( ('Condição de Faturamento'!$A$2:$A$1000 = Tabela1[[#This Row],[Unidade]]) * ('Condição de Faturamento'!$B$2:$B$1000 = Tabela1[[#This Row],[Categoria]]) * ('Condição de Faturamento'!$C$2:$C$1000 = Tabela1[[#This Row],[Fornecedor]]) ), 'Condição de Faturamento'!$D$2:$D$1000 ) = "Emissão no mês da prestação do serviço", Tabela1[[#This Row],[Mês de referência para faturamento]], DATE( YEAR(Tabela1[[#This Row],[Mês de referência para faturamento]]), MONTH(Tabela1[[#This Row],[Mês de referência para faturamento]]) + 1, DAY(Tabela1[[#This Row],[Mês de referência para faturamento]]) ) ), DATE( YEAR(Tabela1[[#This Row],[Mês de referência para faturamento]]), MONTH(Tabela1[[#This Row],[Mês de referência para faturamento]]) + 1, DAY(Tabela1[[#This Row],[Mês de referência para faturamento]]) ) )} -> 45717 | AI3: =K3-L3 -> 25078.52 | AJ3: =AB3-AC3 -> 0 | AK3: =J3-U3 -> 28239.78 | AM3: =_xlfn.XLOOKUP(Tabela1[[#This Row],[Unidade]],tabShoppingsEmails[Shopping],tabShoppingsEmails[E-mails consolidados]) -> patricia.benvenuti@allos.co; ludmila.fachin@allos.co; emerson.silveira@allos.co; bruna.zanella@allos.co; wallace.nascimento@allos.co; juliana.slomp@allos.co
B4: Sim | C4: Shopping Villagio Caxias | D4: Limpeza | E4: GPS | F4: 25 | G4: 30 | H4: 68 | I4: 0 | J4: 222827.16 | K4: 0 | L4: -15434.14 | M4: 0 | N4: 0 | O4: -2599.65 | P4: 0 | Q4: 0 | R4: =221288.13-J4 -> -1539.03 | S4: 0 | T4: Sim | U4: =(J4+L4+Q4+R4+S4+N4)+IF(T4="Sim",O4+P4,0) -> 203254.34 | W4: =IF(J4="","",U4*(1+V4)) -> 203254.34 | X4: 22427.211 | Y4: 1.1 | Z4: 45717 | AA4: {=IFERROR( IF( _xlfn.XLOOKUP( 1, ( ('Condição de Faturamento'!$A$2:$A$1000 = Tabela1[[#This Row],[Unidade]]) * ('Condição de Faturamento'!$B$2:$B$1000 = Tabela1[[#This Row],[Categoria]]) * ('Condição de Faturamento'!$C$2:$C$1000 = Tabela1[[#This Row],[Fornecedor]]) ), 'Condição de Faturamento'!$D$2:$D$1000 ) = "Emissão no mês da prestação do serviço", Tabela1[[#This Row],[Mês de referência para faturamento]], DATE( YEAR(Tabela1[[#This Row],[Mês de referência para faturamento]]), MONTH(Tabela1[[#This Row],[Mês de referência para faturamento]]) + 1, DAY(Tabela1[[#This Row],[Mês de referência para faturamento]]) ) ), DATE( YEAR(Tabela1[[#This Row],[Mês de referência para faturamento]]), MONTH(Tabela1[[#This Row],[Mês de referência para faturamento]]) + 1, DAY(Tabela1[[#This Row],[Mês de referência para faturamento]]) ) )} -> 45748 | AB4: 4131.1831 | AC4: 4131.1831 | AI4: =K4-L4 -> 15434.14 | AJ4: =AB4-AC4 -> 0 | AK4: =J4-U4 -> 19572.82 | AM4: =_xlfn.XLOOKUP(Tabela1[[#This Row],[Unidade]],tabShoppingsEmails[Shopping],tabShoppingsEmails[E-mails consolidados]) -> patricia.benvenuti@allos.co; ludmila.fachin@allos.co; emerson.silveira@allos.co; bruna.zanella@allos.co; wallace.nascimento@allos.co; juliana.slomp@allos.co
B5: Sim | C5: Shopping Villagio Caxias | D5: Limpeza | E5: GPS | F5: 25 | G5: 30 | H5: 66 | I5: 0 | J5: 222827.16 | K5: 0 | L5: -14428.83 | M5: 0 | N5: 0 | O5: -2971.03 | P5: 0 | Q5: 0 | R5: =222353.61-J5 -> -473.55 | S5: 0 | T5: Sim | U5: =(J5+L5+Q5+R5+S5+N5)+IF(T5="Sim",O5+P5,0) -> 204953.75 | W5: =IF(J5="","",U5*(1+V5)) -> 204953.75 | Z5: 45748 | AA5: {=IFERROR( IF( _xlfn.XLOOKUP( 1, ( ('Condição de Faturamento'!$A$2:$A$1000 = Tabela1[[#This Row],[Unidade]]) * ('Condição de Faturamento'!$B$2:$B$1000 = Tabela1[[#This Row],[Categoria]]) * ('Condição de Faturamento'!$C$2:$C$1000 = Tabela1[[#This Row],[Fornecedor]]) ), 'Condição de Faturamento'!$D$2:$D$1000 ) = "Emissão no mês da prestação do serviço", Tabela1[[#This Row],[Mês de referência para faturamento]], DATE( YEAR(Tabela1[[#This Row],[Mês de referência para faturamento]]), MONTH(Tabela1[[#This Row],[Mês de referência para faturamento]]) + 1, DAY(Tabela1[[#This Row],[Mês de referência para faturamento]]) ) ), DATE( YEAR(Tabela1[[#This Row],[Mês de referência para faturamento]]), MONTH(Tabela1[[#This Row],[Mês de referência para faturamento]]) + 1, DAY(Tabela1[[#This Row],[Mês de referência para faturamento]]) ) )} -> 45778 | AB5: 7190.6889 | AC5: 7190.6889 | AI5: =K5-L5 -> 14428.83 | AJ5: =AB5-AC5 -> 0 | AK5: =J5-U5 -> 17873.41 | AM5: =_xlfn.XLOOKUP(Tabela1[[#This Row],[Unidade]],tabShoppingsEmails[Shopping],tabShoppingsEmails[E-mails consolidados]) -> patricia.benvenuti@allos.co; ludmila.fachin@allos.co; emerson.silveira@allos.co; bruna.zanella@allos.co; wallace.nascimento@allos.co; juliana.slomp@allos.co
A6: 45817 | B6: Sim | C6: Shopping Villagio Caxias | D6: Limpeza | E6: GPS | F6: 25 | G6: 30 | H6: 94 | I6: 0 | J6: 222827.16 | K6: 0 | L6: -20485.66 | M6: 0 | N6: 0 | O6: -2971.03 | P6: 0 | Q6: 0 | R6: =221880.06-Tabela1[[#This Row],[Valor Planilha]] -> -947.1 | S6: -3278.08 | T6: Sim | U6: =(J6+L6+Q6+R6+S6+N6)+IF(T6="Sim",O6+P6,0) -> 195145.29 | W6: =IF(J6="","",U6*(1+V6)) -> 195145.29 | Z6: 45778 | AA6: {=IFERROR( IF( _xlfn.XLOOKUP( 1, ( ('Condição de Faturamento'!$A$2:$A$1000 = Tabela1[[#This Row],[Unidade]]) * ('Condição de Faturamento'!$B$2:$B$1000 = Tabela1[[#This Row],[Categoria]]) * ('Condição de Faturamento'!$C$2:$C$1000 = Tabela1[[#This Row],[Fornecedor]]) ), 'Condição de Faturamento'!$D$2:$D$1000 ) = "Emissão no mês da prestação do serviço", Tabela1[[#This Row],[Mês de referência para faturamento]], DATE( YEAR(Tabela1[[#This Row],[Mês de referência para faturamento]]), MONTH(Tabela1[[#This Row],[Mês de referência para faturamento]]) + 1, DAY(Tabela1[[#This Row],[Mês de referência para faturamento]]) ) ), DATE( YEAR(Tabela1[[#This Row],[Mês de referência para faturamento]]), MONTH(Tabela1[[#This Row],[Mês de referência para faturamento]]) + 1, DAY(Tabela1[[#This Row],[Mês de referência para faturamento]]) ) )} -> 45809 | AB6: 6243.8189 | AC6: 6243.8189 | AI6: =K6-L6 -> 20485.66 | AJ6: =AB6-AC6 -> 0 | AK6: =J6-U6 -> 27681.87 | AM6: =_xlfn.XLOOKUP(Tabela1[[#This Row],[Unidade]],tabShoppingsEmails[Shopping],tabShoppingsEmails[E-mails consolidados]) -> patricia.benvenuti@allos.co; ludmila.fachin@allos.co; emerson.silveira@allos.co; bruna.zanella@allos.co; wallace.nascimento@allos.co; juliana.slomp@allos.co
A7: 45842 | B7: Sim | C7: Shopping Villagio Caxias | D7: Limpeza | E7: GPS | F7: 25 | G7: 30 | H7: 63 | I7: 0 | J7: 222827.16 | K7: 0 | L7: -13312.08 | M7: 0 | N7: 0 | O7: -2228.27 | P7: 0 | Q7: 0 | R7: =222116.84-Tabela1[[#This Row],[Valor Planilha]] -> -710.32 | S7: 0 | T7: Sim | U7: =(J7+L7+Q7+R7+S7+N7)+IF(T7="Sim",O7+P7,0) -> 206576.49 | W7: =IF(J7="","",U7*(1+V7)) -> 206576.49 | Z7: 45809 | AA7: {=IFERROR( IF( _xlfn.XLOOKUP( 1, ( ('Condição de Faturamento'!$A$2:$A$1000 = Tabela1[[#This Row],[Unidade]]) * ('Condição de Faturamento'!$B$2:$B$1000 = Tabela1[[#This Row],[Categoria]]) * ('Condição de Faturamento'!$C$2:$C$1000 = Tabela1[[#This Row],[Fornecedor]]) ), 'Condição de Faturamento'!$D$2:$D$1000 ) = "Emissão no mês da prestação do serviço", Tabela1[[#This Row],[Mês de referência para faturamento]], DATE( YEAR(Tabela1[[#This Row],[Mês de referência para faturamento]]), MONTH(Tabela1[[#This Row],[Mês de referência para faturamento]]) + 1, DAY(Tabela1[[#This Row],[Mês de referência para faturamento]]) ) ), DATE( YEAR(Tabela1[[#This Row],[Mês de referência para faturamento]]), MONTH(Tabela1[[#This Row],[Mês de referência para faturamento]]) + 1, DAY(Tabela1[[#This Row],[Mês de referência para faturamento]]) ) )} -> 45839 | AB7: 3165.6615 | AC7: 3165.6615 | AI7: =K7-L7 -> 13312.08 | AJ7: =AB7-AC7 -> 0 | AK7: =J7-U7 -> 16250.67 | AM7: =_xlfn.XLOOKUP(Tabela1[[#This Row],[Unidade]],tabShoppingsEmails[Shopping],tabShoppingsEmails[E-mails consolidados]) -> patricia.benvenuti@allos.co; ludmila.fachin@allos.co; emerson.silveira@allos.co; bruna.zanella@allos.co; wallace.nascimento@allos.co; juliana.slomp@allos.co
A8: 45874 | B8: Sim | C8: Shopping Villagio Caxias | D8: Limpeza | E8: GPS | F8: 25 | G8: 30 | H8: 74 | I8: 5.66 | J8: 222827.16 | K8: 0 | L8: -15515.18 | M8: 0 | N8: -199.3452 | O8: -2228.27 | P8: 0 | Q8: 0 | R8: =221288.13-Tabela1[[#This Row],[Valor Planilha]] -> -1539.03 | S8: 0 | T8: Sim | U8: =(J8+L8+Q8+R8+S8+N8)+IF(T8="Sim",O8+P8,0) -> 203345.33 | W8: =IF(J8="","",U8*(1+V8)) -> 203345.33 | Z8: 45839 | AA8: {=IFERROR( IF( _xlfn.XLOOKUP( 1, ( ('Condição de Faturamento'!$A$2:$A$1000 = Tabela1[[#This Row],[Unidade]]) * ('Condição de Faturamento'!$B$2:$B$1000 = Tabela1[[#This Row],[Categoria]]) * ('Condição de Faturamento'!$C$2:$C$1000 = Tabela1[[#This Row],[Fornecedor]]) ), 'Condição de Faturamento'!$D$2:$D$1000 ) = "Emissão no mês da prestação do serviço", Tabela1[[#This Row],[Mês de referência para faturamento]], DATE( YEAR(Tabela1[[#This Row],[Mês de referência para faturamento]]), MONTH(Tabela1[[#This Row],[Mês de referência para faturamento]]) + 1, DAY(Tabela1[[#This Row],[Mês de referência para faturamento]]) ) ), DATE( YEAR(Tabela1[[#This Row],[Mês de referência para faturamento]]), MONTH(Tabela1[[#This Row],[Mês de referência para faturamento]]) + 1, DAY(Tabela1[[#This Row],[Mês de referência para faturamento]]) ) )} -> 45870 | AB8: 3241.2739 | AC8: 3241.2739 | AI8: =K8-L8 -> 15515.18 | AJ8: =AB8-AC8 -> 0 | AK8: =J8-U8 -> 19481.825 | AM8: =_xlfn.XLOOKUP(Tabela1[[#This Row],[Unidade]],tabShoppingsEmails[Shopping],tabShoppingsEmails[E-mails consolidados]) -> patricia.benvenuti@allos.co; ludmila.fachin@allos.co; emerson.silveira@allos.co; bruna.zanella@allos.co; wallace.nascimento@allos.co; juliana.slomp@allos.co
A9: 45908 | B9: Sim | C9: Shopping Villagio Caxias | D9: Limpeza | E9: GPS | F9: 25 | G9: 30 | H9: 96 | I9: 0 | J9: 222827.16 | K9: 0 | L9: -19896.09 | M9: 0 | N9: 0 | O9: -2228.27 | P9: 0 | Q9: 0 | R9: =221761.66-Tabela1[[#This Row],[Valor Planilha]] -> -1065.5 | S9: 0 | T9: Sim | U9: =(J9+L9+Q9+R9+S9+N9)+IF(T9="Sim",O9+P9,0) -> 199637.3 | W9: =IF(J9="","",U9*(1+V9)) -> 199637.3 | Z9: 45870 | AA9: {=IFERROR( IF( _xlfn.XLOOKUP( 1, ( ('Condição de Faturamento'!$A$2:$A$1000 = Tabela1[[#This Row],[Unidade]]) * ('Condição de Faturamento'!$B$2:$B$1000 = Tabela1[[#This Row],[Categoria]]) * ('Condição de Faturamento'!$C$2:$C$1000 = Tabela1[[#This Row],[Fornecedor]]) ), 'Condição de Faturamento'!$D$2:$D$1000 ) = "Emissão no mês da prestação do serviço", Tabela1[[#This Row],[Mês de referência para faturamento]], DATE( YEAR(Tabela1[[#This Row],[Mês de referência para faturamento]]), MONTH(Tabela1[[#This Row],[Mês de referência para faturamento]]) + 1, DAY(Tabela1[[#This Row],[Mês de referência para faturamento]]) ) ), DATE( YEAR(Tabela1[[#This Row],[Mês de referência para faturamento]]), MONTH(Tabela1[[#This Row],[Mês de referência para faturamento]]) + 1, DAY(Tabela1[[#This Row],[Mês de referência para faturamento]]) ) )} -> 45901 | AB9: 2201.1872 | AC9: 2201.1872 | AI9: =K9-L9 -> 19896.09 | AJ9: =AB9-AC9 -> 0 | AK9: =J9-U9 -> 23189.86 | AM9: =_xlfn.XLOOKUP(Tabela1[[#This Row],[Unidade]],tabShoppingsEmails[Shopping],tabShoppingsEmails[E-mails consolidados]) -> patricia.benvenuti@allos.co; ludmila.fachin@allos.co; emerson.silveira@allos.co; bruna.zanella@allos.co; wallace.nascimento@allos.co; juliana.slomp@allos.co
A10: 45936 | B10: Sim | C10: Shopping Villagio Caxias | D10: Limpeza | E10: GPS | F10: 25 | G10: 30 | H10: 12 | I10: 3.33 | J10: 222827.16 | K10: 0 | L10: -2534.43 | M10: 0 | N10: -112.2126 | O10: -2599.65 | P10: 0 | Q10: 0 | R10: =221761.66-Tabela1[[#This Row],[Valor Planilha]] -> -1065.5 | S10: 0 | T10: Sim | U10: =(J10+L10+Q10+R10+S10+N10)+IF(T10="Sim",O10+P10,0) -> 216515.37 | W10: =IF(J10="","",U10*(1+V10)) -> 216515.37 | Z10: 45901 | AA10: {=IFERROR( IF( _xlfn.XLOOKUP( 1, ( ('Condição de Faturamento'!$A$2:$A$1000 = Tabela1[[#This Row],[Unidade]]) * ('Condição de Faturamento'!$B$2:$B$1000 = Tabela1[[#This Row],[Categoria]]) * ('Condição de Faturamento'!$C$2:$C$1000 = Tabela1[[#This Row],[Fornecedor]]) ), 'Condição de Faturamento'!$D$2:$D$1000 ) = "Emissão no mês da prestação do serviço", Tabela1[[#This Row],[Mês de referência para faturamento]], DATE( YEAR(Tabela1[[#This Row],[Mês de referência para faturamento]]), MONTH(Tabela1[[#This Row],[Mês de referência para faturamento]]) + 1, DAY(Tabela1[[#This Row],[Mês de referência para faturamento]]) ) ), DATE( YEAR(Tabela1[[#This Row],[Mês de referência para faturamento]]), MONTH(Tabela1[[#This Row],[Mês de referência para faturamento]]) + 1, DAY(Tabela1[[#This Row],[Mês de referência para faturamento]]) ) )} -> 45931 | AB10: 3300.189 | AC10: 3300.189 | AI10: =K10-L10 -> 2534.43 | AJ10: =AB10-AC10 -> 0 | AK10: =J10-U10 -> 6311.7926 | AM10: =_xlfn.XLOOKUP(Tabela1[[#This Row],[Unidade]],tabShoppingsEmails[Shopping],tabShoppingsEmails[E-mails consolidados]) -> patricia.benvenuti@allos.co; ludmila.fachin@allos.co; emerson.silveira@allos.co; bruna.zanella@allos.co; wallace.nascimento@allos.co; juliana.slomp@allos.co
C11: Shopping Villagio Caxias | D11: Limpeza | E11: GPS | F11: 25 | U11: =(J11+L11+Q11+R11+S11+N11)+IF(T11="Sim",O11+P11,0) -> 0 | W11: =IF(J11="","",U11*(1+V11)) | Z11: 45931 | AA11: {=IFERROR( IF( _xlfn.XLOOKUP( 1, ( ('Condição de Faturamento'!$A$2:$A$1000 = Tabela1[[#This Row],[Unidade]]) * ('Condição de Faturamento'!$B$2:$B$1000 = Tabela1[[#This Row],[Categoria]]) * ('Condição de Faturamento'!$C$2:$C$1000 = Tabela1[[#This Row],[Fornecedor]]) ), 'Condição de Faturamento'!$D$2:$D$1000 ) = "Emissão no mês da prestação do serviço", Tabela1[[#This Row],[Mês de referência para faturamento]], DATE( YEAR(Tabela1[[#This Row],[Mês de referência para faturamento]]), MONTH(Tabela1[[#This Row],[Mês de referência para faturamento]]) + 1, DAY(Tabela1[[#This Row],[Mês de referência para faturamento]]) ) ), DATE( YEAR(Tabela1[[#This Row],[Mês de referência para faturamento]]), MONTH(Tabela1[[#This Row],[Mês de referência para faturamento]]) + 1, DAY(Tabela1[[#This Row],[Mês de referência para faturamento]]) ) )} -> 45962 | AI11: =K11-L11 -> 0 | AJ11: =AB11-AC11 -> 0 | AK11: =J11-U11 -> 0 | AM11: =_xlfn.XLOOKUP(Tabela1[[#This Row],[Unidade]],tabShoppingsEmails[Shopping],tabShoppingsEmails[E-mails consolidados]) -> patricia.benvenuti@allos.co; ludmila.fachin@allos.co; emerson.silveira@allos.co; bruna.zanella@allos.co; wallace.nascimento@allos.co; juliana.slomp@allos.co
C12: Shopping Villagio Caxias | D12: Limpeza | E12: GPS | F12: 25 | U12: =(J12+L12+Q12+R12+S12+N12)+IF(T12="Sim",O12+P12,0) -> 0 | W12: =IF(J12="","",U12*(1+V12)) | Z12: 45962 | AA12: {=IFERROR( IF( _xlfn.XLOOKUP( 1, ( ('Condição de Faturamento'!$A$2:$A$1000 = Tabela1[[#This Row],[Unidade]]) * ('Condição de Faturamento'!$B$2:$B$1000 = Tabela1[[#This Row],[Categoria]]) * ('Condição de Faturamento'!$C$2:$C$1000 = Tabela1[[#This Row],[Fornecedor]]) ), 'Condição de Faturamento'!$D$2:$D$1000 ) = "Emissão no mês da prestação do serviço", Tabela1[[#This Row],[Mês de referência para faturamento]], DATE( YEAR(Tabela1[[#This Row],[Mês de referência para faturamento]]), MONTH(Tabela1[[#This Row],[Mês de referência para faturamento]]) + 1, DAY(Tabela1[[#This Row],[Mês de referência para faturamento]]) ) ), DATE( YEAR(Tabela1[[#This Row],[Mês de referência para faturamento]]), MONTH(Tabela1[[#This Row],[Mês de referência para faturamento]]) + 1, DAY(Tabela1[[#This Row],[Mês de referência para faturamento]]) ) )} -> 45992 | AI12: =K12-L12 -> 0 | AJ12: =AB12-AC12 -> 0 | AK12: =J12-U12 -> 0 | AM12: =_xlfn.XLOOKUP(Tabela1[[#This Row],[Unidade]],tabShoppingsEmails[Shopping],tabShoppingsEmails[E-mails consolidados]) -> patricia.benvenuti@allos.co; ludmila.fachin@allos.co; emerson.silveira@allos.co; bruna.zanella@allos.co; wallace.nascimento@allos.co; juliana.slomp@allos.co
C13: Shopping Villagio Caxias | D13: Limpeza | E13: GPS | F13: 25 | U13: =(J13+L13+Q13+R13+S13+N13)+IF(T13="Sim",O13+P13,0) -> 0 | W13: =IF(J13="","",U13*(1+V13)) | Z13: 45992 | AA13: {=IFERROR( IF( _xlfn.XLOOKUP( 1, ( ('Condição de Faturamento'!$A$2:$A$1000 = Tabela1[[#This Row],[Unidade]]) * ('Condição de Faturamento'!$B$2:$B$1000 = Tabela1[[#This Row],[Categoria]]) * ('Condição de Faturamento'!$C$2:$C$1000 = Tabela1[[#This Row],[Fornecedor]]) ), 'Condição de Faturamento'!$D$2:$D$1000 ) = "Emissão no mês da prestação do serviço", Tabela1[[#This Row],[Mês de referência para faturamento]], DATE( YEAR(Tabela1[[#This Row],[Mês de referência para faturamento]]), MONTH(Tabela1[[#This Row],[Mês de referência para faturamento]]) + 1, DAY(Tabela1[[#This Row],[Mês de referência para faturamento]]) ) ), DATE( YEAR(Tabela1[[#This Row],[Mês de referência para faturamento]]), MONTH(Tabela1[[#This Row],[Mês de referência para faturamento]]) + 1, DAY(Tabela1[[#This Row],[Mês de referência para faturamento]]) ) )} -> 46023 | AI13: =K13-L13 -> 0 | AJ13: =AB13-AC13 -> 0 | AK13: =J13-U13 -> 0 | AM13: =_xlfn.XLOOKUP(Tabela1[[#This Row],[Unidade]],tabShoppingsEmails[Shopping],tabShoppingsEmails[E-mails consolidados]) -> patricia.benvenuti@allos.co; ludmila.fachin@allos.co; emerson.silveira@allos.co; bruna.zanella@allos.co; wallace.nascimento@allos.co; juliana.slomp@allos.co
B14: Não | C14: Shopping Villagio Caxias | D14: Resíduos | E14: Recicla Engenharia | F14: 3 | G14: 3 | H14: infomação pendente | I14: infomação pendente | J14: 65000 | K14: 0 | M14: 0 | O14: preenchimento pendente | P14: 0 | Q14: 0 | R14: 0 | S14: 0 | U14: =(J14+L14+Q14+R14+S14+N14)+IF(T14="Sim",O14+P14,0) -> 65000 | W14: =IF(J14="","",U14*(1+V14)) -> 65000 | Z14: 45870 | AA14: {=IFERROR( IF( _xlfn.XLOOKUP( 1, ( ('Condição de Faturamento'!$A$2:$A$1000 = Tabela1[[#This Row],[Unidade]]) * ('Condição de Faturamento'!$B$2:$B$1000 = Tabela1[[#This Row],[Categoria]]) * ('Condição de Faturamento'!$C$2:$C$1000 = Tabela1[[#This Row],[Fornecedor]]) ), 'Condição de Faturamento'!$D$2:$D$1000 ) = "Emissão no mês da prestação do serviço", Tabela1[[#This Row],[Mês de referência para faturamento]], DATE( YEAR(Tabela1[[#This Row],[Mês de referência para faturamento]]), MONTH(Tabela1[[#This Row],[Mês de referência para faturamento]]) + 1, DAY(Tabela1[[#This Row],[Mês de referência para faturamento]]) ) ), DATE( YEAR(Tabela1[[#This Row],[Mês de referência para faturamento]]), MONTH(Tabela1[[#This Row],[Mês de referência para faturamento]]) + 1, DAY(Tabela1[[#This Row],[Mês de referência para faturamento]]) ) )} -> 45901 | AI14: =K14-L14 -> 0 | AJ14: =AB14-AC14 -> 0 | AK14: =J14-U14 -> 0 | AM14: =_xlfn.XLOOKUP(Tabela1[[#This Row],[Unidade]],tabShoppingsEmails[Shopping],tabShoppingsEmails[E-mails consolidados]) -> patricia.benvenuti@allos.co; ludmila.fachin@allos.co; emerson.silveira@allos.co; bruna.zanella@allos.co; wallace.nascimento@allos.co; juliana.slomp@allos.co
B15: Não | C15: Shopping Villagio Caxias | D15: Resíduos | E15: Recicla Engenharia | F15: 3 | G15: 3 | H15: infomação pendente | I15: infomação pendente | J15: 65000 | O15: preenchimento pendente | Q15: 0 | R15: 0 | S15: 0 | T15: Não | U15: =(J15+L15+Q15+R15+S15+N15)+IF(T15="Sim",O15+P15,0) -> 65000 | W15: =IF(J15="","",U15*(1+V15)) -> 65000 | Z15: 45901 | AA15: {=IFERROR( IF( _xlfn.XLOOKUP( 1, ( ('Condição de Faturamento'!$A$2:$A$1000 = Tabela1[[#This Row],[Unidade]]) * ('Condição de Faturamento'!$B$2:$B$1000 = Tabela1[[#This Row],[Categoria]]) * ('Condição de Faturamento'!$C$2:$C$1000 = Tabela1[[#This Row],[Fornecedor]]) ), 'Condição de Faturamento'!$D$2:$D$1000 ) = "Emissão no mês da prestação do serviço", Tabela1[[#This Row],[Mês de referência para faturamento]], DATE( YEAR(Tabela1[[#This Row],[Mês de referência para faturamento]]), MONTH(Tabela1[[#This Row],[Mês de referência para faturamento]]) + 1, DAY(Tabela1[[#This Row],[Mês de referência para faturamento]]) ) ), DATE( YEAR(Tabela1[[#This Row],[Mês de referência para faturamento]]), MONTH(Tabela1[[#This Row],[Mês de referência para faturamento]]) + 1, DAY(Tabela1[[#This Row],[Mês de referência para faturamento]]) ) )} -> 45931 | AI15: =K15-L15 -> 0 | AJ15: =AB15-AC15 -> 0 | AK15: =J15-U15 -> 0 | AM15: =_xlfn.XLOOKUP(Tabela1[[#This Row],[Unidade]],tabShoppingsEmails[Shopping],tabShoppingsEmails[E-mails consolidados]) -> patricia.benvenuti@allos.co; ludmila.fachin@allos.co; emerson.silveira@allos.co; bruna.zanella@allos.co; wallace.nascimento@allos.co; juliana.slomp@allos.co
C16: Shopping Villagio Caxias | D16: Resíduos | E16: Recicla Engenharia | F16: 3 | G16: 3 | U16: =(J16+L16+Q16+R16+S16+N16)+IF(T16="Sim",O16+P16,0) -> 0 | Z16: 45931 | AA16: {=IFERROR( IF( _xlfn.XLOOKUP( 1, ( ('Condição de Faturamento'!$A$2:$A$1000 = Tabela1[[#This Row],[Unidade]]) * ('Condição de Faturamento'!$B$2:$B$1000 = Tabela1[[#This Row],[Categoria]]) * ('Condição de Faturamento'!$C$2:$C$1000 = Tabela1[[#This Row],[Fornecedor]]) ), 'Condição de Faturamento'!$D$2:$D$1000 ) = "Emissão no mês da prestação do serviço", Tabela1[[#This Row],[Mês de referência para faturamento]], DATE( YEAR(Tabela1[[#This Row],[Mês de referência para faturamento]]), MONTH(Tabela1[[#This Row],[Mês de referência para faturamento]]) + 1, DAY(Tabela1[[#This Row],[Mês de referência para faturamento]]) ) ), DATE( YEAR(Tabela1[[#This Row],[Mês de referência para faturamento]]), MONTH(Tabela1[[#This Row],[Mês de referência para faturamento]]) + 1, DAY(Tabela1[[#This Row],[Mês de referência para faturamento]]) ) )} -> 45962 | AI16: =K16-L16 -> 0 | AJ16: =AB16-AC16 -> 0 | AK16: =J16-U16 -> 0 | AM16: =_xlfn.XLOOKUP(Tabela1[[#This Row],[Unidade]],tabShoppingsEmails[Shopping],tabShoppingsEmails[E-mails consolidados]) -> patricia.benvenuti@allos.co; ludmila.fachin@allos.co; emerson.silveira@allos.co; bruna.zanella@allos.co; wallace.nascimento@allos.co; juliana.slomp@allos.co
C17: Shopping Villagio Caxias | D17: Resíduos | E17: Recicla Engenharia | F17: 3 | G17: 3 | U17: =(J17+L17+Q17+R17+S17+N17)+IF(T17="Sim",O17+P17,0) -> 0 | Z17: 45962 | AA17: {=IFERROR( IF( _xlfn.XLOOKUP( 1, ( ('Condição de Faturamento'!$A$2:$A$1000 = Tabela1[[#This Row],[Unidade]]) * ('Condição de Faturamento'!$B$2:$B$1000 = Tabela1[[#This Row],[Categoria]]) * ('Condição de Faturamento'!$C$2:$C$1000 = Tabela1[[#This Row],[Fornecedor]]) ), 'Condição de Faturamento'!$D$2:$D$1000 ) = "Emissão no mês da prestação do serviço", Tabela1[[#This Row],[Mês de referência para faturamento]], DATE( YEAR(Tabela1[[#This Row],[Mês de referência para faturamento]]), MONTH(Tabela1[[#This Row],[Mês de referência para faturamento]]) + 1, DAY(Tabela1[[#This Row],[Mês de referência para faturamento]]) ) ), DATE( YEAR(Tabela1[[#This Row],[Mês de referência para faturamento]]), MONTH(Tabela1[[#This Row],[Mês de referência para faturamento]]) + 1, DAY(Tabela1[[#This Row],[Mês de referência para faturamento]]) ) )} -> 45992 | AI17: =K17-L17 -> 0 | AJ17: =AB17-AC17 -> 0 | AK17: =J17-U17 -> 0 | AM17: =_xlfn.XLOOKUP(Tabela1[[#This Row],[Unidade]],tabShoppingsEmails[Shopping],tabShoppingsEmails[E-mails consolidados]) -> patricia.benvenuti@allos.co; ludmila.fachin@allos.co; emerson.silveira@allos.co; bruna.zanella@allos.co; wallace.nascimento@allos.co; juliana.slomp@allos.co
C18: Shopping Villagio Caxias | D18: Resíduos | E18: Recicla Engenharia | F18: 3 | G18: 3 | U18: =(J18+L18+Q18+R18+S18+N18)+IF(T18="Sim",O18+P18,0) -> 0 | Z18: 45992 | AA18: {=IFERROR( IF( _xlfn.XLOOKUP( 1, ( ('Condição de Faturamento'!$A$2:$A$1000 = Tabela1[[#This Row],[Unidade]]) * ('Condição de Faturamento'!$B$2:$B$1000 = Tabela1[[#This Row],[Categoria]]) * ('Condição de Faturamento'!$C$2:$C$1000 = Tabela1[[#This Row],[Fornecedor]]) ), 'Condição de Faturamento'!$D$2:$D$1000 ) = "Emissão no mês da prestação do serviço", Tabela1[[#This Row],[Mês de referência para faturamento]], DATE( YEAR(Tabela1[[#This Row],[Mês de referência para faturamento]]), MONTH(Tabela1[[#This Row],[Mês de referência para faturamento]]) + 1, DAY(Tabela1[[#This Row],[Mês de referência para faturamento]]) ) ), DATE( YEAR(Tabela1[[#This Row],[Mês de referência para faturamento]]), MONTH(Tabela1[[#This Row],[Mês de referência para faturamento]]) + 1, DAY(Tabela1[[#This Row],[Mês de referência para faturamento]]) ) )} -> 46023 | AI18: =K18-L18 -> 0 | AJ18: =AB18-AC18 -> 0 | AK18: =J18-U18 -> 0 | AM18: =_xlfn.XLOOKUP(Tabela1[[#This Row],[Unidade]],tabShoppingsEmails[Shopping],tabShoppingsEmails[E-mails consolidados]) -> patricia.benvenuti@allos.co; ludmila.fachin@allos.co; emerson.silveira@allos.co; bruna.zanella@allos.co; wallace.nascimento@allos.co; juliana.slomp@allos.co
B19: Sim | C19: Shopping Villagio Caxias | D19: Portaria | E19: Veper | F19: 8 | G19: 8 | H19: 0 | I19: 7.42 | J19: 36468.39 | K19: 0 | L19: 0 | M19: 0 | N19: -149.6248 | O19: 0 | P19: 0 | Q19: 0 | R19: 0 | S19: 0 | T19: Sim | U19: =(J19+L19+Q19+R19+S19+N19)+IF(T19="Sim",O19+P19,0) -> 36318.765 | W19: =IF(J19="","",U19*(1+V19)) -> 36318.765 | Z19: 45658 | AA19: {=IFERROR( IF( _xlfn.XLOOKUP( 1, ( ('Condição de Faturamento'!$A$2:$A$1000 = Tabela1[[#This Row],[Unidade]]) * ('Condição de Faturamento'!$B$2:$B$1000 = Tabela1[[#This Row],[Categoria]]) * ('Condição de Faturamento'!$C$2:$C$1000 = Tabela1[[#This Row],[Fornecedor]]) ), 'Condição de Faturamento'!$D$2:$D$1000 ) = "Emissão no mês da prestação do serviço", Tabela1[[#This Row],[Mês de referência para faturamento]], DATE( YEAR(Tabela1[[#This Row],[Mês de referência para faturamento]]), MONTH(Tabela1[[#This Row],[Mês de referência para faturamento]]) + 1, DAY(Tabela1[[#This Row],[Mês de referência para faturamento]]) ) ), DATE( YEAR(Tabela1[[#This Row],[Mês de referência para faturamento]]), MONTH(Tabela1[[#This Row],[Mês de referência para faturamento]]) + 1, DAY(Tabela1[[#This Row],[Mês de referência para faturamento]]) ) )} -> 45689 | AI19: =K19-L19 -> 0 | AJ19: =AB19-AC19 -> 0 | AK19: =J19-U19 -> 149.6248 | AM19: =_xlfn.XLOOKUP(Tabela1[[#This Row],[Unidade]],tabShoppingsEmails[Shopping],tabShoppingsEmails[E-mails consolidados]) -> patricia.benvenuti@allos.co; ludmila.fachin@allos.co; emerson.silveira@allos.co; bruna.zanella@allos.co; wallace.nascimento@allos.co; juliana.slomp@allos.co
B20: Sim | C20: Shopping Villagio Caxias | D20: Portaria | E20: Veper | F20: 8 | G20: 8 | H20: 0 | I20: 19.5 | J20: 36468.39 | K20: 0 | L20: 0 | M20: 0 | N20: -400.42 | O20: -364.68 | P20: 0 | Q20: 0 | R20: 0 | S20: 0 | T20: Sim | U20: =(J20+L20+Q20+R20+S20+N20)+IF(T20="Sim",O20+P20,0) -> 35703.29 | W20: =IF(J20="","",U20*(1+V20)) -> 35703.29 | Z20: 45689 | AA20: {=IFERROR( IF( _xlfn.XLOOKUP( 1, ( ('Condição de Faturamento'!$A$2:$A$1000 = Tabela1[[#This Row],[Unidade]]) * ('Condição de Faturamento'!$B$2:$B$1000 = Tabela1[[#This Row],[Categoria]]) * ('Condição de Faturamento'!$C$2:$C$1000 = Tabela1[[#This Row],[Fornecedor]]) ), 'Condição de Faturamento'!$D$2:$D$1000 ) = "Emissão no mês da prestação do serviço", Tabela1[[#This Row],[Mês de referência para faturamento]], DATE( YEAR(Tabela1[[#This Row],[Mês de referência para faturamento]]), MONTH(Tabela1[[#This Row],[Mês de referência para faturamento]]) + 1, DAY(Tabela1[[#This Row],[Mês de referência para faturamento]]) ) ), DATE( YEAR(Tabela1[[#This Row],[Mês de referência para faturamento]]), MONTH(Tabela1[[#This Row],[Mês de referência para faturamento]]) + 1, DAY(Tabela1[[#This Row],[Mês de referência para faturamento]]) ) )} -> 45717 | AI20: =K20-L20 -> 0 | AJ20: =AB20-AC20 -> 0 | AK20: =J20-U20 -> 765.1 | AM20: =_xlfn.XLOOKUP(Tabela1[[#This Row],[Unidade]],tabShoppingsEmails[Shopping],tabShoppingsEmails[E-mails consolidados]) -> patricia.benvenuti@allos.co; ludmila.fachin@allos.co; emerson.silveira@allos.co; bruna.zanella@allos.co; wallace.nascimento@allos.co; juliana.slomp@allos.co
B21: Sim | C21: Shopping Villagio Caxias | D21: Portaria | E21: Veper | F21: 8 | G21: 8 | H21: 0 | I21: 41.48 | J21: 42452.35 | K21: 0 | L21: 0 | M21: 0 | N21: -992.51533 | O21: -424.52 | P21: 0 | Q21: 0 | R21: =38712.3743513944-J21 -> -3739.9756 | S21: 0 | T21: Sim | U21: =(J21+L21+Q21+R21+S21+N21)+IF(T21="Sim",O21+P21,0) -> 37295.339 | W21: =IF(J21="","",U21*(1+V21)) -> 37295.339 | Z21: 45717 | AA21: {=IFERROR( IF( _xlfn.XLOOKUP( 1, ( ('Condição de Faturamento'!$A$2:$A$1000 = Tabela1[[#This Row],[Unidade]]) * ('Condição de Faturamento'!$B$2:$B$1000 = Tabela1[[#This Row],[Categoria]]) * ('Condição de Faturamento'!$C$2:$C$1000 = Tabela1[[#This Row],[Fornecedor]]) ), 'Condição de Faturamento'!$D$2:$D$1000 ) = "Emissão no mês da prestação do serviço", Tabela1[[#This Row],[Mês de referência para faturamento]], DATE( YEAR(Tabela1[[#This Row],[Mês de referência para faturamento]]), MONTH(Tabela1[[#This Row],[Mês de referência para faturamento]]) + 1, DAY(Tabela1[[#This Row],[Mês de referência para faturamento]]) ) ), DATE( YEAR(Tabela1[[#This Row],[Mês de referência para faturamento]]), MONTH(Tabela1[[#This Row],[Mês de referência para faturamento]]) + 1, DAY(Tabela1[[#This Row],[Mês de referência para faturamento]]) ) )} -> 45748 | AI21: =K21-L21 -> 0 | AJ21: =AB21-AC21 -> 0 | AK21: =J21-U21 -> 5157.011 | AM21: =_xlfn.XLOOKUP(Tabela1[[#This Row],[Unidade]],tabShoppingsEmails[Shopping],tabShoppingsEmails[E-mails consolidados]) -> patricia.benvenuti@allos.co; ludmila.fachin@allos.co; emerson.silveira@allos.co; bruna.zanella@allos.co; wallace.nascimento@allos.co; juliana.slomp@allos.co
A22: 45722 | B22: Sim | C22: Shopping Villagio Caxias | D22: Portaria | E22: Veper | F22: 8 | G22: 8 | H22: 0 | I22: 2.01 | J22: 42452.35 | K22: 0 | L22: 0 | M22: 0 | N22: -48.400133 | O22: -212.26 | P22: 0 | Q22: 0 | R22: =39460.3692248094-Tabela1[[#This Row],[Valor Planilha]] -> -2991.9808 | S22: 0 | T22: Sim | U22: =(J22+L22+Q22+R22+S22+N22)+IF(T22="Sim",O22+P22,0) -> 39199.709 | W22: =IF(J22="","",U22*(1+V22)) -> 39199.709 | Z22: 45748 | AA22: {=IFERROR( IF( _xlfn.XLOOKUP( 1, ( ('Condição de Faturamento'!$A$2:$A$1000 = Tabela1[[#This Row],[Unidade]]) * ('Condição de Faturamento'!$B$2:$B$1000 = Tabela1[[#This Row],[Categoria]]) * ('Condição de Faturamento'!$C$2:$C$1000 = Tabela1[[#This Row],[Fornecedor]]) ), 'Condição de Faturamento'!$D$2:$D$1000 ) = "Emissão no mês da prestação do serviço", Tabela1[[#This Row],[Mês de referência para faturamento]], DATE( YEAR(Tabela1[[#This Row],[Mês de referência para faturamento]]), MONTH(Tabela1[[#This Row],[Mês de referência para faturamento]]) + 1, DAY(Tabela1[[#This Row],[Mês de referência para faturamento]]) ) ), DATE( YEAR(Tabela1[[#This Row],[Mês de referência para faturamento]]), MONTH(Tabela1[[#This Row],[Mês de referência para faturamento]]) + 1, DAY(Tabela1[[#This Row],[Mês de referência para faturamento]]) ) )} -> 45778 | AI22: =K22-L22 -> 0 | AJ22: =AB22-AC22 -> 0 | AK22: =J22-U22 -> 3252.6409 | AM22: =_xlfn.XLOOKUP(Tabela1[[#This Row],[Unidade]],tabShoppingsEmails[Shopping],tabShoppingsEmails[E-mails consolidados]) -> patricia.benvenuti@allos.co; ludmila.fachin@allos.co; emerson.silveira@allos.co; bruna.zanella@allos.co; wallace.nascimento@allos.co; juliana.slomp@allos.co
A23: 45811 | B23: Sim | C23: Shopping Villagio Caxias | D23: Portaria | E23: Veper | F23: 8 | G23: 8 | H23: 0 | I23: 0 | J23: 46399.92 | K23: 0 | L23: 0 | M23: 0 | N23: 0 | O23: -232 | P23: 0 | Q23: 0 | R23: =44903.9300710717-Tabela1[[#This Row],[Valor Planilha]] -> -1495.9897 | S23: 0 | T23: Sim | U23: =(J23+L23+Q23+R23+S23+N23)+IF(T23="Sim",O23+P23,0) -> 44671.93 | W23: =IF(J23="","",U23*(1+V23)) -> 44671.93 | X23: 13806.448 | Y23: 1.1 | Z23: 45778 | AA23: {=IFERROR( IF( _xlfn.XLOOKUP( 1, ( ('Condição de Faturamento'!$A$2:$A$1000 = Tabela1[[#This Row],[Unidade]]) * ('Condição de Faturamento'!$B$2:$B$1000 = Tabela1[[#This Row],[Categoria]]) * ('Condição de Faturamento'!$C$2:$C$1000 = Tabela1[[#This Row],[Fornecedor]]) ), 'Condição de Faturamento'!$D$2:$D$1000 ) = "Emissão no mês da prestação do serviço", Tabela1[[#This Row],[Mês de referência para faturamento]], DATE( YEAR(Tabela1[[#This Row],[Mês de referência para faturamento]]), MONTH(Tabela1[[#This Row],[Mês de referência para faturamento]]) + 1, DAY(Tabela1[[#This Row],[Mês de referência para faturamento]]) ) ), DATE( YEAR(Tabela1[[#This Row],[Mês de referência para faturamento]]), MONTH(Tabela1[[#This Row],[Mês de referência para faturamento]]) + 1, DAY(Tabela1[[#This Row],[Mês de referência para faturamento]]) ) )} -> 45809 | AI23: =K23-L23 -> 0 | AJ23: =AB23-AC23 -> 0 | AK23: =J23-U23 -> 1727.9897 | AM23: =_xlfn.XLOOKUP(Tabela1[[#This Row],[Unidade]],tabShoppingsEmails[Shopping],tabShoppingsEmails[E-mails consolidados]) -> patricia.benvenuti@allos.co; ludmila.fachin@allos.co; emerson.silveira@allos.co; bruna.zanella@allos.co; wallace.nascimento@allos.co; juliana.slomp@allos.co
A24: 45841 | B24: Sim | C24: Shopping Villagio Caxias | D24: Portaria | E24: Veper | F24: 8 | G24: 8 | H24: 0 | I24: 21.77 | J24: 46399.92 | K24: 0 | L24: 0 | M24: 0 | N24: -569.85133 | O24: -464 | P24: 0 | Q24: 0 | R24: =45651.9249444867-Tabela1[[#This Row],[Valor Planilha]] -> -747.99487 | S24: 0 | T24: Sim | U24: =(J24+L24+Q24+R24+S24+N24)+IF(T24="Sim",O24+P24,0) -> 44618.074 | W24: =IF(J24="","",U24*(1+V24)) -> 44618.074 | Z24: 45809 | AA24: {=IFERROR( IF( _xlfn.XLOOKUP( 1, ( ('Condição de Faturamento'!$A$2:$A$1000 = Tabela1[[#This Row],[Unidade]]) * ('Condição de Faturamento'!$B$2:$B$1000 = Tabela1[[#This Row],[Categoria]]) * ('Condição de Faturamento'!$C$2:$C$1000 = Tabela1[[#This Row],[Fornecedor]]) ), 'Condição de Faturamento'!$D$2:$D$1000 ) = "Emissão no mês da prestação do serviço", Tabela1[[#This Row],[Mês de referência para faturamento]], DATE( YEAR(Tabela1[[#This Row],[Mês de referência para faturamento]]), MONTH(Tabela1[[#This Row],[Mês de referência para faturamento]]) + 1, DAY(Tabela1[[#This Row],[Mês de referência para faturamento]]) ) ), DATE( YEAR(Tabela1[[#This Row],[Mês de referência para faturamento]]), MONTH(Tabela1[[#This Row],[Mês de referência para faturamento]]) + 1, DAY(Tabela1[[#This Row],[Mês de referência para faturamento]]) ) )} -> 45839 | AI24: =K24-L24 -> 0 | AJ24: =AB24-AC24 -> 0 | AK24: =J24-U24 -> 1781.8462 | AM24: =_xlfn.XLOOKUP(Tabela1[[#This Row],[Unidade]],tabShoppingsEmails[Shopping],tabShoppingsEmails[E-mails consolidados]) -> patricia.benvenuti@allos.co; ludmila.fachin@allos.co; emerson.silveira@allos.co; bruna.zanella@allos.co; wallace.nascimento@allos.co; juliana.slomp@allos.co
A25: 45876 | B25: Sim | C25: Shopping Villagio Caxias | D25: Portaria | E25: Protesul | F25: 8 | G25: 8 | H25: 0 | I25: 3 | J25: 51048.21 | K25: 0 | L25: 0 | M25: 0 | N25: -98.26 | O25: 0 | P25: 0 | Q25: 0 | R25: 0 | S25: 0 | T25: Sim | U25: =(J25+L25+Q25+R25+S25+N25)+IF(T25="Sim",O25+P25,0) -> 50949.95 | W25: =IF(J25="","",U25*(1+V25)) -> 50949.95 | Z25: 45839 | AA25: {=IFERROR( IF( _xlfn.XLOOKUP( 1, ( ('Condição de Faturamento'!$A$2:$A$1000 = Tabela1[[#This Row],[Unidade]]) * ('Condição de Faturamento'!$B$2:$B$1000 = Tabela1[[#This Row],[Categoria]]) * ('Condição de Faturamento'!$C$2:$C$1000 = Tabela1[[#This Row],[Fornecedor]]) ), 'Condição de Faturamento'!$D$2:$D$1000 ) = "Emissão no mês da prestação do serviço", Tabela1[[#This Row],[Mês de referência para faturamento]], DATE( YEAR(Tabela1[[#This Row],[Mês de referência para faturamento]]), MONTH(Tabela1[[#This Row],[Mês de referência para faturamento]]) + 1, DAY(Tabela1[[#This Row],[Mês de referência para faturamento]]) ) ), DATE( YEAR(Tabela1[[#This Row],[Mês de referência para faturamento]]), MONTH(Tabela1[[#This Row],[Mês de referência para faturamento]]) + 1, DAY(Tabela1[[#This Row],[Mês de referência para faturamento]]) ) )} -> 45870 | AI25: =K25-L25 -> 0 | AJ25: =AB25-AC25 -> 0 | AK25: =J25-U25 -> 98.26 | AM25: =_xlfn.XLOOKUP(Tabela1[[#This Row],[Unidade]],tabShoppingsEmails[Shopping],tabShoppingsEmails[E-mails consolidados]) -> patricia.benvenuti@allos.co; ludmila.fachin@allos.co; emerson.silveira@allos.co; bruna.zanella@allos.co; wallace.nascimento@allos.co; juliana.slomp@allos.co
A26: 45904 | B26: Sim | C26: Shopping Villagio Caxias | D26: Portaria | E26: Protesul | F26: 8 | G26: 8 | H26: 0 | I26: 8.27 | J26: 51048.21 | K26: 0 | L26: 0 | M26: 0 | N26: -281.49 | O26: -510.48 | P26: 0 | Q26: 0 | R26: 0 | S26: 0 | T26: Sim | U26: =(J26+L26+Q26+R26+S26+N26)+IF(T26="Sim",O26+P26,0) -> 50256.24 | W26: =IF(J26="","",U26*(1+V26)) -> 50256.24 | Z26: 45870 | AA26: {=IFERROR( IF( _xlfn.XLOOKUP( 1, ( ('Condição de Faturamento'!$A$2:$A$1000 = Tabela1[[#This Row],[Unidade]]) * ('Condição de Faturamento'!$B$2:$B$1000 = Tabela1[[#This Row],[Categoria]]) * ('Condição de Faturamento'!$C$2:$C$1000 = Tabela1[[#This Row],[Fornecedor]]) ), 'Condição de Faturamento'!$D$2:$D$1000 ) = "Emissão no mês da prestação do serviço", Tabela1[[#This Row],[Mês de referência para faturamento]], DATE( YEAR(Tabela1[[#This Row],[Mês de referência para faturamento]]), MONTH(Tabela1[[#This Row],[Mês de referência para faturamento]]) + 1, DAY(Tabela1[[#This Row],[Mês de referência para faturamento]]) ) ), DATE( YEAR(Tabela1[[#This Row],[Mês de referência para faturamento]]), MONTH(Tabela1[[#This Row],[Mês de referência para faturamento]]) + 1, DAY(Tabela1[[#This Row],[Mês de referência para faturamento]]) ) )} -> 45901 | AI26: =K26-L26 -> 0 | AJ26: =AB26-AC26 -> 0 | AK26: =J26-U26 -> 791.97 | AM26: =_xlfn.XLOOKUP(Tabela1[[#This Row],[Unidade]],tabShoppingsEmails[Shopping],tabShoppingsEmails[E-mails consolidados]) -> patricia.benvenuti@allos.co; ludmila.fachin@allos.co; emerson.silveira@allos.co; bruna.zanella@allos.co; wallace.nascimento@allos.co; juliana.slomp@allos.co
A27: 45931 | B27: Sim | C27: Shopping Villagio Caxias | D27: Portaria | E27: Protesul | F27: 8 | G27: 8 | H27: 0 | I27: 0.23 | J27: 51048.21 | K27: 0 | L27: 0 | M27: 0 | N27: -182.9252 | O27: -255.24 | P27: 0 | Q27: 0 | R27: 0 | S27: 0 | T27: Sim | U27: =(J27+L27+Q27+R27+S27+N27)+IF(T27="Sim",O27+P27,0) -> 50610.045 | W27: =IF(J27="","",U27*(1+V27)) -> 50610.045 | Z27: 45901 | AA27: {=IFERROR( IF( _xlfn.XLOOKUP( 1, ( ('Condição de Faturamento'!$A$2:$A$1000 = Tabela1[[#This Row],[Unidade]]) * ('Condição de Faturamento'!$B$2:$B$1000 = Tabela1[[#This Row],[Categoria]]) * ('Condição de Faturamento'!$C$2:$C$1000 = Tabela1[[#This Row],[Fornecedor]]) ), 'Condição de Faturamento'!$D$2:$D$1000 ) = "Emissão no mês da prestação do serviço", Tabela1[[#This Row],[Mês de referência para faturamento]], DATE( YEAR(Tabela1[[#This Row],[Mês de referência para faturamento]]), MONTH(Tabela1[[#This Row],[Mês de referência para faturamento]]) + 1, DAY(Tabela1[[#This Row],[Mês de referência para faturamento]]) ) ), DATE( YEAR(Tabela1[[#This Row],[Mês de referência para faturamento]]), MONTH(Tabela1[[#This Row],[Mês de referência para faturamento]]) + 1, DAY(Tabela1[[#This Row],[Mês de referência para faturamento]]) ) )} -> 45931 | AI27: =K27-L27 -> 0 | AJ27: =AB27-AC27 -> 0 | AK27: =J27-U27 -> 438.1652 | AM27: =_xlfn.XLOOKUP(Tabela1[[#This Row],[Unidade]],tabShoppingsEmails[Shopping],tabShoppingsEmails[E-mails consolidados]) -> patricia.benvenuti@allos.co; ludmila.fachin@allos.co; emerson.silveira@allos.co; bruna.zanella@allos.co; wallace.nascimento@allos.co; juliana.slomp@allos.co
C28: Shopping Villagio Caxias | D28: Portaria | E28: Protesul | F28: 8 | U28: =(J28+L28+Q28+R28+S28+N28)+IF(T28="Sim",O28+P28,0) -> 0 | W28: =IF(J28="","",U28*(1+V28)) | Z28: 45931 | AA28: {=IFERROR( IF( _xlfn.XLOOKUP( 1, ( ('Condição de Faturamento'!$A$2:$A$1000 = Tabela1[[#This Row],[Unidade]]) * ('Condição de Faturamento'!$B$2:$B$1000 = Tabela1[[#This Row],[Categoria]]) * ('Condição de Faturamento'!$C$2:$C$1000 = Tabela1[[#This Row],[Fornecedor]]) ), 'Condição de Faturamento'!$D$2:$D$1000 ) = "Emissão no mês da prestação do serviço", Tabela1[[#This Row],[Mês de referência para faturamento]], DATE( YEAR(Tabela1[[#This Row],[Mês de referência para faturamento]]), MONTH(Tabela1[[#This Row],[Mês de referência para faturamento]]) + 1, DAY(Tabela1[[#This Row],[Mês de referência para faturamento]]) ) ), DATE( YEAR(Tabela1[[#This Row],[Mês de referência para faturamento]]), MONTH(Tabela1[[#This Row],[Mês de referência para faturamento]]) + 1, DAY(Tabela1[[#This Row],[Mês de referência para faturamento]]) ) )} -> 45962 | AI28: =K28-L28 -> 0 | AJ28: =AB28-AC28 -> 0 | AK28: =J28-U28 -> 0 | AM28: =_xlfn.XLOOKUP(Tabela1[[#This Row],[Unidade]],tabShoppingsEmails[Shopping],tabShoppingsEmails[E-mails consolidados]) -> patricia.benvenuti@allos.co; ludmila.fachin@allos.co; emerson.silveira@allos.co; bruna.zanella@allos.co; wallace.nascimento@allos.co; juliana.slomp@allos.co
C29: Shopping Villagio Caxias | D29: Portaria | E29: Protesul | F29: 8 | U29: =(J29+L29+Q29+R29+S29+N29)+IF(T29="Sim",O29+P29,0) -> 0 | W29: =IF(J29="","",U29*(1+V29)) | Z29: 45962 | AA29: {=IFERROR( IF( _xlfn.XLOOKUP( 1, ( ('Condição de Faturamento'!$A$2:$A$1000 = Tabela1[[#This Row],[Unidade]]) * ('Condição de Faturamento'!$B$2:$B$1000 = Tabela1[[#This Row],[Categoria]]) * ('Condição de Faturamento'!$C$2:$C$1000 = Tabela1[[#This Row],[Fornecedor]]) ), 'Condição de Faturamento'!$D$2:$D$1000 ) = "Emissão no mês da prestação do serviço", Tabela1[[#This Row],[Mês de referência para faturamento]], DATE( YEAR(Tabela1[[#This Row],[Mês de referência para faturamento]]), MONTH(Tabela1[[#This Row],[Mês de referência para faturamento]]) + 1, DAY(Tabela1[[#This Row],[Mês de referência para faturamento]]) ) ), DATE( YEAR(Tabela1[[#This Row],[Mês de referência para faturamento]]), MONTH(Tabela1[[#This Row],[Mês de referência para faturamento]]) + 1, DAY(Tabela1[[#This Row],[Mês de referência para faturamento]]) ) )} -> 45992 | AI29: =K29-L29 -> 0 | AJ29: =AB29-AC29 -> 0 | AK29: =J29-U29 -> 0 | AM29: =_xlfn.XLOOKUP(Tabela1[[#This Row],[Unidade]],tabShoppingsEmails[Shopping],tabShoppingsEmails[E-mails consolidados]) -> patricia.benvenuti@allos.co; ludmila.fachin@allos.co; emerson.silveira@allos.co; bruna.zanella@allos.co; wallace.nascimento@allos.co; juliana.slomp@allos.co
C30: Shopping Villagio Caxias | D30: Portaria | E30: Protesul | F30: 8 | U30: =(J30+L30+Q30+R30+S30+N30)+IF(T30="Sim",O30+P30,0) -> 0 | W30: =IF(J30="","",U30*(1+V30)) | Z30: 45992 | AA30: {=IFERROR( IF( _xlfn.XLOOKUP( 1, ( ('Condição de Faturamento'!$A$2:$A$1000 = Tabela1[[#This Row],[Unidade]]) * ('Condição de Faturamento'!$B$2:$B$1000 = Tabela1[[#This Row],[Categoria]]) * ('Condição de Faturamento'!$C$2:$C$1000 = Tabela1[[#This Row],[Fornecedor]]) ), 'Condição de Faturamento'!$D$2:$D$1000 ) = "Emissão no mês da prestação do serviço", Tabela1[[#This Row],[Mês de referência para faturamento]], DATE( YEAR(Tabela1[[#This Row],[Mês de referência para faturamento]]), MONTH(Tabela1[[#This Row],[Mês de referência para faturamento]]) + 1, DAY(Tabela1[[#This Row],[Mês de referência para faturamento]]) ) ), DATE( YEAR(Tabela1[[#This Row],[Mês de referência para faturamento]]), MONTH(Tabela1[[#This Row],[Mês de referência para faturamento]]) + 1, DAY(Tabela1[[#This Row],[Mês de referência para faturamento]]) ) )} -> 46023 | AI30: =K30-L30 -> 0 | AJ30: =AB30-AC30 -> 0 | AK30: =J30-U30 -> 0 | AM30: =_xlfn.XLOOKUP(Tabela1[[#This Row],[Unidade]],tabShoppingsEmails[Shopping],tabShoppingsEmails[E-mails consolidados]) -> patricia.benvenuti@allos.co; ludmila.fachin@allos.co; emerson.silveira@allos.co; bruna.zanella@allos.co; wallace.nascimento@allos.co; juliana.slomp@allos.co
B31: Sim | C31: Shopping Villagio Caxias | D31: Vigilância | E31: Veper | F31: 12 | G31: 12 | H31: 0 | I31: 1.6 | J31: 76454.99 | K31: 0 | L31: 0 | M31: 0 | N31: -42.016 | O31: -382.32 | P31: 0 | Q31: 0 | R31: 0 | S31: 0 | T31: Sim | U31: =(J31+L31+Q31+R31+S31+N31)+IF(T31="Sim",O31+P31,0) -> 76030.654 | W31: =IF(J31="","",U31*(1+V31)) -> 76030.654 | Z31: 45658 | AA31: {=IFERROR( IF( _xlfn.XLOOKUP( 1, ( ('Condição de Faturamento'!$A$2:$A$1000 = Tabela1[[#This Row],[Unidade]]) * ('Condição de Faturamento'!$B$2:$B$1000 = Tabela1[[#This Row],[Categoria]]) * ('Condição de Faturamento'!$C$2:$C$1000 = Tabela1[[#This Row],[Fornecedor]]) ), 'Condição de Faturamento'!$D$2:$D$1000 ) = "Emissão no mês da prestação do serviço", Tabela1[[#This Row],[Mês de referência para faturamento]], DATE( YEAR(Tabela1[[#This Row],[Mês de referência para faturamento]]), MONTH(Tabela1[[#This Row],[Mês de referência para faturamento]]) + 1, DAY(Tabela1[[#This Row],[Mês de referência para faturamento]]) ) ), DATE( YEAR(Tabela1[[#This Row],[Mês de referência para faturamento]]), MONTH(Tabela1[[#This Row],[Mês de referência para faturamento]]) + 1, DAY(Tabela1[[#This Row],[Mês de referência para faturamento]]) ) )} -> 45689 | AI31: =K31-L31 -> 0 | AJ31: =AB31-AC31 -> 0 | AK31: =J31-U31 -> 424.336 | AM31: =_xlfn.XLOOKUP(Tabela1[[#This Row],[Unidade]],tabShoppingsEmails[Shopping],tabShoppingsEmails[E-mails consolidados]) -> patricia.benvenuti@allos.co; ludmila.fachin@allos.co; emerson.silveira@allos.co; bruna.zanella@allos.co; wallace.nascimento@allos.co; juliana.slomp@allos.co
B32: Sim | C32: Shopping Villagio Caxias | D32: Vigilância | E32: Veper | F32: 12 | G32: 12 | H32: 0 | I32: 1.9666667 | J32: 76454.99 | K32: 0 | L32: 0 | M32: 0 | N32: -51.644667 | O32: -1146.97 | P32: 0 | Q32: 0 | R32: 0 | S32: 0 | T32: Sim | U32: =(J32+L32+Q32+R32+S32+N32)+IF(T32="Sim",O32+P32,0) -> 75256.376 | W32: =IF(J32="","",U32*(1+V32)) -> 75256.376 | Z32: 45689 | AA32: {=IFERROR( IF( _xlfn.XLOOKUP( 1, ( ('Condição de Faturamento'!$A$2:$A$1000 = Tabela1[[#This Row],[Unidade]]) * ('Condição de Faturamento'!$B$2:$B$1000 = Tabela1[[#This Row],[Categoria]]) * ('Condição de Faturamento'!$C$2:$C$1000 = Tabela1[[#This Row],[Fornecedor]]) ), 'Condição de Faturamento'!$D$2:$D$1000 ) = "Emissão no mês da prestação do serviço", Tabela1[[#This Row],[Mês de referência para faturamento]], DATE( YEAR(Tabela1[[#This Row],[Mês de referência para faturamento]]), MONTH(Tabela1[[#This Row],[Mês de referência para faturamento]]) + 1, DAY(Tabela1[[#This Row],[Mês de referência para faturamento]]) ) ), DATE( YEAR(Tabela1[[#This Row],[Mês de referência para faturamento]]), MONTH(Tabela1[[#This Row],[Mês de referência para faturamento]]) + 1, DAY(Tabela1[[#This Row],[Mês de referência para faturamento]]) ) )} -> 45717 | AB32: 1394.6804 | AC32: 1394.6804 | AI32: =K32-L32 -> 0 | AJ32: =AB32-AC32 -> 0 | AK32: =J32-U32 -> 1198.6147 | AM32: =_xlfn.XLOOKUP(Tabela1[[#This Row],[Unidade]],tabShoppingsEmails[Shopping],tabShoppingsEmails[E-mails consolidados]) -> patricia.benvenuti@allos.co; ludmila.fachin@allos.co; emerson.silveira@allos.co; bruna.zanella@allos.co; wallace.nascimento@allos.co; juliana.slomp@allos.co
B33: Sim | C33: Shopping Villagio Caxias | D33: Vigilância | E33: Veper | F33: 12 | G33: 12 | H33: 0 | I33: 3.08 | J33: 76454.99 | K33: 0 | L33: 0 | M33: 0 | N33: -80.968333 | O33: -1146.97 | P33: 0 | Q33: 0 | R33: 0 | S33: 0 | T33: Sim | U33: =(J33+L33+Q33+R33+S33+N33)+IF(T33="Sim",O33+P33,0) -> 75227.052 | W33: =IF(J33="","",U33*(1+V33)) -> 75227.052 | Z33: 45717 | AA33: {=IFERROR( IF( _xlfn.XLOOKUP( 1, ( ('Condição de Faturamento'!$A$2:$A$1000 = Tabela1[[#This Row],[Unidade]]) * ('Condição de Faturamento'!$B$2:$B$1000 = Tabela1[[#This Row],[Categoria]]) * ('Condição de Faturamento'!$C$2:$C$1000 = Tabela1[[#This Row],[Fornecedor]]) ), 'Condição de Faturamento'!$D$2:$D$1000 ) = "Emissão no mês da prestação do serviço", Tabela1[[#This Row],[Mês de referência para faturamento]], DATE( YEAR(Tabela1[[#This Row],[Mês de referência para faturamento]]), MONTH(Tabela1[[#This Row],[Mês de referência para faturamento]]) + 1, DAY(Tabela1[[#This Row],[Mês de referência para faturamento]]) ) ), DATE( YEAR(Tabela1[[#This Row],[Mês de referência para faturamento]]), MONTH(Tabela1[[#This Row],[Mês de referência para faturamento]]) + 1, DAY(Tabela1[[#This Row],[Mês de referência para faturamento]]) ) )} -> 45748 | AB33: 2801.2911 | AC33: 2801.2911 | AI33: =K33-L33 -> 0 | AJ33: =AB33-AC33 -> 0 | AK33: =J33-U33 -> 1227.9383 | AM33: =_xlfn.XLOOKUP(Tabela1[[#This Row],[Unidade]],tabShoppingsEmails[Shopping],tabShoppingsEmails[E-mails consolidados]) -> patricia.benvenuti@allos.co; ludmila.fachin@allos.co; emerson.silveira@allos.co; bruna.zanella@allos.co; wallace.nascimento@allos.co; juliana.slomp@allos.co
B34: Sim | C34: Shopping Villagio Caxias | D34: Vigilância | E34: Veper | F34: 12 | G34: 12 | H34: 0 | I34: 2 | J34: 76454.99 | K34: 0 | L34: 0 | M34: 0 | N34: -57.86 | O34: 0 | P34: 0 | Q34: 0 | R34: 0 | S34: 0 | T34: Sim | U34: =(J34+L34+Q34+R34+S34+N34)+IF(T34="Sim",O34+P34,0) -> 76397.13 | W34: =IF(J34="","",U34*(1+V34)) -> 76397.13 | Z34: 45748 | AA34: {=IFERROR( IF( _xlfn.XLOOKUP( 1, ( ('Condição de Faturamento'!$A$2:$A$1000 = Tabela1[[#This Row],[Unidade]]) * ('Condição de Faturamento'!$B$2:$B$1000 = Tabela1[[#This Row],[Categoria]]) * ('Condição de Faturamento'!$C$2:$C$1000 = Tabela1[[#This Row],[Fornecedor]]) ), 'Condição de Faturamento'!$D$2:$D$1000 ) = "Emissão no mês da prestação do serviço", Tabela1[[#This Row],[Mês de referência para faturamento]], DATE( YEAR(Tabela1[[#This Row],[Mês de referência para faturamento]]), MONTH(Tabela1[[#This Row],[Mês de referência para faturamento]]) + 1, DAY(Tabela1[[#This Row],[Mês de referência para faturamento]]) ) ), DATE( YEAR(Tabela1[[#This Row],[Mês de referência para faturamento]]), MONTH(Tabela1[[#This Row],[Mês de referência para faturamento]]) + 1, DAY(Tabela1[[#This Row],[Mês de referência para faturamento]]) ) )} -> 45778 | AB34: 1672.2473 | AC34: 1672.2473 | AI34: =K34-L34 -> 0 | AJ34: =AB34-AC34 -> 0 | AK34: =J34-U34 -> 57.86 | AM34: =_xlfn.XLOOKUP(Tabela1[[#This Row],[Unidade]],tabShoppingsEmails[Shopping],tabShoppingsEmails[E-mails consolidados]) -> patricia.benvenuti@allos.co; ludmila.fachin@allos.co; emerson.silveira@allos.co; bruna.zanella@allos.co; wallace.nascimento@allos.co; juliana.slomp@allos.co
A35: 45811 | B35: sim | C35: Shopping Villagio Caxias | D35: Vigilância | E35: Veper | F35: 12 | G35: 12 | H35: 0 | I35: 12.5 | J35: 83872.722 | K35: 0 | L35: 0 | M35: 0 | N35: -397.25 | O35: -838.73 | P35: 0 | Q35: 0 | R35: 0 | S35: 0 | T35: Sim | U35: =(J35+L35+Q35+R35+S35+N35)+IF(T35="Sim",O35+P35,0) -> 82636.742 | W35: =IF(J35="","",U35*(1+V35)) -> 82636.742 | X35: 7574.3612 | Y35: 1.1 | Z35: 45778 | AA35: {=IFERROR( IF( _xlfn.XLOOKUP( 1, ( ('Condição de Faturamento'!$A$2:$A$1000 = Tabela1[[#This Row],[Unidade]]) * ('Condição de Faturamento'!$B$2:$B$1000 = Tabela1[[#This Row],[Categoria]]) * ('Condição de Faturamento'!$C$2:$C$1000 = Tabela1[[#This Row],[Fornecedor]]) ), 'Condição de Faturamento'!$D$2:$D$1000 ) = "Emissão no mês da prestação do serviço", Tabela1[[#This Row],[Mês de referência para faturamento]], DATE( YEAR(Tabela1[[#This Row],[Mês de referência para faturamento]]), MONTH(Tabela1[[#This Row],[Mês de referência para faturamento]]) + 1, DAY(Tabela1[[#This Row],[Mês de referência para faturamento]]) ) ), DATE( YEAR(Tabela1[[#This Row],[Mês de referência para faturamento]]), MONTH(Tabela1[[#This Row],[Mês de referência para faturamento]]) + 1, DAY(Tabela1[[#This Row],[Mês de referência para faturamento]]) ) )} -> 45809 | AB35: 800.34888 | AC35: 800.34888 | AI35: =K35-L35 -> 0 | AJ35: =AB35-AC35 -> 0 | AK35: =J35-U35 -> 1235.98 | AM35: =_xlfn.XLOOKUP(Tabela1[[#This Row],[Unidade]],tabShoppingsEmails[Shopping],tabShoppingsEmails[E-mails consolidados]) -> patricia.benvenuti@allos.co; ludmila.fachin@allos.co; emerson.silveira@allos.co; bruna.zanella@allos.co; wallace.nascimento@allos.co; juliana.slomp@allos.co
A36: 45841 | B36: Sim | C36: Shopping Villagio Caxias | D36: Vigilância | E36: Veper | F36: 12 | G36: 12 | H36: 0 | I36: 0.67 | J36: 83872.722 | K36: 0 | L36: 0 | M36: 0 | N36: -19.293333 | O36: 0 | P36: 0 | Q36: 0 | R36: 0 | S36: 0 | T36: Sim | U36: =(J36+L36+Q36+R36+S36+N36)+IF(T36="Sim",O36+P36,0) -> 83853.429 | W36: =IF(J36="","",U36*(1+V36)) -> 83853.429 | Z36: 45809 | AA36: {=IFERROR( IF( _xlfn.XLOOKUP( 1, ( ('Condição de Faturamento'!$A$2:$A$1000 = Tabela1[[#This Row],[Unidade]]) * ('Condição de Faturamento'!$B$2:$B$1000 = Tabela1[[#This Row],[Categoria]]) * ('Condição de Faturamento'!$C$2:$C$1000 = Tabela1[[#This Row],[Fornecedor]]) ), 'Condição de Faturamento'!$D$2:$D$1000 ) = "Emissão no mês da prestação do serviço", Tabela1[[#This Row],[Mês de referência para faturamento]], DATE( YEAR(Tabela1[[#This Row],[Mês de referência para faturamento]]), MONTH(Tabela1[[#This Row],[Mês de referência para faturamento]]) + 1, DAY(Tabela1[[#This Row],[Mês de referência para faturamento]]) ) ), DATE( YEAR(Tabela1[[#This Row],[Mês de referência para faturamento]]), MONTH(Tabela1[[#This Row],[Mês de referência para faturamento]]) + 1, DAY(Tabela1[[#This Row],[Mês de referência para faturamento]]) ) )} -> 45839 | AI36: =K36-L36 -> 0 | AJ36: =AB36-AC36 -> 0 | AK36: =J36-U36 -> 19.293333 | AM36: =_xlfn.XLOOKUP(Tabela1[[#This Row],[Unidade]],tabShoppingsEmails[Shopping],tabShoppingsEmails[E-mails consolidados]) -> patricia.benvenuti@allos.co; ludmila.fachin@allos.co; emerson.silveira@allos.co; bruna.zanella@allos.co; wallace.nascimento@allos.co; juliana.slomp@allos.co
