Workbook
Name SegmentaçãodeDados_Categoria: #N/A
Name SegmentaçãodeDados_Fornecedor: #N/A
Name SegmentaçãodeDados_Mês: #N/A
Name SegmentaçãodeDados_Unidade: #N/A

Sheet Infos Relatório
C1: 45292 | I1: 45323 | O1: 45352 | U1: 45383 | AA1: 45413 | AG1: 45444 | AM1: 45474 | AS1: 45505 | AY1: 45536 | BE1: 45566 | BK1: 45597 | BQ1: 45627
B2: Limpeza | C2: =C1 -> 45292 | I2: =I1 -> 45323 | O2: =O1 -> 45352 | U2: =U1 -> 45383 | AA2: =AA1 -> 45413 | AG2: =AG1 -> 45444 | AM2: =AM1 -> 45474 | AS2: =AS1 -> 45505 | AY2: =AY1 -> 45536 | BE2: =BE1 -> 45566 | BK2: =BK1 -> 45597 | BQ2: =BQ1 -> 45627
B3: Fornecedor | C3: Qtd Shopping | D3: HC Total | E3: Valor total contrato | F3: Desconto SLA Total | G3: Desconto médio % | H3: QTD de faltas | I3: Qtd Shopping | J3: HC Total | K3: Valor total contrato | L3: Desconto SLA Total | M3: Desconto médio % | N3: QTD de faltas | O3: Qtd Shopping | P3: HC Total | Q3: Valor total contrato | R3: Desconto SLA Total | S3: Desconto médio % | T3: QTD de faltas | U3: Qtd Shopping | V3: HC Total | W3: Valor total contrato | X3: Desconto SLA Total | Y3: Desconto médio % | Z3: QTD de faltas | AA3: Qtd Shopping | AB3: HC Total | AC3: Valor total contrato | AD3: Desconto SLA Total | AE3: Desconto médio % | AF3: QTD de faltas | AG3: Qtd Shopping | AH3: HC Total | AI3: Valor total contrato | AJ3: Desconto SLA Total | AK3: Desconto médio % | AL3: QTD de faltas | AM3: Qtd Shopping | AN3: HC Total | AO3: Valor total contrato | AP3: Desconto SLA Total | AQ3: Desconto médio % | AR3: QTD de faltas | AS3: Qtd Shopping | AT3: HC Total | AU3: Valor total contrato | AV3: Desconto SLA Total | AW3: Desconto médio % | AX3: QTD de faltas | AY3: Qtd Shopping | AZ3: HC Total | BA3: Valor total contrato | BB3: Desconto SLA Total | BC3: Desconto médio % | BD3: QTD de faltas | BE3: Qtd Shopping | BF3: HC Total | BG3: Valor total contrato | BH3: Desconto SLA Total | BI3: Desconto médio % | BJ3: QTD de faltas | BK3: Qtd Shopping | BL3: HC Total | BM3: Valor total contrato | BN3: Desconto SLA Total | BO3: Desconto médio % | BP3: QTD de faltas | BQ3: Qtd Shopping | BR3: HC Total | BS3: Valor total contrato | BT3: Desconto SLA Total | BU3: Desconto médio % | BV3: QTD de faltas
B4: Action Fire | C4: =COUNTIFS('Faturamento SP3'!$D$2:$D$692,'Infos Relatório'!$B$2,'Faturamento SP3'!$E$2:$E$692,'Infos Relatório'!$B4,'Faturamento SP3'!$Z$2:$Z$692,'Infos Relatório'!C$1) -> 0 | D4: =SUMIFS('Faturamento SP3'!$G$2:$G$692,'Faturamento SP3'!$D$2:$D$692,'Infos Relatório'!$B$2,'Faturamento SP3'!$E$2:$E$692,'Infos Relatório'!$B4,'Faturamento SP3'!$Z$2:$Z$692,'Infos Relatório'!C$1) -> 0 | E4: =SUMIFS('Faturamento SP3'!$J$2:$J$692,'Faturamento SP3'!$D$2:$D$692,'Infos Relatório'!$B$2,'Faturamento SP3'!$E$2:$E$692,'Infos Relatório'!$B4,'Faturamento SP3'!$Z$2:$Z$692,'Infos Relatório'!C$1) -> 0 | F4: =SUMIFS('Faturamento SP3'!$O$2:$O$692,'Faturamento SP3'!$D$2:$D$692,'Infos Relatório'!$B$2,'Faturamento SP3'!$E$2:$E$692,'Infos Relatório'!$B4,'Faturamento SP3'!$Z$2:$Z$692,'Infos Relatório'!C$1,'Faturamento SP3'!$T$2:$T$692,"Sim")+SUMIFS('Faturamento SP3'!$P$2:$P$692,'Faturamento SP3'!$D$2:$D$692,'Infos Relatório'!$B$2,'Faturamento SP3'!$E$2:$E$692,'Infos Relatório'!$B4,'Faturamento SP3'!$Z$2:$Z$692,'Infos Relatório'!C$1,'Faturamento SP3'!$T$2:$T$692,"Sim") -> 0 | G4: =F4/E4 -> #DIV/0! | H4: =SUMIFS('Faturamento SP3'!$H$2:$H$692,'Faturamento SP3'!$D$2:$D$692,'Infos Relatório'!$B$2,'Faturamento SP3'!$E$2:$E$692,'Infos Relatório'!$B4,'Faturamento SP3'!$Z$2:$Z$692,'Infos Relatório'!C$1) -> 0 | I4: =COUNTIFS('Faturamento SP3'!$D$2:$D$692,'Infos Relatório'!$B$2,'Faturamento SP3'!$E$2:$E$692,'Infos Relatório'!$B4,'Faturamento SP3'!$Z$2:$Z$692,'Infos Relatório'!I$1) -> 0 | J4: =SUMIFS('Faturamento SP3'!$G$2:$G$692,'Faturamento SP3'!$D$2:$D$692,'Infos Relatório'!$B$2,'Faturamento SP3'!$E$2:$E$692,'Infos Relatório'!$B4,'Faturamento SP3'!$Z$2:$Z$692,'Infos Relatório'!I$1) -> 0 | K4: =SUMIFS('Faturamento SP3'!$J$2:$J$692,'Faturamento SP3'!$D$2:$D$692,'Infos Relatório'!$B$2,'Faturamento SP3'!$E$2:$E$692,'Infos Relatório'!$B4,'Faturamento SP3'!$Z$2:$Z$692,'Infos Relatório'!I$1) -> 0 | L4: =SUMIFS('Faturamento SP3'!$O$2:$O$692,'Faturamento SP3'!$D$2:$D$692,'Infos Relatório'!$B$2,'Faturamento SP3'!$E$2:$E$692,'Infos Relatório'!$B4,'Faturamento SP3'!$Z$2:$Z$692,'Infos Relatório'!I$1,'Faturamento SP3'!$T$2:$T$692,"Sim")+SUMIFS('Faturamento SP3'!$P$2:$P$692,'Faturamento SP3'!$D$2:$D$692,'Infos Relatório'!$B$2,'Faturamento SP3'!$E$2:$E$692,'Infos Relatório'!$B4,'Faturamento SP3'!$Z$2:$Z$692,'Infos Relatório'!I$1,'Faturamento SP3'!$T$2:$T$692,"Sim") -> 0 | M4: =L4/K4 -> #DIV/0! | N4: =SUMIFS('Faturamento SP3'!$H$2:$H$692,'Faturamento SP3'!$D$2:$D$692,'Infos Relatório'!$B$2,'Faturamento SP3'!$E$2:$E$692,'Infos Relatório'!$B4,'Faturamento SP3'!$Z$2:$Z$692,'Infos Relatório'!I$1) -> 0 | O4: =COUNTIFS('Faturamento SP3'!$D$2:$D$692,'Infos Relatório'!$B$2,'Faturamento SP3'!$E$2:$E$692,'Infos Relatório'!$B4,'Faturamento SP3'!$Z$2:$Z$692,'Infos Relatório'!O$1) -> 0 | P4: =SUMIFS('Faturamento SP3'!$G$2:$G$692,'Faturamento SP3'!$D$2:$D$692,'Infos Relatório'!$B$2,'Faturamento SP3'!$E$2:$E$692,'Infos Relatório'!$B4,'Faturamento SP3'!$Z$2:$Z$692,'Infos Relatório'!O$1) -> 0 | Q4: =SUMIFS('Faturamento SP3'!$J$2:$J$692,'Faturamento SP3'!$D$2:$D$692,'Infos Relatório'!$B$2,'Faturamento SP3'!$E$2:$E$692,'Infos Relatório'!$B4,'Faturamento SP3'!$Z$2:$Z$692,'Infos Relatório'!O$1) -> 0 | R4: =SUMIFS('Faturamento SP3'!$O$2:$O$692,'Faturamento SP3'!$D$2:$D$692,'Infos Relatório'!$B$2,'Faturamento SP3'!$E$2:$E$692,'Infos Relatório'!$B4,'Faturamento SP3'!$Z$2:$Z$692,'Infos Relatório'!O$1,'Faturamento SP3'!$T$2:$T$692,"Sim")+SUMIFS('Faturamento SP3'!$P$2:$P$692,'Faturamento SP3'!$D$2:$D$692,'Infos Relatório'!$B$2,'Faturamento SP3'!$E$2:$E$692,'Infos Relatório'!$B4,'Faturamento SP3'!$Z$2:$Z$692,'Infos Relatório'!O$1,'Faturamento SP3'!$T$2:$T$692,"Sim") -> 0 | S4: =R4/Q4 -> #DIV/0! | T4: =SUMIFS('Faturamento SP3'!$H$2:$H$692,'Faturamento SP3'!$D$2:$D$692,'Infos Relatório'!$B$2,'Faturamento SP3'!$E$2:$E$692,'Infos Relatório'!$B4,'Faturamento SP3'!$Z$2:$Z$692,'Infos Relatório'!O$1) -> 0 | U4: =COUNTIFS('Faturamento SP3'!$D$2:$D$692,'Infos Relatório'!$B$2,'Faturamento SP3'!$E$2:$E$692,'Infos Relatório'!$B4,'Faturamento SP3'!$Z$2:$Z$692,'Infos Relatório'!U$1) -> 0 | V4: =SUMIFS('Faturamento SP3'!$G$2:$G$692,'Faturamento SP3'!$D$2:$D$692,'Infos Relatório'!$B$2,'Faturamento SP3'!$E$2:$E$692,'Infos Relatório'!$B4,'Faturamento SP3'!$Z$2:$Z$692,'Infos Relatório'!U$1) -> 0 | W4: =SUMIFS('Faturamento SP3'!$J$2:$J$692,'Faturamento SP3'!$D$2:$D$692,'Infos Relatório'!$B$2,'Faturamento SP3'!$E$2:$E$692,'Infos Relatório'!$B4,'Faturamento SP3'!$Z$2:$Z$692,'Infos Relatório'!U$1) -> 0 | X4: =SUMIFS('Faturamento SP3'!$O$2:$O$692,'Faturamento SP3'!$D$2:$D$692,'Infos Relatório'!$B$2,'Faturamento SP3'!$E$2:$E$692,'Infos Relatório'!$B4,'Faturamento SP3'!$Z$2:$Z$692,'Infos Relatório'!U$1,'Faturamento SP3'!$T$2:$T$692,"Sim")+SUMIFS('Faturamento SP3'!$P$2:$P$692,'Faturamento SP3'!$D$2:$D$692,'Infos Relatório'!$B$2,'Faturamento SP3'!$E$2:$E$692,'Infos Relatório'!$B4,'Faturamento SP3'!$Z$2:$Z$692,'Infos Relatório'!U$1,'Faturamento SP3'!$T$2:$T$692,"Sim") -> 0 | Y4: =X4/W4 -> #DIV/0! | Z4: =SUMIFS('Faturamento SP3'!$H$2:$H$692,'Faturamento SP3'!$D$2:$D$692,'Infos Relatório'!$B$2,'Faturamento SP3'!$E$2:$E$692,'Infos Relatório'!$B4,'Faturamento SP3'!$Z$2:$Z$692,'Infos Relatório'!U$1) -> 0 | AA4: =COUNTIFS('Faturamento SP3'!$D$2:$D$692,'Infos Relatório'!$B$2,'Faturamento SP3'!$E$2:$E$692,'Infos Relatório'!$B4,'Faturamento SP3'!$Z$2:$Z$692,'Infos Relatório'!AA$1) -> 0 | AB4: =SUMIFS('Faturamento SP3'!$G$2:$G$692,'Faturamento SP3'!$D$2:$D$692,'Infos Relatório'!$B$2,'Faturamento SP3'!$E$2:$E$692,'Infos Relatório'!$B4,'Faturamento SP3'!$Z$2:$Z$692,'Infos Relatório'!AA$1) -> 0 | AC4: =SUMIFS('Faturamento SP3'!$J$2:$J$692,'Faturamento SP3'!$D$2:$D$692,'Infos Relatório'!$B$2,'Faturamento SP3'!$E$2:$E$692,'Infos Relatório'!$B4,'Faturamento SP3'!$Z$2:$Z$692,'Infos Relatório'!AA$1) -> 0 | AD4: =SUMIFS('Faturamento SP3'!$O$2:$O$692,'Faturamento SP3'!$D$2:$D$692,'Infos Relatório'!$B$2,'Faturamento SP3'!$E$2:$E$692,'Infos Relatório'!$B4,'Faturamento SP3'!$Z$2:$Z$692,'Infos Relatório'!AA$1,'Faturamento SP3'!$T$2:$T$692,"Sim")+SUMIFS('Faturamento SP3'!$P$2:$P$692,'Faturamento SP3'!$D$2:$D$692,'Infos Relatório'!$B$2,'Faturamento SP3'!$E$2:$E$692,'Infos Relatório'!$B4,'Faturamento SP3'!$Z$2:$Z$692,'Infos Relatório'!AA$1,'Faturamento SP3'!$T$2:$T$692,"Sim") -> 0 | AE4: =AD4/AC4 -> #DIV/0! | AF4: =SUMIFS('Faturamento SP3'!$H$2:$H$692,'Faturamento SP3'!$D$2:$D$692,'Infos Relatório'!$B$2,'Faturamento SP3'!$E$2:$E$692,'Infos Relatório'!$B4,'Faturamento SP3'!$Z$2:$Z$692,'Infos Relatório'!AA$1) -> 0 | AG4: =COUNTIFS('Faturamento SP3'!$D$2:$D$692,'Infos Relatório'!$B$2,'Faturamento SP3'!$E$2:$E$692,'Infos Relatório'!$B4,'Faturamento SP3'!$Z$2:$Z$692,'Infos Relatório'!AG$1) -> 0 | AH4: =SUMIFS('Faturamento SP3'!$G$2:$G$692,'Faturamento SP3'!$D$2:$D$692,'Infos Relatório'!$B$2,'Faturamento SP3'!$E$2:$E$692,'Infos Relatório'!$B4,'Faturamento SP3'!$Z$2:$Z$692,'Infos Relatório'!AG$1) -> 0 | AI4: =SUMIFS('Faturamento SP3'!$J$2:$J$692,'Faturamento SP3'!$D$2:$D$692,'Infos Relatório'!$B$2,'Faturamento SP3'!$E$2:$E$692,'Infos Relatório'!$B4,'Faturamento SP3'!$Z$2:$Z$692,'Infos Relatório'!AG$1) -> 0 | AJ4: =SUMIFS('Faturamento SP3'!$O$2:$O$692,'Faturamento SP3'!$D$2:$D$692,'Infos Relatório'!$B$2,'Faturamento SP3'!$E$2:$E$692,'Infos Relatório'!$B4,'Faturamento SP3'!$Z$2:$Z$692,'Infos Relatório'!AG$1,'Faturamento SP3'!$T$2:$T$692,"Sim")+SUMIFS('Faturamento SP3'!$P$2:$P$692,'Faturamento SP3'!$D$2:$D$692,'Infos Relatório'!$B$2,'Faturamento SP3'!$E$2:$E$692,'Infos Relatório'!$B4,'Faturamento SP3'!$Z$2:$Z$692,'Infos Relatório'!AG$1,'Faturamento SP3'!$T$2:$T$692,"Sim") -> 0 | AK4: =AJ4/AI4 -> #DIV/0! | AL4: =SUMIFS('Faturamento SP3'!$H$2:$H$692,'Faturamento SP3'!$D$2:$D$692,'Infos Relatório'!$B$2,'Faturamento SP3'!$E$2:$E$692,'Infos Relatório'!$B4,'Faturamento SP3'!$Z$2:$Z$692,'Infos Relatório'!AG$1) -> 0 | AM4: =COUNTIFS('Faturamento SP3'!$D$2:$D$692,'Infos Relatório'!$B$2,'Faturamento SP3'!$E$2:$E$692,'Infos Relatório'!$B4,'Faturamento SP3'!$Z$2:$Z$692,'Infos Relatório'!AM$1) -> 0 | AN4: =SUMIFS('Faturamento SP3'!$G$2:$G$692,'Faturamento SP3'!$D$2:$D$692,'Infos Relatório'!$B$2,'Faturamento SP3'!$E$2:$E$692,'Infos Relatório'!$B4,'Faturamento SP3'!$Z$2:$Z$692,'Infos Relatório'!AM$1) -> 0 | AO4: =SUMIFS('Faturamento SP3'!$J$2:$J$692,'Faturamento SP3'!$D$2:$D$692,'Infos Relatório'!$B$2,'Faturamento SP3'!$E$2:$E$692,'Infos Relatório'!$B4,'Faturamento SP3'!$Z$2:$Z$692,'Infos Relatório'!AM$1) -> 0 | AP4: =SUMIFS('Faturamento SP3'!$O$2:$O$692,'Faturamento SP3'!$D$2:$D$692,'Infos Relatório'!$B$2,'Faturamento SP3'!$E$2:$E$692,'Infos Relatório'!$B4,'Faturamento SP3'!$Z$2:$Z$692,'Infos Relatório'!AM$1,'Faturamento SP3'!$T$2:$T$692,"Sim")+SUMIFS('Faturamento SP3'!$P$2:$P$692,'Faturamento SP3'!$D$2:$D$692,'Infos Relatório'!$B$2,'Faturamento SP3'!$E$2:$E$692,'Infos Relatório'!$B4,'Faturamento SP3'!$Z$2:$Z$692,'Infos Relatório'!AM$1,'Faturamento SP3'!$T$2:$T$692,"Sim") -> 0 | AQ4: =AP4/AO4 -> #DIV/0! | AR4: =SUMIFS('Faturamento SP3'!$H$2:$H$692,'Faturamento SP3'!$D$2:$D$692,'Infos Relatório'!$B$2,'Faturamento SP3'!$E$2:$E$692,'Infos Relatório'!$B4,'Faturamento SP3'!$Z$2:$Z$692,'Infos Relatório'!AM$1) -> 0 | AS4: =COUNTIFS('Faturamento SP3'!$D$2:$D$692,'Infos Relatório'!$B$2,'Faturamento SP3'!$E$2:$E$692,'Infos Relatório'!$B4,'Faturamento SP3'!$Z$2:$Z$692,'Infos Relatório'!AS$1) -> 0 | AT4: =SUMIFS('Faturamento SP3'!$G$2:$G$692,'Faturamento SP3'!$D$2:$D$692,'Infos Relatório'!$B$2,'Faturamento SP3'!$E$2:$E$692,'Infos Relatório'!$B4,'Faturamento SP3'!$Z$2:$Z$692,'Infos Relatório'!AS$1) -> 0 | AU4: =SUMIFS('Faturamento SP3'!$J$2:$J$692,'Faturamento SP3'!$D$2:$D$692,'Infos Relatório'!$B$2,'Faturamento SP3'!$E$2:$E$692,'Infos Relatório'!$B4,'Faturamento SP3'!$Z$2:$Z$692,'Infos Relatório'!AS$1) -> 0 | AV4: =SUMIFS('Faturamento SP3'!$O$2:$O$692,'Faturamento SP3'!$D$2:$D$692,'Infos Relatório'!$B$2,'Faturamento SP3'!$E$2:$E$692,'Infos Relatório'!$B4,'Faturamento SP3'!$Z$2:$Z$692,'Infos Relatório'!AS$1,'Faturamento SP3'!$T$2:$T$692,"Sim")+SUMIFS('Faturamento SP3'!$P$2:$P$692,'Faturamento SP3'!$D$2:$D$692,'Infos Relatório'!$B$2,'Faturamento SP3'!$E$2:$E$692,'Infos Relatório'!$B4,'Faturamento SP3'!$Z$2:$Z$692,'Infos Relatório'!AS$1,'Faturamento SP3'!$T$2:$T$692,"Sim") -> 0 | AW4: =AV4/AU4 -> #DIV/0! | AX4: =SUMIFS('Faturamento SP3'!$H$2:$H$692,'Faturamento SP3'!$D$2:$D$692,'Infos Relatório'!$B$2,'Faturamento SP3'!$E$2:$E$692,'Infos Relatório'!$B4,'Faturamento SP3'!$Z$2:$Z$692,'Infos Relatório'!AS$1) -> 0 | AY4: =COUNTIFS('Faturamento SP3'!$D$2:$D$692,'Infos Relatório'!$B$2,'Faturamento SP3'!$E$2:$E$692,'Infos Relatório'!$B4,'Faturamento SP3'!$Z$2:$Z$692,'Infos Relatório'!AY$1) -> 0 | AZ4: =SUMIFS('Faturamento SP3'!$G$2:$G$692,'Faturamento SP3'!$D$2:$D$692,'Infos Relatório'!$B$2,'Faturamento SP3'!$E$2:$E$692,'Infos Relatório'!$B4,'Faturamento SP3'!$Z$2:$Z$692,'Infos Relatório'!AY$1) -> 0 | BA4: =SUMIFS('Faturamento SP3'!$J$2:$J$692,'Faturamento SP3'!$D$2:$D$692,'Infos Relatório'!$B$2,'Faturamento SP3'!$E$2:$E$692,'Infos Relatório'!$B4,'Faturamento SP3'!$Z$2:$Z$692,'Infos Relatório'!AY$1) -> 0 | BB4: =SUMIFS('Faturamento SP3'!$O$2:$O$692,'Faturamento SP3'!$D$2:$D$692,'Infos Relatório'!$B$2,'Faturamento SP3'!$E$2:$E$692,'Infos Relatório'!$B4,'Faturamento SP3'!$Z$2:$Z$692,'Infos Relatório'!AY$1,'Faturamento SP3'!$T$2:$T$692,"Sim")+SUMIFS('Faturamento SP3'!$P$2:$P$692,'Faturamento SP3'!$D$2:$D$692,'Infos Relatório'!$B$2,'Faturamento SP3'!$E$2:$E$692,'Infos Relatório'!$B4,'Faturamento SP3'!$Z$2:$Z$692,'Infos Relatório'!AY$1,'Faturamento SP3'!$T$2:$T$692,"Sim") -> 0 | BC4: =BB4/BA4 -> #DIV/0! | BD4: =SUMIFS('Faturamento SP3'!$H$2:$H$692,'Faturamento SP3'!$D$2:$D$692,'Infos Relatório'!$B$2,'Faturamento SP3'!$E$2:$E$692,'Infos Relatório'!$B4,'Faturamento SP3'!$Z$2:$Z$692,'Infos Relatório'!AY$1) -> 0 | BE4: =COUNTIFS('Faturamento SP3'!$D$2:$D$692,'Infos Relatório'!$B$2,'Faturamento SP3'!$E$2:$E$692,'Infos Relatório'!$B4,'Faturamento SP3'!$Z$2:$Z$692,'Infos Relatório'!BE$1) -> 0 | BF4: =SUMIFS('Faturamento SP3'!$G$2:$G$692,'Faturamento SP3'!$D$2:$D$692,'Infos Relatório'!$B$2,'Faturamento SP3'!$E$2:$E$692,'Infos Relatório'!$B4,'Faturamento SP3'!$Z$2:$Z$692,'Infos Relatório'!BE$1) -> 0 | BG4: =SUMIFS('Faturamento SP3'!$J$2:$J$692,'Faturamento SP3'!$D$2:$D$692,'Infos Relatório'!$B$2,'Faturamento SP3'!$E$2:$E$692,'Infos Relatório'!$B4,'Faturamento SP3'!$Z$2:$Z$692,'Infos Relatório'!BE$1) -> 0 | BH4: =SUMIFS('Faturamento SP3'!$O$2:$O$692,'Faturamento SP3'!$D$2:$D$692,'Infos Relatório'!$B$2,'Faturamento SP3'!$E$2:$E$692,'Infos Relatório'!$B4,'Faturamento SP3'!$Z$2:$Z$692,'Infos Relatório'!BE$1,'Faturamento SP3'!$T$2:$T$692,"Sim")+SUMIFS('Faturamento SP3'!$P$2:$P$692,'Faturamento SP3'!$D$2:$D$692,'Infos Relatório'!$B$2,'Faturamento SP3'!$E$2:$E$692,'Infos Relatório'!$B4,'Faturamento SP3'!$Z$2:$Z$692,'Infos Relatório'!BE$1,'Faturamento SP3'!$T$2:$T$692,"Sim") -> 0 | BI4: =BH4/BG4 -> #DIV/0! | BJ4: =SUMIFS('Faturamento SP3'!$H$2:$H$692,'Faturamento SP3'!$D$2:$D$692,'Infos Relatório'!$B$2,'Faturamento SP3'!$E$2:$E$692,'Infos Relatório'!$B4,'Faturamento SP3'!$Z$2:$Z$692,'Infos Relatório'!BE$1) -> 0 | BK4: =COUNTIFS('Faturamento SP3'!$D$2:$D$692,'Infos Relatório'!$B$2,'Faturamento SP3'!$E$2:$E$692,'Infos Relatório'!$B4,'Faturamento SP3'!$Z$2:$Z$692,'Infos Relatório'!BK$1) -> 0 | BL4: =SUMIFS('Faturamento SP3'!$G$2:$G$692,'Faturamento SP3'!$D$2:$D$692,'Infos Relatório'!$B$2,'Faturamento SP3'!$E$2:$E$692,'Infos Relatório'!$B4,'Faturamento SP3'!$Z$2:$Z$692,'Infos Relatório'!BK$1) -> 0 | BM4: =SUMIFS('Faturamento SP3'!$J$2:$J$692,'Faturamento SP3'!$D$2:$D$692,'Infos Relatório'!$B$2,'Faturamento SP3'!$E$2:$E$692,'Infos Relatório'!$B4,'Faturamento SP3'!$Z$2:$Z$692,'Infos Relatório'!BK$1) -> 0 | BN4: =SUMIFS('Faturamento SP3'!$O$2:$O$692,'Faturamento SP3'!$D$2:$D$692,'Infos Relatório'!$B$2,'Faturamento SP3'!$E$2:$E$692,'Infos Relatório'!$B4,'Faturamento SP3'!$Z$2:$Z$692,'Infos Relatório'!BK$1,'Faturamento SP3'!$T$2:$T$692,"Sim")+SUMIFS('Faturamento SP3'!$P$2:$P$692,'Faturamento SP3'!$D$2:$D$692,'Infos Relatório'!$B$2,'Faturamento SP3'!$E$2:$E$692,'Infos Relatório'!$B4,'Faturamento SP3'!$Z$2:$Z$692,'Infos Relatório'!BK$1,'Faturamento SP3'!$T$2:$T$692,"Sim") -> 0 | BO4: =BN4/BM4 -> #DIV/0! | BP4: =SUMIFS('Faturamento SP3'!$H$2:$H$692,'Faturamento SP3'!$D$2:$D$692,'Infos Relatório'!$B$2,'Faturamento SP3'!$E$2:$E$692,'Infos Relatório'!$B4,'Faturamento SP3'!$Z$2:$Z$692,'Infos Relatório'!BK$1) -> 0 | BQ4: =COUNTIFS('Faturamento SP3'!$D$2:$D$692,'Infos Relatório'!$B$2,'Faturamento SP3'!$E$2:$E$692,'Infos Relatório'!$B4,'Faturamento SP3'!$Z$2:$Z$692,'Infos Relatório'!BQ$1) -> 0 | BR4: =SUMIFS('Faturamento SP3'!$G$2:$G$692,'Faturamento SP3'!$D$2:$D$692,'Infos Relatório'!$B$2,'Faturamento SP3'!$E$2:$E$692,'Infos Relatório'!$B4,'Faturamento SP3'!$Z$2:$Z$692,'Infos Relatório'!BQ$1) -> 0 | BS4: =SUMIFS('Faturamento SP3'!$J$2:$J$692,'Faturamento SP3'!$D$2:$D$692,'Infos Relatório'!$B$2,'Faturamento SP3'!$E$2:$E$692,'Infos Relatório'!$B4,'Faturamento SP3'!$Z$2:$Z$692,'Infos Relatório'!BQ$1) -> 0 | BT4: =SUMIFS('Faturamento SP3'!$O$2:$O$692,'Faturamento SP3'!$D$2:$D$692,'Infos Relatório'!$B$2,'Faturamento SP3'!$E$2:$E$692,'Infos Relatório'!$B4,'Faturamento SP3'!$Z$2:$Z$692,'Infos Relatório'!BQ$1,'Faturamento SP3'!$T$2:$T$692,"Sim")+SUMIFS('Faturamento SP3'!$P$2:$P$692,'Faturamento SP3'!$D$2:$D$692,'Infos Relatório'!$B$2,'Faturamento SP3'!$E$2:$E$692,'Infos Relatório'!$B4,'Faturamento SP3'!$Z$2:$Z$692,'Infos Relatório'!BQ$1,'Faturamento SP3'!$T$2:$T$692,"Sim") -> 0 | BU4: =BT4/BS4 -> #DIV/0! | BV4: =SUMIFS('Faturamento SP3'!$H$2:$H$692,'Faturamento SP3'!$D$2:$D$692,'Infos Relatório'!$B$2,'Faturamento SP3'!$E$2:$E$692,'Infos Relatório'!$B4,'Faturamento SP3'!$Z$2:$Z$692,'Infos Relatório'!BQ$1) -> 0
B5: Agro Rio | C5: =COUNTIFS('Faturamento SP3'!$D$2:$D$692,'Infos Relatório'!$B$2,'Faturamento SP3'!$E$2:$E$692,'Infos Relatório'!$B5,'Faturamento SP3'!$Z$2:$Z$692,'Infos Relatório'!C$1) -> 0 | D5: =SUMIFS('Faturamento SP3'!$G$2:$G$692,'Faturamento SP3'!$D$2:$D$692,'Infos Relatório'!$B$2,'Faturamento SP3'!$E$2:$E$692,'Infos Relatório'!$B5,'Faturamento SP3'!$Z$2:$Z$692,'Infos Relatório'!C$1) -> 0 | E5: =SUMIFS('Faturamento SP3'!$J$2:$J$692,'Faturamento SP3'!$D$2:$D$692,'Infos Relatório'!$B$2,'Faturamento SP3'!$E$2:$E$692,'Infos Relatório'!$B5,'Faturamento SP3'!$Z$2:$Z$692,'Infos Relatório'!C$1) -> 0 | F5: =SUMIFS('Faturamento SP3'!$O$2:$O$692,'Faturamento SP3'!$D$2:$D$692,'Infos Relatório'!$B$2,'Faturamento SP3'!$E$2:$E$692,'Infos Relatório'!$B5,'Faturamento SP3'!$Z$2:$Z$692,'Infos Relatório'!C$1,'Faturamento SP3'!$T$2:$T$692,"Sim")+SUMIFS('Faturamento SP3'!$P$2:$P$692,'Faturamento SP3'!$D$2:$D$692,'Infos Relatório'!$B$2,'Faturamento SP3'!$E$2:$E$692,'Infos Relatório'!$B5,'Faturamento SP3'!$Z$2:$Z$692,'Infos Relatório'!C$1,'Faturamento SP3'!$T$2:$T$692,"Sim") -> 0 | G5: =F5/E5 -> #DIV/0! | H5: =SUMIFS('Faturamento SP3'!$H$2:$H$692,'Faturamento SP3'!$D$2:$D$692,'Infos Relatório'!$B$2,'Faturamento SP3'!$E$2:$E$692,'Infos Relatório'!$B5,'Faturamento SP3'!$Z$2:$Z$692,'Infos Relatório'!C$1) -> 0 | I5: =COUNTIFS('Faturamento SP3'!$D$2:$D$692,'Infos Relatório'!$B$2,'Faturamento SP3'!$E$2:$E$692,'Infos Relatório'!$B5,'Faturamento SP3'!$Z$2:$Z$692,'Infos Relatório'!I$1) -> 0 | J5: =SUMIFS('Faturamento SP3'!$G$2:$G$692,'Faturamento SP3'!$D$2:$D$692,'Infos Relatório'!$B$2,'Faturamento SP3'!$E$2:$E$692,'Infos Relatório'!$B5,'Faturamento SP3'!$Z$2:$Z$692,'Infos Relatório'!I$1) -> 0 | K5: =SUMIFS('Faturamento SP3'!$J$2:$J$692,'Faturamento SP3'!$D$2:$D$692,'Infos Relatório'!$B$2,'Faturamento SP3'!$E$2:$E$692,'Infos Relatório'!$B5,'Faturamento SP3'!$Z$2:$Z$692,'Infos Relatório'!I$1) -> 0 | L5: =SUMIFS('Faturamento SP3'!$O$2:$O$692,'Faturamento SP3'!$D$2:$D$692,'Infos Relatório'!$B$2,'Faturamento SP3'!$E$2:$E$692,'Infos Relatório'!$B5,'Faturamento SP3'!$Z$2:$Z$692,'Infos Relatório'!I$1,'Faturamento SP3'!$T$2:$T$692,"Sim")+SUMIFS('Faturamento SP3'!$P$2:$P$692,'Faturamento SP3'!$D$2:$D$692,'Infos Relatório'!$B$2,'Faturamento SP3'!$E$2:$E$692,'Infos Relatório'!$B5,'Faturamento SP3'!$Z$2:$Z$692,'Infos Relatório'!I$1,'Faturamento SP3'!$T$2:$T$692,"Sim") -> 0 | M5: =L5/K5 -> #DIV/0! | N5: =SUMIFS('Faturamento SP3'!$H$2:$H$692,'Faturamento SP3'!$D$2:$D$692,'Infos Relatório'!$B$2,'Faturamento SP3'!$E$2:$E$692,'Infos Relatório'!$B5,'Faturamento SP3'!$Z$2:$Z$692,'Infos Relatório'!I$1) -> 0 | O5: =COUNTIFS('Faturamento SP3'!$D$2:$D$692,'Infos Relatório'!$B$2,'Faturamento SP3'!$E$2:$E$692,'Infos Relatório'!$B5,'Faturamento SP3'!$Z$2:$Z$692,'Infos Relatório'!O$1) -> 0 | P5: =SUMIFS('Faturamento SP3'!$G$2:$G$692,'Faturamento SP3'!$D$2:$D$692,'Infos Relatório'!$B$2,'Faturamento SP3'!$E$2:$E$692,'Infos Relatório'!$B5,'Faturamento SP3'!$Z$2:$Z$692,'Infos Relatório'!O$1) -> 0 | Q5: =SUMIFS('Faturamento SP3'!$J$2:$J$692,'Faturamento SP3'!$D$2:$D$692,'Infos Relatório'!$B$2,'Faturamento SP3'!$E$2:$E$692,'Infos Relatório'!$B5,'Faturamento SP3'!$Z$2:$Z$692,'Infos Relatório'!O$1) -> 0 | R5: =SUMIFS('Faturamento SP3'!$O$2:$O$692,'Faturamento SP3'!$D$2:$D$692,'Infos Relatório'!$B$2,'Faturamento SP3'!$E$2:$E$692,'Infos Relatório'!$B5,'Faturamento SP3'!$Z$2:$Z$692,'Infos Relatório'!O$1,'Faturamento SP3'!$T$2:$T$692,"Sim")+SUMIFS('Faturamento SP3'!$P$2:$P$692,'Faturamento SP3'!$D$2:$D$692,'Infos Relatório'!$B$2,'Faturamento SP3'!$E$2:$E$692,'Infos Relatório'!$B5,'Faturamento SP3'!$Z$2:$Z$692,'Infos Relatório'!O$1,'Faturamento SP3'!$T$2:$T$692,"Sim") -> 0 | S5: =R5/Q5 -> #DIV/0! | T5: =SUMIFS('Faturamento SP3'!$H$2:$H$692,'Faturamento SP3'!$D$2:$D$692,'Infos Relatório'!$B$2,'Faturamento SP3'!$E$2:$E$692,'Infos Relatório'!$B5,'Faturamento SP3'!$Z$2:$Z$692,'Infos Relatório'!O$1) -> 0 | U5: =COUNTIFS('Faturamento SP3'!$D$2:$D$692,'Infos Relatório'!$B$2,'Faturamento SP3'!$E$2:$E$692,'Infos Relatório'!$B5,'Faturamento SP3'!$Z$2:$Z$692,'Infos Relatório'!U$1) -> 0 | V5: =SUMIFS('Faturamento SP3'!$G$2:$G$692,'Faturamento SP3'!$D$2:$D$692,'Infos Relatório'!$B$2,'Faturamento SP3'!$E$2:$E$692,'Infos Relatório'!$B5,'Faturamento SP3'!$Z$2:$Z$692,'Infos Relatório'!U$1) -> 0 | W5: =SUMIFS('Faturamento SP3'!$J$2:$J$692,'Faturamento SP3'!$D$2:$D$692,'Infos Relatório'!$B$2,'Faturamento SP3'!$E$2:$E$692,'Infos Relatório'!$B5,'Faturamento SP3'!$Z$2:$Z$692,'Infos Relatório'!U$1) -> 0 | X5: =SUMIFS('Faturamento SP3'!$O$2:$O$692,'Faturamento SP3'!$D$2:$D$692,'Infos Relatório'!$B$2,'Faturamento SP3'!$E$2:$E$692,'Infos Relatório'!$B5,'Faturamento SP3'!$Z$2:$Z$692,'Infos Relatório'!U$1,'Faturamento SP3'!$T$2:$T$692,"Sim")+SUMIFS('Faturamento SP3'!$P$2:$P$692,'Faturamento SP3'!$D$2:$D$692,'Infos Relatório'!$B$2,'Faturamento SP3'!$E$2:$E$692,'Infos Relatório'!$B5,'Faturamento SP3'!$Z$2:$Z$692,'Infos Relatório'!U$1,'Faturamento SP3'!$T$2:$T$692,"Sim") -> 0 | Y5: =X5/W5 -> #DIV/0! | Z5: =SUMIFS('Faturamento SP3'!$H$2:$H$692,'Faturamento SP3'!$D$2:$D$692,'Infos Relatório'!$B$2,'Faturamento SP3'!$E$2:$E$692,'Infos Relatório'!$B5,'Faturamento SP3'!$Z$2:$Z$692,'Infos Relatório'!U$1) -> 0 | AA5: =COUNTIFS('Faturamento SP3'!$D$2:$D$692,'Infos Relatório'!$B$2,'Faturamento SP3'!$E$2:$E$692,'Infos Relatório'!$B5,'Faturamento SP3'!$Z$2:$Z$692,'Infos Relatório'!AA$1) -> 0 | AB5: =SUMIFS('Faturamento SP3'!$G$2:$G$692,'Faturamento SP3'!$D$2:$D$692,'Infos Relatório'!$B$2,'Faturamento SP3'!$E$2:$E$692,'Infos Relatório'!$B5,'Faturamento SP3'!$Z$2:$Z$692,'Infos Relatório'!AA$1) -> 0 | AC5: =SUMIFS('Faturamento SP3'!$J$2:$J$692,'Faturamento SP3'!$D$2:$D$692,'Infos Relatório'!$B$2,'Faturamento SP3'!$E$2:$E$692,'Infos Relatório'!$B5,'Faturamento SP3'!$Z$2:$Z$692,'Infos Relatório'!AA$1) -> 0 | AD5: =SUMIFS('Faturamento SP3'!$O$2:$O$692,'Faturamento SP3'!$D$2:$D$692,'Infos Relatório'!$B$2,'Faturamento SP3'!$E$2:$E$692,'Infos Relatório'!$B5,'Faturamento SP3'!$Z$2:$Z$692,'Infos Relatório'!AA$1,'Faturamento SP3'!$T$2:$T$692,"Sim")+SUMIFS('Faturamento SP3'!$P$2:$P$692,'Faturamento SP3'!$D$2:$D$692,'Infos Relatório'!$B$2,'Faturamento SP3'!$E$2:$E$692,'Infos Relatório'!$B5,'Faturamento SP3'!$Z$2:$Z$692,'Infos Relatório'!AA$1,'Faturamento SP3'!$T$2:$T$692,"Sim") -> 0 | AE5: =AD5/AC5 -> #DIV/0! | AF5: =SUMIFS('Faturamento SP3'!$H$2:$H$692,'Faturamento SP3'!$D$2:$D$692,'Infos Relatório'!$B$2,'Faturamento SP3'!$E$2:$E$692,'Infos Relatório'!$B5,'Faturamento SP3'!$Z$2:$Z$692,'Infos Relatório'!AA$1) -> 0 | AG5: =COUNTIFS('Faturamento SP3'!$D$2:$D$692,'Infos Relatório'!$B$2,'Faturamento SP3'!$E$2:$E$692,'Infos Relatório'!$B5,'Faturamento SP3'!$Z$2:$Z$692,'Infos Relatório'!AG$1) -> 0 | AH5: =SUMIFS('Faturamento SP3'!$G$2:$G$692,'Faturamento SP3'!$D$2:$D$692,'Infos Relatório'!$B$2,'Faturamento SP3'!$E$2:$E$692,'Infos Relatório'!$B5,'Faturamento SP3'!$Z$2:$Z$692,'Infos Relatório'!AG$1) -> 0 | AI5: =SUMIFS('Faturamento SP3'!$J$2:$J$692,'Faturamento SP3'!$D$2:$D$692,'Infos Relatório'!$B$2,'Faturamento SP3'!$E$2:$E$692,'Infos Relatório'!$B5,'Faturamento SP3'!$Z$2:$Z$692,'Infos Relatório'!AG$1) -> 0 | AJ5: =SUMIFS('Faturamento SP3'!$O$2:$O$692,'Faturamento SP3'!$D$2:$D$692,'Infos Relatório'!$B$2,'Faturamento SP3'!$E$2:$E$692,'Infos Relatório'!$B5,'Faturamento SP3'!$Z$2:$Z$692,'Infos Relatório'!AG$1,'Faturamento SP3'!$T$2:$T$692,"Sim")+SUMIFS('Faturamento SP3'!$P$2:$P$692,'Faturamento SP3'!$D$2:$D$692,'Infos Relatório'!$B$2,'Faturamento SP3'!$E$2:$E$692,'Infos Relatório'!$B5,'Faturamento SP3'!$Z$2:$Z$692,'Infos Relatório'!AG$1,'Faturamento SP3'!$T$2:$T$692,"Sim") -> 0 | AK5: =AJ5/AI5 -> #DIV/0! | AL5: =SUMIFS('Faturamento SP3'!$H$2:$H$692,'Faturamento SP3'!$D$2:$D$692,'Infos Relatório'!$B$2,'Faturamento SP3'!$E$2:$E$692,'Infos Relatório'!$B5,'Faturamento SP3'!$Z$2:$Z$692,'Infos Relatório'!AG$1) -> 0 | AM5: =COUNTIFS('Faturamento SP3'!$D$2:$D$692,'Infos Relatório'!$B$2,'Faturamento SP3'!$E$2:$E$692,'Infos Relatório'!$B5,'Faturamento SP3'!$Z$2:$Z$692,'Infos Relatório'!AM$1) -> 0 | AN5: =SUMIFS('Faturamento SP3'!$G$2:$G$692,'Faturamento SP3'!$D$2:$D$692,'Infos Relatório'!$B$2,'Faturamento SP3'!$E$2:$E$692,'Infos Relatório'!$B5,'Faturamento SP3'!$Z$2:$Z$692,'Infos Relatório'!AM$1) -> 0 | AO5: =SUMIFS('Faturamento SP3'!$J$2:$J$692,'Faturamento SP3'!$D$2:$D$692,'Infos Relatório'!$B$2,'Faturamento SP3'!$E$2:$E$692,'Infos Relatório'!$B5,'Faturamento SP3'!$Z$2:$Z$692,'Infos Relatório'!AM$1) -> 0 | AP5: =SUMIFS('Faturamento SP3'!$O$2:$O$692,'Faturamento SP3'!$D$2:$D$692,'Infos Relatório'!$B$2,'Faturamento SP3'!$E$2:$E$692,'Infos Relatório'!$B5,'Faturamento SP3'!$Z$2:$Z$692,'Infos Relatório'!AM$1,'Faturamento SP3'!$T$2:$T$692,"Sim")+SUMIFS('Faturamento SP3'!$P$2:$P$692,'Faturamento SP3'!$D$2:$D$692,'Infos Relatório'!$B$2,'Faturamento SP3'!$E$2:$E$692,'Infos Relatório'!$B5,'Faturamento SP3'!$Z$2:$Z$692,'Infos Relatório'!AM$1,'Faturamento SP3'!$T$2:$T$692,"Sim") -> 0 | AQ5: =AP5/AO5 -> #DIV/0! | AR5: =SUMIFS('Faturamento SP3'!$H$2:$H$692,'Faturamento SP3'!$D$2:$D$692,'Infos Relatório'!$B$2,'Faturamento SP3'!$E$2:$E$692,'Infos Relatório'!$B5,'Faturamento SP3'!$Z$2:$Z$692,'Infos Relatório'!AM$1) -> 0 | AS5: =COUNTIFS('Faturamento SP3'!$D$2:$D$692,'Infos Relatório'!$B$2,'Faturamento SP3'!$E$2:$E$692,'Infos Relatório'!$B5,'Faturamento SP3'!$Z$2:$Z$692,'Infos Relatório'!AS$1) -> 0 | AT5: =SUMIFS('Faturamento SP3'!$G$2:$G$692,'Faturamento SP3'!$D$2:$D$692,'Infos Relatório'!$B$2,'Faturamento SP3'!$E$2:$E$692,'Infos Relatório'!$B5,'Faturamento SP3'!$Z$2:$Z$692,'Infos Relatório'!AS$1) -> 0 | AU5: =SUMIFS('Faturamento SP3'!$J$2:$J$692,'Faturamento SP3'!$D$2:$D$692,'Infos Relatório'!$B$2,'Faturamento SP3'!$E$2:$E$692,'Infos Relatório'!$B5,'Faturamento SP3'!$Z$2:$Z$692,'Infos Relatório'!AS$1) -> 0 | AV5: =SUMIFS('Faturamento SP3'!$O$2:$O$692,'Faturamento SP3'!$D$2:$D$692,'Infos Relatório'!$B$2,'Faturamento SP3'!$E$2:$E$692,'Infos Relatório'!$B5,'Faturamento SP3'!$Z$2:$Z$692,'Infos Relatório'!AS$1,'Faturamento SP3'!$T$2:$T$692,"Sim")+SUMIFS('Faturamento SP3'!$P$2:$P$692,'Faturamento SP3'!$D$2:$D$692,'Infos Relatório'!$B$2,'Faturamento SP3'!$E$2:$E$692,'Infos Relatório'!$B5,'Faturamento SP3'!$Z$2:$Z$692,'Infos Relatório'!AS$1,'Faturamento SP3'!$T$2:$T$692,"Sim") -> 0 | AW5: =AV5/AU5 -> #DIV/0! | AX5: =SUMIFS('Faturamento SP3'!$H$2:$H$692,'Faturamento SP3'!$D$2:$D$692,'Infos Relatório'!$B$2,'Faturamento SP3'!$E$2:$E$692,'Infos Relatório'!$B5,'Faturamento SP3'!$Z$2:$Z$692,'Infos Relatório'!AS$1) -> 0 | AY5: =COUNTIFS('Faturamento SP3'!$D$2:$D$692,'Infos Relatório'!$B$2,'Faturamento SP3'!$E$2:$E$692,'Infos Relatório'!$B5,'Faturamento SP3'!$Z$2:$Z$692,'Infos Relatório'!AY$1) -> 0 | AZ5: =SUMIFS('Faturamento SP3'!$G$2:$G$692,'Faturamento SP3'!$D$2:$D$692,'Infos Relatório'!$B$2,'Faturamento SP3'!$E$2:$E$692,'Infos Relatório'!$B5,'Faturamento SP3'!$Z$2:$Z$692,'Infos Relatório'!AY$1) -> 0 | BA5: =SUMIFS('Faturamento SP3'!$J$2:$J$692,'Faturamento SP3'!$D$2:$D$692,'Infos Relatório'!$B$2,'Faturamento SP3'!$E$2:$E$692,'Infos Relatório'!$B5,'Faturamento SP3'!$Z$2:$Z$692,'Infos Relatório'!AY$1) -> 0 | BB5: =SUMIFS('Faturamento SP3'!$O$2:$O$692,'Faturamento SP3'!$D$2:$D$692,'Infos Relatório'!$B$2,'Faturamento SP3'!$E$2:$E$692,'Infos Relatório'!$B5,'Faturamento SP3'!$Z$2:$Z$692,'Infos Relatório'!AY$1,'Faturamento SP3'!$T$2:$T$692,"Sim")+SUMIFS('Faturamento SP3'!$P$2:$P$692,'Faturamento SP3'!$D$2:$D$692,'Infos Relatório'!$B$2,'Faturamento SP3'!$E$2:$E$692,'Infos Relatório'!$B5,'Faturamento SP3'!$Z$2:$Z$692,'Infos Relatório'!AY$1,'Faturamento SP3'!$T$2:$T$692,"Sim") -> 0 | BC5: =BB5/BA5 -> #DIV/0! | BD5: =SUMIFS('Faturamento SP3'!$H$2:$H$692,'Faturamento SP3'!$D$2:$D$692,'Infos Relatório'!$B$2,'Faturamento SP3'!$E$2:$E$692,'Infos Relatório'!$B5,'Faturamento SP3'!$Z$2:$Z$692,'Infos Relatório'!AY$1) -> 0 | BE5: =COUNTIFS('Faturamento SP3'!$D$2:$D$692,'Infos Relatório'!$B$2,'Faturamento SP3'!$E$2:$E$692,'Infos Relatório'!$B5,'Faturamento SP3'!$Z$2:$Z$692,'Infos Relatório'!BE$1) -> 0 | BF5: =SUMIFS('Faturamento SP3'!$G$2:$G$692,'Faturamento SP3'!$D$2:$D$692,'Infos Relatório'!$B$2,'Faturamento SP3'!$E$2:$E$692,'Infos Relatório'!$B5,'Faturamento SP3'!$Z$2:$Z$692,'Infos Relatório'!BE$1) -> 0 | BG5: =SUMIFS('Faturamento SP3'!$J$2:$J$692,'Faturamento SP3'!$D$2:$D$692,'Infos Relatório'!$B$2,'Faturamento SP3'!$E$2:$E$692,'Infos Relatório'!$B5,'Faturamento SP3'!$Z$2:$Z$692,'Infos Relatório'!BE$1) -> 0 | BH5: =SUMIFS('Faturamento SP3'!$O$2:$O$692,'Faturamento SP3'!$D$2:$D$692,'Infos Relatório'!$B$2,'Faturamento SP3'!$E$2:$E$692,'Infos Relatório'!$B5,'Faturamento SP3'!$Z$2:$Z$692,'Infos Relatório'!BE$1,'Faturamento SP3'!$T$2:$T$692,"Sim")+SUMIFS('Faturamento SP3'!$P$2:$P$692,'Faturamento SP3'!$D$2:$D$692,'Infos Relatório'!$B$2,'Faturamento SP3'!$E$2:$E$692,'Infos Relatório'!$B5,'Faturamento SP3'!$Z$2:$Z$692,'Infos Relatório'!BE$1,'Faturamento SP3'!$T$2:$T$692,"Sim") -> 0 | BI5: =BH5/BG5 -> #DIV/0! | BJ5: =SUMIFS('Faturamento SP3'!$H$2:$H$692,'Faturamento SP3'!$D$2:$D$692,'Infos Relatório'!$B$2,'Faturamento SP3'!$E$2:$E$692,'Infos Relatório'!$B5,'Faturamento SP3'!$Z$2:$Z$692,'Infos Relatório'!BE$1) -> 0 | BK5: =COUNTIFS('Faturamento SP3'!$D$2:$D$692,'Infos Relatório'!$B$2,'Faturamento SP3'!$E$2:$E$692,'Infos Relatório'!$B5,'Faturamento SP3'!$Z$2:$Z$692,'Infos Relatório'!BK$1) -> 0 | BL5: =SUMIFS('Faturamento SP3'!$G$2:$G$692,'Faturamento SP3'!$D$2:$D$692,'Infos Relatório'!$B$2,'Faturamento SP3'!$E$2:$E$692,'Infos Relatório'!$B5,'Faturamento SP3'!$Z$2:$Z$692,'Infos Relatório'!BK$1) -> 0 | BM5: =SUMIFS('Faturamento SP3'!$J$2:$J$692,'Faturamento SP3'!$D$2:$D$692,'Infos Relatório'!$B$2,'Faturamento SP3'!$E$2:$E$692,'Infos Relatório'!$B5,'Faturamento SP3'!$Z$2:$Z$692,'Infos Relatório'!BK$1) -> 0 | BN5: =SUMIFS('Faturamento SP3'!$O$2:$O$692,'Faturamento SP3'!$D$2:$D$692,'Infos Relatório'!$B$2,'Faturamento SP3'!$E$2:$E$692,'Infos Relatório'!$B5,'Faturamento SP3'!$Z$2:$Z$692,'Infos Relatório'!BK$1,'Faturamento SP3'!$T$2:$T$692,"Sim")+SUMIFS('Faturamento SP3'!$P$2:$P$692,'Faturamento SP3'!$D$2:$D$692,'Infos Relatório'!$B$2,'Faturamento SP3'!$E$2:$E$692,'Infos Relatório'!$B5,'Faturamento SP3'!$Z$2:$Z$692,'Infos Relatório'!BK$1,'Faturamento SP3'!$T$2:$T$692,"Sim") -> 0 | BO5: =BN5/BM5 -> #DIV/0! | BP5: =SUMIFS('Faturamento SP3'!$H$2:$H$692,'Faturamento SP3'!$D$2:$D$692,'Infos Relatório'!$B$2,'Faturamento SP3'!$E$2:$E$692,'Infos Relatório'!$B5,'Faturamento SP3'!$Z$2:$Z$692,'Infos Relatório'!BK$1) -> 0 | BQ5: =COUNTIFS('Faturamento SP3'!$D$2:$D$692,'Infos Relatório'!$B$2,'Faturamento SP3'!$E$2:$E$692,'Infos Relatório'!$B5,'Faturamento SP3'!$Z$2:$Z$692,'Infos Relatório'!BQ$1) -> 0 | BR5: =SUMIFS('Faturamento SP3'!$G$2:$G$692,'Faturamento SP3'!$D$2:$D$692,'Infos Relatório'!$B$2,'Faturamento SP3'!$E$2:$E$692,'Infos Relatório'!$B5,'Faturamento SP3'!$Z$2:$Z$692,'Infos Relatório'!BQ$1) -> 0 | BS5: =SUMIFS('Faturamento SP3'!$J$2:$J$692,'Faturamento SP3'!$D$2:$D$692,'Infos Relatório'!$B$2,'Faturamento SP3'!$E$2:$E$692,'Infos Relatório'!$B5,'Faturamento SP3'!$Z$2:$Z$692,'Infos Relatório'!BQ$1) -> 0 | BT5: =SUMIFS('Faturamento SP3'!$O$2:$O$692,'Faturamento SP3'!$D$2:$D$692,'Infos Relatório'!$B$2,'Faturamento SP3'!$E$2:$E$692,'Infos Relatório'!$B5,'Faturamento SP3'!$Z$2:$Z$692,'Infos Relatório'!BQ$1,'Faturamento SP3'!$T$2:$T$692,"Sim")+SUMIFS('Faturamento SP3'!$P$2:$P$692,'Faturamento SP3'!$D$2:$D$692,'Infos Relatório'!$B$2,'Faturamento SP3'!$E$2:$E$692,'Infos Relatório'!$B5,'Faturamento SP3'!$Z$2:$Z$692,'Infos Relatório'!BQ$1,'Faturamento SP3'!$T$2:$T$692,"Sim") -> 0 | BU5: =BT5/BS5 -> #DIV/0! | BV5: =SUMIFS('Faturamento SP3'!$H$2:$H$692,'Faturamento SP3'!$D$2:$D$692,'Infos Relatório'!$B$2,'Faturamento SP3'!$E$2:$E$692,'Infos Relatório'!$B5,'Faturamento SP3'!$Z$2:$Z$692,'Infos Relatório'!BQ$1) -> 0
B6: AgroGarden | C6: =COUNTIFS('Faturamento SP3'!$D$2:$D$692,'Infos Relatório'!$B$2,'Faturamento SP3'!$E$2:$E$692,'Infos Relatório'!$B6,'Faturamento SP3'!$Z$2:$Z$692,'Infos Relatório'!C$1) -> 0 | D6: =SUMIFS('Faturamento SP3'!$G$2:$G$692,'Faturamento SP3'!$D$2:$D$692,'Infos Relatório'!$B$2,'Faturamento SP3'!$E$2:$E$692,'Infos Relatório'!$B6,'Faturamento SP3'!$Z$2:$Z$692,'Infos Relatório'!C$1) -> 0 | E6: =SUMIFS('Faturamento SP3'!$J$2:$J$692,'Faturamento SP3'!$D$2:$D$692,'Infos Relatório'!$B$2,'Faturamento SP3'!$E$2:$E$692,'Infos Relatório'!$B6,'Faturamento SP3'!$Z$2:$Z$692,'Infos Relatório'!C$1) -> 0 | F6: =SUMIFS('Faturamento SP3'!$O$2:$O$692,'Faturamento SP3'!$D$2:$D$692,'Infos Relatório'!$B$2,'Faturamento SP3'!$E$2:$E$692,'Infos Relatório'!$B6,'Faturamento SP3'!$Z$2:$Z$692,'Infos Relatório'!C$1,'Faturamento SP3'!$T$2:$T$692,"Sim")+SUMIFS('Faturamento SP3'!$P$2:$P$692,'Faturamento SP3'!$D$2:$D$692,'Infos Relatório'!$B$2,'Faturamento SP3'!$E$2:$E$692,'Infos Relatório'!$B6,'Faturamento SP3'!$Z$2:$Z$692,'Infos Relatório'!C$1,'Faturamento SP3'!$T$2:$T$692,"Sim") -> 0 | G6: =F6/E6 -> #DIV/0! | H6: =SUMIFS('Faturamento SP3'!$H$2:$H$692,'Faturamento SP3'!$D$2:$D$692,'Infos Relatório'!$B$2,'Faturamento SP3'!$E$2:$E$692,'Infos Relatório'!$B6,'Faturamento SP3'!$Z$2:$Z$692,'Infos Relatório'!C$1) -> 0 | I6: =COUNTIFS('Faturamento SP3'!$D$2:$D$692,'Infos Relatório'!$B$2,'Faturamento SP3'!$E$2:$E$692,'Infos Relatório'!$B6,'Faturamento SP3'!$Z$2:$Z$692,'Infos Relatório'!I$1) -> 0 | J6: =SUMIFS('Faturamento SP3'!$G$2:$G$692,'Faturamento SP3'!$D$2:$D$692,'Infos Relatório'!$B$2,'Faturamento SP3'!$E$2:$E$692,'Infos Relatório'!$B6,'Faturamento SP3'!$Z$2:$Z$692,'Infos Relatório'!I$1) -> 0 | K6: =SUMIFS('Faturamento SP3'!$J$2:$J$692,'Faturamento SP3'!$D$2:$D$692,'Infos Relatório'!$B$2,'Faturamento SP3'!$E$2:$E$692,'Infos Relatório'!$B6,'Faturamento SP3'!$Z$2:$Z$692,'Infos Relatório'!I$1) -> 0 | L6: =SUMIFS('Faturamento SP3'!$O$2:$O$692,'Faturamento SP3'!$D$2:$D$692,'Infos Relatório'!$B$2,'Faturamento SP3'!$E$2:$E$692,'Infos Relatório'!$B6,'Faturamento SP3'!$Z$2:$Z$692,'Infos Relatório'!I$1,'Faturamento SP3'!$T$2:$T$692,"Sim")+SUMIFS('Faturamento SP3'!$P$2:$P$692,'Faturamento SP3'!$D$2:$D$692,'Infos Relatório'!$B$2,'Faturamento SP3'!$E$2:$E$692,'Infos Relatório'!$B6,'Faturamento SP3'!$Z$2:$Z$692,'Infos Relatório'!I$1,'Faturamento SP3'!$T$2:$T$692,"Sim") -> 0 | M6: =L6/K6 -> #DIV/0! | N6: =SUMIFS('Faturamento SP3'!$H$2:$H$692,'Faturamento SP3'!$D$2:$D$692,'Infos Relatório'!$B$2,'Faturamento SP3'!$E$2:$E$692,'Infos Relatório'!$B6,'Faturamento SP3'!$Z$2:$Z$692,'Infos Relatório'!I$1) -> 0 | O6: =COUNTIFS('Faturamento SP3'!$D$2:$D$692,'Infos Relatório'!$B$2,'Faturamento SP3'!$E$2:$E$692,'Infos Relatório'!$B6,'Faturamento SP3'!$Z$2:$Z$692,'Infos Relatório'!O$1) -> 0 | P6: =SUMIFS('Faturamento SP3'!$G$2:$G$692,'Faturamento SP3'!$D$2:$D$692,'Infos Relatório'!$B$2,'Faturamento SP3'!$E$2:$E$692,'Infos Relatório'!$B6,'Faturamento SP3'!$Z$2:$Z$692,'Infos Relatório'!O$1) -> 0 | Q6: =SUMIFS('Faturamento SP3'!$J$2:$J$692,'Faturamento SP3'!$D$2:$D$692,'Infos Relatório'!$B$2,'Faturamento SP3'!$E$2:$E$692,'Infos Relatório'!$B6,'Faturamento SP3'!$Z$2:$Z$692,'Infos Relatório'!O$1) -> 0 | R6: =SUMIFS('Faturamento SP3'!$O$2:$O$692,'Faturamento SP3'!$D$2:$D$692,'Infos Relatório'!$B$2,'Faturamento SP3'!$E$2:$E$692,'Infos Relatório'!$B6,'Faturamento SP3'!$Z$2:$Z$692,'Infos Relatório'!O$1,'Faturamento SP3'!$T$2:$T$692,"Sim")+SUMIFS('Faturamento SP3'!$P$2:$P$692,'Faturamento SP3'!$D$2:$D$692,'Infos Relatório'!$B$2,'Faturamento SP3'!$E$2:$E$692,'Infos Relatório'!$B6,'Faturamento SP3'!$Z$2:$Z$692,'Infos Relatório'!O$1,'Faturamento SP3'!$T$2:$T$692,"Sim") -> 0 | S6: =R6/Q6 -> #DIV/0! | T6: =SUMIFS('Faturamento SP3'!$H$2:$H$692,'Faturamento SP3'!$D$2:$D$692,'Infos Relatório'!$B$2,'Faturamento SP3'!$E$2:$E$692,'Infos Relatório'!$B6,'Faturamento SP3'!$Z$2:$Z$692,'Infos Relatório'!O$1) -> 0 | U6: =COUNTIFS('Faturamento SP3'!$D$2:$D$692,'Infos Relatório'!$B$2,'Faturamento SP3'!$E$2:$E$692,'Infos Relatório'!$B6,'Faturamento SP3'!$Z$2:$Z$692,'Infos Relatório'!U$1) -> 0 | V6: =SUMIFS('Faturamento SP3'!$G$2:$G$692,'Faturamento SP3'!$D$2:$D$692,'Infos Relatório'!$B$2,'Faturamento SP3'!$E$2:$E$692,'Infos Relatório'!$B6,'Faturamento SP3'!$Z$2:$Z$692,'Infos Relatório'!U$1) -> 0 | W6: =SUMIFS('Faturamento SP3'!$J$2:$J$692,'Faturamento SP3'!$D$2:$D$692,'Infos Relatório'!$B$2,'Faturamento SP3'!$E$2:$E$692,'Infos Relatório'!$B6,'Faturamento SP3'!$Z$2:$Z$692,'Infos Relatório'!U$1) -> 0 | X6: =SUMIFS('Faturamento SP3'!$O$2:$O$692,'Faturamento SP3'!$D$2:$D$692,'Infos Relatório'!$B$2,'Faturamento SP3'!$E$2:$E$692,'Infos Relatório'!$B6,'Faturamento SP3'!$Z$2:$Z$692,'Infos Relatório'!U$1,'Faturamento SP3'!$T$2:$T$692,"Sim")+SUMIFS('Faturamento SP3'!$P$2:$P$692,'Faturamento SP3'!$D$2:$D$692,'Infos Relatório'!$B$2,'Faturamento SP3'!$E$2:$E$692,'Infos Relatório'!$B6,'Faturamento SP3'!$Z$2:$Z$692,'Infos Relatório'!U$1,'Faturamento SP3'!$T$2:$T$692,"Sim") -> 0 | Y6: =X6/W6 -> #DIV/0! | Z6: =SUMIFS('Faturamento SP3'!$H$2:$H$692,'Faturamento SP3'!$D$2:$D$692,'Infos Relatório'!$B$2,'Faturamento SP3'!$E$2:$E$692,'Infos Relatório'!$B6,'Faturamento SP3'!$Z$2:$Z$692,'Infos Relatório'!U$1) -> 0 | AA6: =COUNTIFS('Faturamento SP3'!$D$2:$D$692,'Infos Relatório'!$B$2,'Faturamento SP3'!$E$2:$E$692,'Infos Relatório'!$B6,'Faturamento SP3'!$Z$2:$Z$692,'Infos Relatório'!AA$1) -> 0 | AB6: =SUMIFS('Faturamento SP3'!$G$2:$G$692,'Faturamento SP3'!$D$2:$D$692,'Infos Relatório'!$B$2,'Faturamento SP3'!$E$2:$E$692,'Infos Relatório'!$B6,'Faturamento SP3'!$Z$2:$Z$692,'Infos Relatório'!AA$1) -> 0 | AC6: =SUMIFS('Faturamento SP3'!$J$2:$J$692,'Faturamento SP3'!$D$2:$D$692,'Infos Relatório'!$B$2,'Faturamento SP3'!$E$2:$E$692,'Infos Relatório'!$B6,'Faturamento SP3'!$Z$2:$Z$692,'Infos Relatório'!AA$1) -> 0 | AD6: =SUMIFS('Faturamento SP3'!$O$2:$O$692,'Faturamento SP3'!$D$2:$D$692,'Infos Relatório'!$B$2,'Faturamento SP3'!$E$2:$E$692,'Infos Relatório'!$B6,'Faturamento SP3'!$Z$2:$Z$692,'Infos Relatório'!AA$1,'Faturamento SP3'!$T$2:$T$692,"Sim")+SUMIFS('Faturamento SP3'!$P$2:$P$692,'Faturamento SP3'!$D$2:$D$692,'Infos Relatório'!$B$2,'Faturamento SP3'!$E$2:$E$692,'Infos Relatório'!$B6,'Faturamento SP3'!$Z$2:$Z$692,'Infos Relatório'!AA$1,'Faturamento SP3'!$T$2:$T$692,"Sim") -> 0 | AE6: =AD6/AC6 -> #DIV/0! | AF6: =SUMIFS('Faturamento SP3'!$H$2:$H$692,'Faturamento SP3'!$D$2:$D$692,'Infos Relatório'!$B$2,'Faturamento SP3'!$E$2:$E$692,'Infos Relatório'!$B6,'Faturamento SP3'!$Z$2:$Z$692,'Infos Relatório'!AA$1) -> 0 | AG6: =COUNTIFS('Faturamento SP3'!$D$2:$D$692,'Infos Relatório'!$B$2,'Faturamento SP3'!$E$2:$E$692,'Infos Relatório'!$B6,'Faturamento SP3'!$Z$2:$Z$692,'Infos Relatório'!AG$1) -> 0 | AH6: =SUMIFS('Faturamento SP3'!$G$2:$G$692,'Faturamento SP3'!$D$2:$D$692,'Infos Relatório'!$B$2,'Faturamento SP3'!$E$2:$E$692,'Infos Relatório'!$B6,'Faturamento SP3'!$Z$2:$Z$692,'Infos Relatório'!AG$1) -> 0 | AI6: =SUMIFS('Faturamento SP3'!$J$2:$J$692,'Faturamento SP3'!$D$2:$D$692,'Infos Relatório'!$B$2,'Faturamento SP3'!$E$2:$E$692,'Infos Relatório'!$B6,'Faturamento SP3'!$Z$2:$Z$692,'Infos Relatório'!AG$1) -> 0 | AJ6: =SUMIFS('Faturamento SP3'!$O$2:$O$692,'Faturamento SP3'!$D$2:$D$692,'Infos Relatório'!$B$2,'Faturamento SP3'!$E$2:$E$692,'Infos Relatório'!$B6,'Faturamento SP3'!$Z$2:$Z$692,'Infos Relatório'!AG$1,'Faturamento SP3'!$T$2:$T$692,"Sim")+SUMIFS('Faturamento SP3'!$P$2:$P$692,'Faturamento SP3'!$D$2:$D$692,'Infos Relatório'!$B$2,'Faturamento SP3'!$E$2:$E$692,'Infos Relatório'!$B6,'Faturamento SP3'!$Z$2:$Z$692,'Infos Relatório'!AG$1,'Faturamento SP3'!$T$2:$T$692,"Sim") -> 0 | AK6: =AJ6/AI6 -> #DIV/0! | AL6: =SUMIFS('Faturamento SP3'!$H$2:$H$692,'Faturamento SP3'!$D$2:$D$692,'Infos Relatório'!$B$2,'Faturamento SP3'!$E$2:$E$692,'Infos Relatório'!$B6,'Faturamento SP3'!$Z$2:$Z$692,'Infos Relatório'!AG$1) -> 0 | AM6: =COUNTIFS('Faturamento SP3'!$D$2:$D$692,'Infos Relatório'!$B$2,'Faturamento SP3'!$E$2:$E$692,'Infos Relatório'!$B6,'Faturamento SP3'!$Z$2:$Z$692,'Infos Relatório'!AM$1) -> 0 | AN6: =SUMIFS('Faturamento SP3'!$G$2:$G$692,'Faturamento SP3'!$D$2:$D$692,'Infos Relatório'!$B$2,'Faturamento SP3'!$E$2:$E$692,'Infos Relatório'!$B6,'Faturamento SP3'!$Z$2:$Z$692,'Infos Relatório'!AM$1) -> 0 | AO6: =SUMIFS('Faturamento SP3'!$J$2:$J$692,'Faturamento SP3'!$D$2:$D$692,'Infos Relatório'!$B$2,'Faturamento SP3'!$E$2:$E$692,'Infos Relatório'!$B6,'Faturamento SP3'!$Z$2:$Z$692,'Infos Relatório'!AM$1) -> 0 | AP6: =SUMIFS('Faturamento SP3'!$O$2:$O$692,'Faturamento SP3'!$D$2:$D$692,'Infos Relatório'!$B$2,'Faturamento SP3'!$E$2:$E$692,'Infos Relatório'!$B6,'Faturamento SP3'!$Z$2:$Z$692,'Infos Relatório'!AM$1,'Faturamento SP3'!$T$2:$T$692,"Sim")+SUMIFS('Faturamento SP3'!$P$2:$P$692,'Faturamento SP3'!$D$2:$D$692,'Infos Relatório'!$B$2,'Faturamento SP3'!$E$2:$E$692,'Infos Relatório'!$B6,'Faturamento SP3'!$Z$2:$Z$692,'Infos Relatório'!AM$1,'Faturamento SP3'!$T$2:$T$692,"Sim") -> 0 | AQ6: =AP6/AO6 -> #DIV/0! | AR6: =SUMIFS('Faturamento SP3'!$H$2:$H$692,'Faturamento SP3'!$D$2:$D$692,'Infos Relatório'!$B$2,'Faturamento SP3'!$E$2:$E$692,'Infos Relatório'!$B6,'Faturamento SP3'!$Z$2:$Z$692,'Infos Relatório'!AM$1) -> 0 | AS6: =COUNTIFS('Faturamento SP3'!$D$2:$D$692,'Infos Relatório'!$B$2,'Faturamento SP3'!$E$2:$E$692,'Infos Relatório'!$B6,'Faturamento SP3'!$Z$2:$Z$692,'Infos Relatório'!AS$1) -> 0 | AT6: =SUMIFS('Faturamento SP3'!$G$2:$G$692,'Faturamento SP3'!$D$2:$D$692,'Infos Relatório'!$B$2,'Faturamento SP3'!$E$2:$E$692,'Infos Relatório'!$B6,'Faturamento SP3'!$Z$2:$Z$692,'Infos Relatório'!AS$1) -> 0 | AU6: =SUMIFS('Faturamento SP3'!$J$2:$J$692,'Faturamento SP3'!$D$2:$D$692,'Infos Relatório'!$B$2,'Faturamento SP3'!$E$2:$E$692,'Infos Relatório'!$B6,'Faturamento SP3'!$Z$2:$Z$692,'Infos Relatório'!AS$1) -> 0 | AV6: =SUMIFS('Faturamento SP3'!$O$2:$O$692,'Faturamento SP3'!$D$2:$D$692,'Infos Relatório'!$B$2,'Faturamento SP3'!$E$2:$E$692,'Infos Relatório'!$B6,'Faturamento SP3'!$Z$2:$Z$692,'Infos Relatório'!AS$1,'Faturamento SP3'!$T$2:$T$692,"Sim")+SUMIFS('Faturamento SP3'!$P$2:$P$692,'Faturamento SP3'!$D$2:$D$692,'Infos Relatório'!$B$2,'Faturamento SP3'!$E$2:$E$692,'Infos Relatório'!$B6,'Faturamento SP3'!$Z$2:$Z$692,'Infos Relatório'!AS$1,'Faturamento SP3'!$T$2:$T$692,"Sim") -> 0 | AW6: =AV6/AU6 -> #DIV/0! | AX6: =SUMIFS('Faturamento SP3'!$H$2:$H$692,'Faturamento SP3'!$D$2:$D$692,'Infos Relatório'!$B$2,'Faturamento SP3'!$E$2:$E$692,'Infos Relatório'!$B6,'Faturamento SP3'!$Z$2:$Z$692,'Infos Relatório'!AS$1) -> 0 | AY6: =COUNTIFS('Faturamento SP3'!$D$2:$D$692,'Infos Relatório'!$B$2,'Faturamento SP3'!$E$2:$E$692,'Infos Relatório'!$B6,'Faturamento SP3'!$Z$2:$Z$692,'Infos Relatório'!AY$1) -> 0 | AZ6: =SUMIFS('Faturamento SP3'!$G$2:$G$692,'Faturamento SP3'!$D$2:$D$692,'Infos Relatório'!$B$2,'Faturamento SP3'!$E$2:$E$692,'Infos Relatório'!$B6,'Faturamento SP3'!$Z$2:$Z$692,'Infos Relatório'!AY$1) -> 0 | BA6: =SUMIFS('Faturamento SP3'!$J$2:$J$692,'Faturamento SP3'!$D$2:$D$692,'Infos Relatório'!$B$2,'Faturamento SP3'!$E$2:$E$692,'Infos Relatório'!$B6,'Faturamento SP3'!$Z$2:$Z$692,'Infos Relatório'!AY$1) -> 0 | BB6: =SUMIFS('Faturamento SP3'!$O$2:$O$692,'Faturamento SP3'!$D$2:$D$692,'Infos Relatório'!$B$2,'Faturamento SP3'!$E$2:$E$692,'Infos Relatório'!$B6,'Faturamento SP3'!$Z$2:$Z$692,'Infos Relatório'!AY$1,'Faturamento SP3'!$T$2:$T$692,"Sim")+SUMIFS('Faturamento SP3'!$P$2:$P$692,'Faturamento SP3'!$D$2:$D$692,'Infos Relatório'!$B$2,'Faturamento SP3'!$E$2:$E$692,'Infos Relatório'!$B6,'Faturamento SP3'!$Z$2:$Z$692,'Infos Relatório'!AY$1,'Faturamento SP3'!$T$2:$T$692,"Sim") -> 0 | BC6: =BB6/BA6 -> #DIV/0! | BD6: =SUMIFS('Faturamento SP3'!$H$2:$H$692,'Faturamento SP3'!$D$2:$D$692,'Infos Relatório'!$B$2,'Faturamento SP3'!$E$2:$E$692,'Infos Relatório'!$B6,'Faturamento SP3'!$Z$2:$Z$692,'Infos Relatório'!AY$1) -> 0 | BE6: =COUNTIFS('Faturamento SP3'!$D$2:$D$692,'Infos Relatório'!$B$2,'Faturamento SP3'!$E$2:$E$692,'Infos Relatório'!$B6,'Faturamento SP3'!$Z$2:$Z$692,'Infos Relatório'!BE$1) -> 0 | BF6: =SUMIFS('Faturamento SP3'!$G$2:$G$692,'Faturamento SP3'!$D$2:$D$692,'Infos Relatório'!$B$2,'Faturamento SP3'!$E$2:$E$692,'Infos Relatório'!$B6,'Faturamento SP3'!$Z$2:$Z$692,'Infos Relatório'!BE$1) -> 0 | BG6: =SUMIFS('Faturamento SP3'!$J$2:$J$692,'Faturamento SP3'!$D$2:$D$692,'Infos Relatório'!$B$2,'Faturamento SP3'!$E$2:$E$692,'Infos Relatório'!$B6,'Faturamento SP3'!$Z$2:$Z$692,'Infos Relatório'!BE$1) -> 0 | BH6: =SUMIFS('Faturamento SP3'!$O$2:$O$692,'Faturamento SP3'!$D$2:$D$692,'Infos Relatório'!$B$2,'Faturamento SP3'!$E$2:$E$692,'Infos Relatório'!$B6,'Faturamento SP3'!$Z$2:$Z$692,'Infos Relatório'!BE$1,'Faturamento SP3'!$T$2:$T$692,"Sim")+SUMIFS('Faturamento SP3'!$P$2:$P$692,'Faturamento SP3'!$D$2:$D$692,'Infos Relatório'!$B$2,'Faturamento SP3'!$E$2:$E$692,'Infos Relatório'!$B6,'Faturamento SP3'!$Z$2:$Z$692,'Infos Relatório'!BE$1,'Faturamento SP3'!$T$2:$T$692,"Sim") -> 0 | BI6: =BH6/BG6 -> #DIV/0! | BJ6: =SUMIFS('Faturamento SP3'!$H$2:$H$692,'Faturamento SP3'!$D$2:$D$692,'Infos Relatório'!$B$2,'Faturamento SP3'!$E$2:$E$692,'Infos Relatório'!$B6,'Faturamento SP3'!$Z$2:$Z$692,'Infos Relatório'!BE$1) -> 0 | BK6: =COUNTIFS('Faturamento SP3'!$D$2:$D$692,'Infos Relatório'!$B$2,'Faturamento SP3'!$E$2:$E$692,'Infos Relatório'!$B6,'Faturamento SP3'!$Z$2:$Z$692,'Infos Relatório'!BK$1) -> 0 | BL6: =SUMIFS('Faturamento SP3'!$G$2:$G$692,'Faturamento SP3'!$D$2:$D$692,'Infos Relatório'!$B$2,'Faturamento SP3'!$E$2:$E$692,'Infos Relatório'!$B6,'Faturamento SP3'!$Z$2:$Z$692,'Infos Relatório'!BK$1) -> 0 | BM6: =SUMIFS('Faturamento SP3'!$J$2:$J$692,'Faturamento SP3'!$D$2:$D$692,'Infos Relatório'!$B$2,'Faturamento SP3'!$E$2:$E$692,'Infos Relatório'!$B6,'Faturamento SP3'!$Z$2:$Z$692,'Infos Relatório'!BK$1) -> 0 | BN6: =SUMIFS('Faturamento SP3'!$O$2:$O$692,'Faturamento SP3'!$D$2:$D$692,'Infos Relatório'!$B$2,'Faturamento SP3'!$E$2:$E$692,'Infos Relatório'!$B6,'Faturamento SP3'!$Z$2:$Z$692,'Infos Relatório'!BK$1,'Faturamento SP3'!$T$2:$T$692,"Sim")+SUMIFS('Faturamento SP3'!$P$2:$P$692,'Faturamento SP3'!$D$2:$D$692,'Infos Relatório'!$B$2,'Faturamento SP3'!$E$2:$E$692,'Infos Relatório'!$B6,'Faturamento SP3'!$Z$2:$Z$692,'Infos Relatório'!BK$1,'Faturamento SP3'!$T$2:$T$692,"Sim") -> 0 | BO6: =BN6/BM6 -> #DIV/0! | BP6: =SUMIFS('Faturamento SP3'!$H$2:$H$692,'Faturamento SP3'!$D$2:$D$692,'Infos Relatório'!$B$2,'Faturamento SP3'!$E$2:$E$692,'Infos Relatório'!$B6,'Faturamento SP3'!$Z$2:$Z$692,'Infos Relatório'!BK$1) -> 0 | BQ6: =COUNTIFS('Faturamento SP3'!$D$2:$D$692,'Infos Relatório'!$B$2,'Faturamento SP3'!$E$2:$E$692,'Infos Relatório'!$B6,'Faturamento SP3'!$Z$2:$Z$692,'Infos Relatório'!BQ$1) -> 0 | BR6: =SUMIFS('Faturamento SP3'!$G$2:$G$692,'Faturamento SP3'!$D$2:$D$692,'Infos Relatório'!$B$2,'Faturamento SP3'!$E$2:$E$692,'Infos Relatório'!$B6,'Faturamento SP3'!$Z$2:$Z$692,'Infos Relatório'!BQ$1) -> 0 | BS6: =SUMIFS('Faturamento SP3'!$J$2:$J$692,'Faturamento SP3'!$D$2:$D$692,'Infos Relatório'!$B$2,'Faturamento SP3'!$E$2:$E$692,'Infos Relatório'!$B6,'Faturamento SP3'!$Z$2:$Z$692,'Infos Relatório'!BQ$1) -> 0 | BT6: =SUMIFS('Faturamento SP3'!$O$2:$O$692,'Faturamento SP3'!$D$2:$D$692,'Infos Relatório'!$B$2,'Faturamento SP3'!$E$2:$E$692,'Infos Relatório'!$B6,'Faturamento SP3'!$Z$2:$Z$692,'Infos Relatório'!BQ$1,'Faturamento SP3'!$T$2:$T$692,"Sim")+SUMIFS('Faturamento SP3'!$P$2:$P$692,'Faturamento SP3'!$D$2:$D$692,'Infos Relatório'!$B$2,'Faturamento SP3'!$E$2:$E$692,'Infos Relatório'!$B6,'Faturamento SP3'!$Z$2:$Z$692,'Infos Relatório'!BQ$1,'Faturamento SP3'!$T$2:$T$692,"Sim") -> 0 | BU6: =BT6/BS6 -> #DIV/0! | BV6: =SUMIFS('Faturamento SP3'!$H$2:$H$692,'Faturamento SP3'!$D$2:$D$692,'Infos Relatório'!$B$2,'Faturamento SP3'!$E$2:$E$692,'Infos Relatório'!$B6,'Faturamento SP3'!$Z$2:$Z$692,'Infos Relatório'!BQ$1) -> 0
