Workbook
Name fim_noturno: Amazonas!$S$4
Name hora_inicial: Amazonas!$S$3
Name inicio_noturno: Amazonas!$S$3
Name SegmentaçãodeDados_Categoria: #N/A
Name SegmentaçãodeDados_Mês_de_referência_para_faturamento: #N/A
Name SegmentaçãodeDados_Unidade: #N/A

Sheet Faltas e atrasos | Cálculos
I3: Amazonas - Atrasos Novembro - Vigilância
H4: Amazonas - Atrasos - Novembro | I4: Função | J4: Escala | K4: Horário entrada | L4: Horário saída | M4: Horário Chegada | N4: Quantidade de horas atraso (Valor nominal) | O4: Valor hora/falta | P4: Total
I5: Vigilante Patrimonial | J5: 12x36 | K5: 0.41666667 | L5: 0.91666667 | M5: 0.42777778 | N5: =(M5-K5)*24 -> 0.26666667 | O5: 28 | P5: =N5*O5 -> 7.4666667
I6: Vigilante Patrimonial | J6: 12x36 | K6: 0.41666667 | L6: 0.91666667 | M6: 0.42013889 | N6: =(M6-K6)*24 -> 0.083333333 | O6: 28 | P6: =N6*O6 -> 2.3333333
I7: Vigilante Patrimonial | J7: 12x36 | K7: 0.41666667 | L7: 0.91666667 | M7: 0.43541667 | N7: =(M7-K7)*24 -> 0.45 | O7: 28 | P7: =N7*O7 -> 12.6
I8: Vigilante Patrimonial | J8: 12x36 | K8: 0.45833333 | L8: 0.95833333 | M8: 0.51666667 | N8: =(M8-K8)*24 -> 1.4 | O8: 28.53 | P8: =N8*O8 -> 39.942
I9: Vigilante Patrimonial | J9: 12x36 | K9: 0.41666667 | L9: 0.91666667 | M9: 0.41944444 | N9: =(M9-K9)*24 -> 0.066666667 | O9: 28 | P9: =N9*O9 -> 1.8666667
I10: Vigilante Patrimonial | J10: 12x36 | K10: 0.45833333 | L10: 0.95833333 | M10: 0.45972222 | N10: =(M10-K10)*24 -> 0.033333333 | O10: 28.53 | P10: =N10*O10 -> 0.951
I11: Total | M11: - | N11: =SUM(N5:N10) -> 2.3 | O11: - | P11: =SUM(P5:P10) -> 65.159667
H14: Manauara | I14: Manauara - Faltas novembro - Limpeza
H15: Novembro | I15: Função | J15: Escala | K15: Horário Entrada Contratual | L15: Horário Saída Contratual | M15: Quantidade de dias de falta | N15: Valor Desconto Falta | O15: Valor Total Falta
I16: ASG - Diurno | J16: 5x1 | K16: 0.56944444 | L16: 0.91666667 | M16: 4 | N16: 127.24 | O16: =M16*N16 -> 508.96
I17: ASG - Noturno | J17: 6X1 | K17: 0.91666667 | L17: 0.26388889 | M17: 7 | N17: 150.93 | O17: =M17*N17 -> 1056.51
I18: Banherista | J18: 12x36 | K18: 0.41666667 | L18: 0.5 | M18: 3 | N18: 157.43 | O18: =M18*N18 -> 472.29
I19: Total | M19: =SUM(M16:M18) -> 14 | O19: =SUM(O16:O18) -> 2037.76
H24: Taboão - Nov | I24: Taboão - Atrasos Novembro - Portaria
I25: Função | J25: Escala | K25: Horário Entrada Contratual | L25: Horário Saída Contratual | M25: Quantidade de horas de falta | N25: Valor hora/falta | O25: Valor Total Falta
I26: Porteiro | J26: 12x36 | K26: 0.29166667 | L26: 0.79166667 | M26: 93.18 | N26: 20.27 | O26: =M26*N26 -> 1888.7586
I27: Porteiro | J27: 12x36 | K27: 0.41666667 | L27: 0.91666667 | M27: 60 | N27: 20.27 | O27: =M27*N27 -> 1216.2
I28: Porteiro | J28: 12x36 | K28: 0.79166667 | L28: 0.29166667 | M28: 24 | N28: 22.28 | O28: =M28*N28 -> 534.72
I29: Total | M29: =SUM(M26:M28) -> 177.18 | O29: =SUM(O26:O28) -> 3639.6786
H32: Taboão - Nov | I32: Taboão - Atrasos Novembro - Vigilância
I33: Função | J33: Escala | K33: Horário Entrada Contratual | L33: Horário Saída Contratual | M33: Quantidade de horas de falta | N33: Valor hora/falta | O33: Valor Total Falta
I34: Vigilante Condutor Armado | J34: 12x36 | K34: 0.29166667 | L34: 0.79166667 | M34: 12 | N34: 28.65 | O34: =M34*N34 -> 343.8
I35: vigilante armado | J35: 12x36 | K35: 0.41666667 | L35: 0.91666667 | M35: 6.5 | N35: 26.83 | O35: =M35*N35 -> 174.395
I36: Vigilante Condutor Armado | J36: 12x36 | K36: 0.79166667 | L36: 0.29166667 | M36: 13.45 | N36: 31.56 | O36: =M36*N36 -> 424.482
I37: Vigilante Condutor Armado | J37: 12x36 | K37: 0.5 | L37: 0 | M37: 0 | N37: 29.62 | O37: =M37*N37 -> 0
I38: Vigilante Líder | J38: 12x36 | K38: 0.29166667 | L38: 0.79166667 | M38: 0 | N38: 29.02 | O38: =M38*N38 -> 0
I39: Vigilante Líder | J39: 12x36 | K39: 0.79166667 | L39: 0.29166667 | M39: 0 | N39: 31.97 | O39: =M39*N39 -> 0
I40: Total | M40: =SUM(M34:M39) -> 31.95 | O40: =SUM(O34:O39) -> 942.677 | P40: **
H43: Taboão - Nov | I43: Taboão - Faltas Novembro - Estacionamento
I44: Função | J44: Escala | K44: Horário Entrada Contratual | L44: Horário Saída Contratual | M44: Quantidade de dias de falta | N44: Valor Desconto Falta | O44: Valor Total Falta
I45: Orientador de acesso | J45: 5x1 | K45: 0.25 | L45: 0.59722222 | N45: 127.89 | O45: =M45*N45 -> 0
I46: Orientador de acesso | J46: 5x1 | K46: 0.29166667 | L46: 0.63888889 | N46: 127.89 | O46: =M46*N46 -> 0
I47: Orientador de acesso | J47: 5x1 | K47: 0.5 | L47: 0.84722222 | N47: 127.89 | O47: =M47*N47 -> 0
I48: Orientador de acesso | J48: 5x1 | K48: 0.58333333 | L48: 0.93055556 | N48: 129.01 | O48: =M48*N48 -> 0
I49: Orientador de acesso | J49: 5x1 | K49: 0.625 | L49: 0.97222222 | M49: 1 | N49: 132.39 | O49: =M49*N49 -> 132.39
I50: Operador de CFTV* | J50: 5x1 | K50: 0.33333333 | L50: 0.68055556 | N50: 152.83 | O50: =M50*N50 -> 0
I51: Operador de CFTV* | J51: 5x1 | K51: 0.625 | L51: 0.97222222 | N51: 158.37 | O51: =M51*N51 -> 0
I52: Operador CFTV Líder | J52: 5x1 | K52: 0.5 | L52: 0.84722222 | N52: 179.4 | O52: =M52*N52 -> 0
...

Sheet Infos Relatório
C1: 45292 | I1: 45323 | O1: 45352 | U1: 45383 | AA1: 45413 | AG1: 45444 | AM1: 45474 | AS1: 45505 | AY1: 45536 | BE1: 45566 | BK1: 45597 | BQ1: 45627
B2: Limpeza | C2: =C1 -> 45292 | I2: =I1 -> 45323 | O2: =O1 -> 45352 | U2: =U1 -> 45383 | AA2: =AA1 -> 45413 | AG2: =AG1 -> 45444 | AM2: =AM1 -> 45474 | AS2: =AS1 -> 45505 | AY2: =AY1 -> 45536 | BE2: =BE1 -> 45566 | BK2: =BK1 -> 45597 | BQ2: =BQ1 -> 45627
B3: Fornecedor | C3: Qtd Shopping | D3: HC Total | E3: Valor total contrato | F3: Desconto SLA Total | G3: Desconto médio % | H3: QTD de faltas | I3: Qtd Shopping | J3: HC Total | K3: Valor total contrato | L3: Desconto SLA Total | M3: Desconto médio % | N3: QTD de faltas | O3: Qtd Shopping | P3: HC Total | Q3: Valor total contrato | R3: Desconto SLA Total | S3: Desconto médio % | T3: QTD de faltas | U3: Qtd Shopping | V3: HC Total | W3: Valor total contrato | X3: Desconto SLA Total | Y3: Desconto médio % | Z3: QTD de faltas | AA3: Qtd Shopping | AB3: HC Total | AC3: Valor total contrato | AD3: Desconto SLA Total | AE3: Desconto médio % | AF3: QTD de faltas | AG3: Qtd Shopping | AH3: HC Total | AI3: Valor total contrato | AJ3: Desconto SLA Total | AK3: Desconto médio % | AL3: QTD de faltas | AM3: Qtd Shopping | AN3: HC Total | AO3: Valor total contrato | AP3: Desconto SLA Total | AQ3: Desconto médio % | AR3: QTD de faltas | AS3: Qtd Shopping | AT3: HC Total | AU3: Valor total contrato | AV3: Desconto SLA Total | AW3: Desconto médio % | AX3: QTD de faltas | AY3: Qtd Shopping | AZ3: HC Total | BA3: Valor total contrato | BB3: Desconto SLA Total | BC3: Desconto médio % | BD3: QTD de faltas | BE3: Qtd Shopping | BF3: HC Total | BG3: Valor total contrato | BH3: Desconto SLA Total | BI3: Desconto médio % | BJ3: QTD de faltas | BK3: Qtd Shopping | BL3: HC Total | BM3: Valor total contrato | BN3: Desconto SLA Total | BO3: Desconto médio % | BP3: QTD de faltas | BQ3: Qtd Shopping | BR3: HC Total | BS3: Valor total contrato | BT3: Desconto SLA Total | BU3: Desconto médio % | BV3: QTD de faltas
B4: Action Fire | C4: =COUNTIFS('Faturamento NNE'!$E$2:$E$707,'Infos Relatório'!$B$2,'Faturamento NNE'!$F$2:$F$707,'Infos Relatório'!$B4,'Faturamento NNE'!$AA$2:$AA$707,'Infos Relatório'!C$1) -> 0 | D4: =SUMIFS('Faturamento NNE'!$H$2:$H$707,'Faturamento NNE'!$E$2:$E$707,'Infos Relatório'!$B$2,'Faturamento NNE'!$F$2:$F$707,'Infos Relatório'!$B4,'Faturamento NNE'!$AA$2:$AA$707,'Infos Relatório'!C$1) -> 0 | E4: =SUMIFS('Faturamento NNE'!$K$2:$K$707,'Faturamento NNE'!$E$2:$E$707,'Infos Relatório'!$B$2,'Faturamento NNE'!$F$2:$F$707,'Infos Relatório'!$B4,'Faturamento NNE'!$AA$2:$AA$707,'Infos Relatório'!C$1) -> 0 | F4: =SUMIFS('Faturamento NNE'!$P$2:$P$707,'Faturamento NNE'!$E$2:$E$707,'Infos Relatório'!$B$2,'Faturamento NNE'!$F$2:$F$707,'Infos Relatório'!$B4,'Faturamento NNE'!$AA$2:$AA$707,'Infos Relatório'!C$1,'Faturamento NNE'!$U$2:$U$707,"Sim")+SUMIFS('Faturamento NNE'!$Q$2:$Q$707,'Faturamento NNE'!$E$2:$E$707,'Infos Relatório'!$B$2,'Faturamento NNE'!$F$2:$F$707,'Infos Relatório'!$B4,'Faturamento NNE'!$AA$2:$AA$707,'Infos Relatório'!C$1,'Faturamento NNE'!$U$2:$U$707,"Sim") -> 0 | G4: =F4/E4 -> #DIV/0! | H4: =SUMIFS('Faturamento NNE'!$I$2:$I$707,'Faturamento NNE'!$E$2:$E$707,'Infos Relatório'!$B$2,'Faturamento NNE'!$F$2:$F$707,'Infos Relatório'!$B4,'Faturamento NNE'!$AA$2:$AA$707,'Infos Relatório'!C$1) -> 0 | I4: =COUNTIFS('Faturamento NNE'!$E$2:$E$707,'Infos Relatório'!$B$2,'Faturamento NNE'!$F$2:$F$707,'Infos Relatório'!$B4,'Faturamento NNE'!$AA$2:$AA$707,'Infos Relatório'!I$1) -> 0 | J4: =SUMIFS('Faturamento NNE'!$H$2:$H$707,'Faturamento NNE'!$E$2:$E$707,'Infos Relatório'!$B$2,'Faturamento NNE'!$F$2:$F$707,'Infos Relatório'!$B4,'Faturamento NNE'!$AA$2:$AA$707,'Infos Relatório'!I$1) -> 0 | K4: =SUMIFS('Faturamento NNE'!$K$2:$K$707,'Faturamento NNE'!$E$2:$E$707,'Infos Relatório'!$B$2,'Faturamento NNE'!$F$2:$F$707,'Infos Relatório'!$B4,'Faturamento NNE'!$AA$2:$AA$707,'Infos Relatório'!I$1) -> 0 | L4: =SUMIFS('Faturamento NNE'!$P$2:$P$707,'Faturamento NNE'!$E$2:$E$707,'Infos Relatório'!$B$2,'Faturamento NNE'!$F$2:$F$707,'Infos Relatório'!$B4,'Faturamento NNE'!$AA$2:$AA$707,'Infos Relatório'!I$1,'Faturamento NNE'!$U$2:$U$707,"Sim")+SUMIFS('Faturamento NNE'!$Q$2:$Q$707,'Faturamento NNE'!$E$2:$E$707,'Infos Relatório'!$B$2,'Faturamento NNE'!$F$2:$F$707,'Infos Relatório'!$B4,'Faturamento NNE'!$AA$2:$AA$707,'Infos Relatório'!I$1,'Faturamento NNE'!$U$2:$U$707,"Sim") -> 0 | M4: =L4/K4 -> #DIV/0! | N4: =SUMIFS('Faturamento NNE'!$I$2:$I$707,'Faturamento NNE'!$E$2:$E$707,'Infos Relatório'!$B$2,'Faturamento NNE'!$F$2:$F$707,'Infos Relatório'!$B4,'Faturamento NNE'!$AA$2:$AA$707,'Infos Relatório'!I$1) -> 0 | O4: =COUNTIFS('Faturamento NNE'!$E$2:$E$707,'Infos Relatório'!$B$2,'Faturamento NNE'!$F$2:$F$707,'Infos Relatório'!$B4,'Faturamento NNE'!$AA$2:$AA$707,'Infos Relatório'!O$1) -> 0 | P4: =SUMIFS('Faturamento NNE'!$H$2:$H$707,'Faturamento NNE'!$E$2:$E$707,'Infos Relatório'!$B$2,'Faturamento NNE'!$F$2:$F$707,'Infos Relatório'!$B4,'Faturamento NNE'!$AA$2:$AA$707,'Infos Relatório'!O$1) -> 0 | Q4: =SUMIFS('Faturamento NNE'!$K$2:$K$707,'Faturamento NNE'!$E$2:$E$707,'Infos Relatório'!$B$2,'Faturamento NNE'!$F$2:$F$707,'Infos Relatório'!$B4,'Faturamento NNE'!$AA$2:$AA$707,'Infos Relatório'!O$1) -> 0 | R4: =SUMIFS('Faturamento NNE'!$P$2:$P$707,'Faturamento NNE'!$E$2:$E$707,'Infos Relatório'!$B$2,'Faturamento NNE'!$F$2:$F$707,'Infos Relatório'!$B4,'Faturamento NNE'!$AA$2:$AA$707,'Infos Relatório'!O$1,'Faturamento NNE'!$U$2:$U$707,"Sim")+SUMIFS('Faturamento NNE'!$Q$2:$Q$707,'Faturamento NNE'!$E$2:$E$707,'Infos Relatório'!$B$2,'Faturamento NNE'!$F$2:$F$707,'Infos Relatório'!$B4,'Faturamento NNE'!$AA$2:$AA$707,'Infos Relatório'!O$1,'Faturamento NNE'!$U$2:$U$707,"Sim") -> 0 | S4: =R4/Q4 -> #DIV/0! | T4: =SUMIFS('Faturamento NNE'!$I$2:$I$707,'Faturamento NNE'!$E$2:$E$707,'Infos Relatório'!$B$2,'Faturamento NNE'!$F$2:$F$707,'Infos Relatório'!$B4,'Faturamento NNE'!$AA$2:$AA$707,'Infos Relatório'!O$1) -> 0 | U4: =COUNTIFS('Faturamento NNE'!$E$2:$E$707,'Infos Relatório'!$B$2,'Faturamento NNE'!$F$2:$F$707,'Infos Relatório'!$B4,'Faturamento NNE'!$AA$2:$AA$707,'Infos Relatório'!U$1) -> 0 | V4: =SUMIFS('Faturamento NNE'!$H$2:$H$707,'Faturamento NNE'!$E$2:$E$707,'Infos Relatório'!$B$2,'Faturamento NNE'!$F$2:$F$707,'Infos Relatório'!$B4,'Faturamento NNE'!$AA$2:$AA$707,'Infos Relatório'!U$1) -> 0 | W4: =SUMIFS('Faturamento NNE'!$K$2:$K$707,'Faturamento NNE'!$E$2:$E$707,'Infos Relatório'!$B$2,'Faturamento NNE'!$F$2:$F$707,'Infos Relatório'!$B4,'Faturamento NNE'!$AA$2:$AA$707,'Infos Relatório'!U$1) -> 0 | X4: =SUMIFS('Faturamento NNE'!$P$2:$P$707,'Faturamento NNE'!$E$2:$E$707,'Infos Relatório'!$B$2,'Faturamento NNE'!$F$2:$F$707,'Infos Relatório'!$B4,'Faturamento NNE'!$AA$2:$AA$707,'Infos Relatório'!U$1,'Faturamento NNE'!$U$2:$U$707,"Sim")+SUMIFS('Faturamento NNE'!$Q$2:$Q$707,'Faturamento NNE'!$E$2:$E$707,'Infos Relatório'!$B$2,'Faturamento NNE'!$F$2:$F$707,'Infos Relatório'!$B4,'Faturamento NNE'!$AA$2:$AA$707,'Infos Relatório'!U$1,'Faturamento NNE'!$U$2:$U$707,"Sim") -> 0 | Y4: =X4/W4 -> #DIV/0! | Z4: =SUMIFS('Faturamento NNE'!$I$2:$I$707,'Faturamento NNE'!$E$2:$E$707,'Infos Relatório'!$B$2,'Faturamento NNE'!$F$2:$F$707,'Infos Relatório'!$B4,'Faturamento NNE'!$AA$2:$AA$707,'Infos Relatório'!U$1) -> 0 | AA4: =COUNTIFS('Faturamento NNE'!$E$2:$E$707,'Infos Relatório'!$B$2,'Faturamento NNE'!$F$2:$F$707,'Infos Relatório'!$B4,'Faturamento NNE'!$AA$2:$AA$707,'Infos Relatório'!AA$1) -> 0 | AB4: =SUMIFS('Faturamento NNE'!$H$2:$H$707,'Faturamento NNE'!$E$2:$E$707,'Infos Relatório'!$B$2,'Faturamento NNE'!$F$2:$F$707,'Infos Relatório'!$B4,'Faturamento NNE'!$AA$2:$AA$707,'Infos Relatório'!AA$1) -> 0 | AC4: =SUMIFS('Faturamento NNE'!$K$2:$K$707,'Faturamento NNE'!$E$2:$E$707,'Infos Relatório'!$B$2,'Faturamento NNE'!$F$2:$F$707,'Infos Relatório'!$B4,'Faturamento NNE'!$AA$2:$AA$707,'Infos Relatório'!AA$1) -> 0 | AD4: =SUMIFS('Faturamento NNE'!$P$2:$P$707,'Faturamento NNE'!$E$2:$E$707,'Infos Relatório'!$B$2,'Faturamento NNE'!$F$2:$F$707,'Infos Relatório'!$B4,'Faturamento NNE'!$AA$2:$AA$707,'Infos Relatório'!AA$1,'Faturamento NNE'!$U$2:$U$707,"Sim")+SUMIFS('Faturamento NNE'!$Q$2:$Q$707,'Faturamento NNE'!$E$2:$E$707,'Infos Relatório'!$B$2,'Faturamento NNE'!$F$2:$F$707,'Infos Relatório'!$B4,'Faturamento NNE'!$AA$2:$AA$707,'Infos Relatório'!AA$1,'Faturamento NNE'!$U$2:$U$707,"Sim") -> 0 | AE4: =AD4/AC4 -> #DIV/0! | AF4: =SUMIFS('Faturamento NNE'!$I$2:$I$707,'Faturamento NNE'!$E$2:$E$707,'Infos Relatório'!$B$2,'Faturamento NNE'!$F$2:$F$707,'Infos Relatório'!$B4,'Faturamento NNE'!$AA$2:$AA$707,'Infos Relatório'!AA$1) -> 0 | AG4: =COUNTIFS('Faturamento NNE'!$E$2:$E$707,'Infos Relatório'!$B$2,'Faturamento NNE'!$F$2:$F$707,'Infos Relatório'!$B4,'Faturamento NNE'!$AA$2:$AA$707,'Infos Relatório'!AG$1) -> 0 | AH4: =SUMIFS('Faturamento NNE'!$H$2:$H$707,'Faturamento NNE'!$E$2:$E$707,'Infos Relatório'!$B$2,'Faturamento NNE'!$F$2:$F$707,'Infos Relatório'!$B4,'Faturamento NNE'!$AA$2:$AA$707,'Infos Relatório'!AG$1) -> 0 | AI4: =SUMIFS('Faturamento NNE'!$K$2:$K$707,'Faturamento NNE'!$E$2:$E$707,'Infos Relatório'!$B$2,'Faturamento NNE'!$F$2:$F$707,'Infos Relatório'!$B4,'Faturamento NNE'!$AA$2:$AA$707,'Infos Relatório'!AG$1) -> 0 | AJ4: =SUMIFS('Faturamento NNE'!$P$2:$P$707,'Faturamento NNE'!$E$2:$E$707,'Infos Relatório'!$B$2,'Faturamento NNE'!$F$2:$F$707,'Infos Relatório'!$B4,'Faturamento NNE'!$AA$2:$AA$707,'Infos Relatório'!AG$1,'Faturamento NNE'!$U$2:$U$707,"Sim")+SUMIFS('Faturamento NNE'!$Q$2:$Q$707,'Faturamento NNE'!$E$2:$E$707,'Infos Relatório'!$B$2,'Faturamento NNE'!$F$2:$F$707,'Infos Relatório'!$B4,'Faturamento NNE'!$AA$2:$AA$707,'Infos Relatório'!AG$1,'Faturamento NNE'!$U$2:$U$707,"Sim") -> 0 | AK4: =AJ4/AI4 -> #DIV/0! | AL4: =SUMIFS('Faturamento NNE'!$I$2:$I$707,'Faturamento NNE'!$E$2:$E$707,'Infos Relatório'!$B$2,'Faturamento NNE'!$F$2:$F$707,'Infos Relatório'!$B4,'Faturamento NNE'!$AA$2:$AA$707,'Infos Relatório'!AG$1) -> 0 | AM4: =COUNTIFS('Faturamento NNE'!$E$2:$E$707,'Infos Relatório'!$B$2,'Faturamento NNE'!$F$2:$F$707,'Infos Relatório'!$B4,'Faturamento NNE'!$AA$2:$AA$707,'Infos Relatório'!AM$1) -> 0 | AN4: =SUMIFS('Faturamento NNE'!$H$2:$H$707,'Faturamento NNE'!$E$2:$E$707,'Infos Relatório'!$B$2,'Faturamento NNE'!$F$2:$F$707,'Infos Relatório'!$B4,'Faturamento NNE'!$AA$2:$AA$707,'Infos Relatório'!AM$1) -> 0 | AO4: =SUMIFS('Faturamento NNE'!$K$2:$K$707,'Faturamento NNE'!$E$2:$E$707,'Infos Relatório'!$B$2,'Faturamento NNE'!$F$2:$F$707,'Infos Relatório'!$B4,'Faturamento NNE'!$AA$2:$AA$707,'Infos Relatório'!AM$1) -> 0 | AP4: =SUMIFS('Faturamento NNE'!$P$2:$P$707,'Faturamento NNE'!$E$2:$E$707,'Infos Relatório'!$B$2,'Faturamento NNE'!$F$2:$F$707,'Infos Relatório'!$B4,'Faturamento NNE'!$AA$2:$AA$707,'Infos Relatório'!AM$1,'Faturamento NNE'!$U$2:$U$707,"Sim")+SUMIFS('Faturamento NNE'!$Q$2:$Q$707,'Faturamento NNE'!$E$2:$E$707,'Infos Relatório'!$B$2,'Faturamento NNE'!$F$2:$F$707,'Infos Relatório'!$B4,'Faturamento NNE'!$AA$2:$AA$707,'Infos Relatório'!AM$1,'Faturamento NNE'!$U$2:$U$707,"Sim") -> 0 | AQ4: =AP4/AO4 -> #DIV/0! | AR4: =SUMIFS('Faturamento NNE'!$I$2:$I$707,'Faturamento NNE'!$E$2:$E$707,'Infos Relatório'!$B$2,'Faturamento NNE'!$F$2:$F$707,'Infos Relatório'!$B4,'Faturamento NNE'!$AA$2:$AA$707,'Infos Relatório'!AM$1) -> 0 | AS4: =COUNTIFS('Faturamento NNE'!$E$2:$E$707,'Infos Relatório'!$B$2,'Faturamento NNE'!$F$2:$F$707,'Infos Relatório'!$B4,'Faturamento NNE'!$AA$2:$AA$707,'Infos Relatório'!AS$1) -> 0 | AT4: =SUMIFS('Faturamento NNE'!$H$2:$H$707,'Faturamento NNE'!$E$2:$E$707,'Infos Relatório'!$B$2,'Faturamento NNE'!$F$2:$F$707,'Infos Relatório'!$B4,'Faturamento NNE'!$AA$2:$AA$707,'Infos Relatório'!AS$1) -> 0 | AU4: =SUMIFS('Faturamento NNE'!$K$2:$K$707,'Faturamento NNE'!$E$2:$E$707,'Infos Relatório'!$B$2,'Faturamento NNE'!$F$2:$F$707,'Infos Relatório'!$B4,'Faturamento NNE'!$AA$2:$AA$707,'Infos Relatório'!AS$1) -> 0 | AV4: =SUMIFS('Faturamento NNE'!$P$2:$P$707,'Faturamento NNE'!$E$2:$E$707,'Infos Relatório'!$B$2,'Faturamento NNE'!$F$2:$F$707,'Infos Relatório'!$B4,'Faturamento NNE'!$AA$2:$AA$707,'Infos Relatório'!AS$1,'Faturamento NNE'!$U$2:$U$707,"Sim")+SUMIFS('Faturamento NNE'!$Q$2:$Q$707,'Faturamento NNE'!$E$2:$E$707,'Infos Relatório'!$B$2,'Faturamento NNE'!$F$2:$F$707,'Infos Relatório'!$B4,'Faturamento NNE'!$AA$2:$AA$707,'Infos Relatório'!AS$1,'Faturamento NNE'!$U$2:$U$707,"Sim") -> 0 | AW4: =AV4/AU4 -> #DIV/0! | AX4: =SUMIFS('Faturamento NNE'!$I$2:$I$707,'Faturamento NNE'!$E$2:$E$707,'Infos Relatório'!$B$2,'Faturamento NNE'!$F$2:$F$707,'Infos Relatório'!$B4,'Faturamento NNE'!$AA$2:$AA$707,'Infos Relatório'!AS$1) -> 0 | AY4: =COUNTIFS('Faturamento NNE'!$E$2:$E$707,'Infos Relatório'!$B$2,'Faturamento NNE'!$F$2:$F$707,'Infos Relatório'!$B4,'Faturamento NNE'!$AA$2:$AA$707,'Infos Relatório'!AY$1) -> 0 | AZ4: =SUMIFS('Faturamento NNE'!$H$2:$H$707,'Faturamento NNE'!$E$2:$E$707,'Infos Relatório'!$B$2,'Faturamento NNE'!$F$2:$F$707,'Infos Relatório'!$B4,'Faturamento NNE'!$AA$2:$AA$707,'Infos Relatório'!AY$1) -> 0 | BA4: =SUMIFS('Faturamento NNE'!$K$2:$K$707,'Faturamento NNE'!$E$2:$E$707,'Infos Relatório'!$B$2,'Faturamento NNE'!$F$2:$F$707,'Infos Relatório'!$B4,'Faturamento NNE'!$AA$2:$AA$707,'Infos Relatório'!AY$1) -> 0 | BB4: =SUMIFS('Faturamento NNE'!$P$2:$P$707,'Faturamento NNE'!$E$2:$E$707,'Infos Relatório'!$B$2,'Faturamento NNE'!$F$2:$F$707,'Infos Relatório'!$B4,'Faturamento NNE'!$AA$2:$AA$707,'Infos Relatório'!AY$1,'Faturamento NNE'!$U$2:$U$707,"Sim")+SUMIFS('Faturamento NNE'!$Q$2:$Q$707,'Faturamento NNE'!$E$2:$E$707,'Infos Relatório'!$B$2,'Faturamento NNE'!$F$2:$F$707,'Infos Relatório'!$B4,'Faturamento NNE'!$AA$2:$AA$707,'Infos Relatório'!AY$1,'Faturamento NNE'!$U$2:$U$707,"Sim") -> 0 | BC4: =BB4/BA4 -> #DIV/0! | BD4: =SUMIFS('Faturamento NNE'!$I$2:$I$707,'Faturamento NNE'!$E$2:$E$707,'Infos Relatório'!$B$2,'Faturamento NNE'!$F$2:$F$707,'Infos Relatório'!$B4,'Faturamento NNE'!$AA$2:$AA$707,'Infos Relatório'!AY$1) -> 0 | BE4: =COUNTIFS('Faturamento NNE'!$E$2:$E$707,'Infos Relatório'!$B$2,'Faturamento NNE'!$F$2:$F$707,'Infos Relatório'!$B4,'Faturamento NNE'!$AA$2:$AA$707,'Infos Relatório'!BE$1) -> 0 | BF4: =SUMIFS('Faturamento NNE'!$H$2:$H$707,'Faturamento NNE'!$E$2:$E$707,'Infos Relatório'!$B$2,'Faturamento NNE'!$F$2:$F$707,'Infos Relatório'!$B4,'Faturamento NNE'!$AA$2:$AA$707,'Infos Relatório'!BE$1) -> 0 | BG4: =SUMIFS('Faturamento NNE'!$K$2:$K$707,'Faturamento NNE'!$E$2:$E$707,'Infos Relatório'!$B$2,'Faturamento NNE'!$F$2:$F$707,'Infos Relatório'!$B4,'Faturamento NNE'!$AA$2:$AA$707,'Infos Relatório'!BE$1) -> 0 | BH4: =SUMIFS('Faturamento NNE'!$P$2:$P$707,'Faturamento NNE'!$E$2:$E$707,'Infos Relatório'!$B$2,'Faturamento NNE'!$F$2:$F$707,'Infos Relatório'!$B4,'Faturamento NNE'!$AA$2:$AA$707,'Infos Relatório'!BE$1,'Faturamento NNE'!$U$2:$U$707,"Sim")+SUMIFS('Faturamento NNE'!$Q$2:$Q$707,'Faturamento NNE'!$E$2:$E$707,'Infos Relatório'!$B$2,'Faturamento NNE'!$F$2:$F$707,'Infos Relatório'!$B4,'Faturamento NNE'!$AA$2:$AA$707,'Infos Relatório'!BE$1,'Faturamento NNE'!$U$2:$U$707,"Sim") -> 0 | BI4: =BH4/BG4 -> #DIV/0! | BJ4: =SUMIFS('Faturamento NNE'!$I$2:$I$707,'Faturamento NNE'!$E$2:$E$707,'Infos Relatório'!$B$2,'Faturamento NNE'!$F$2:$F$707,'Infos Relatório'!$B4,'Faturamento NNE'!$AA$2:$AA$707,'Infos Relatório'!BE$1) -> 0 | BK4: =COUNTIFS('Faturamento NNE'!$E$2:$E$707,'Infos Relatório'!$B$2,'Faturamento NNE'!$F$2:$F$707,'Infos Relatório'!$B4,'Faturamento NNE'!$AA$2:$AA$707,'Infos Relatório'!BK$1) -> 0 | BL4: =SUMIFS('Faturamento NNE'!$H$2:$H$707,'Faturamento NNE'!$E$2:$E$707,'Infos Relatório'!$B$2,'Faturamento NNE'!$F$2:$F$707,'Infos Relatório'!$B4,'Faturamento NNE'!$AA$2:$AA$707,'Infos Relatório'!BK$1) -> 0 | BM4: =SUMIFS('Faturamento NNE'!$K$2:$K$707,'Faturamento NNE'!$E$2:$E$707,'Infos Relatório'!$B$2,'Faturamento NNE'!$F$2:$F$707,'Infos Relatório'!$B4,'Faturamento NNE'!$AA$2:$AA$707,'Infos Relatório'!BK$1) -> 0 | BN4: =SUMIFS('Faturamento NNE'!$P$2:$P$707,'Faturamento NNE'!$E$2:$E$707,'Infos Relatório'!$B$2,'Faturamento NNE'!$F$2:$F$707,'Infos Relatório'!$B4,'Faturamento NNE'!$AA$2:$AA$707,'Infos Relatório'!BK$1,'Faturamento NNE'!$U$2:$U$707,"Sim")+SUMIFS('Faturamento NNE'!$Q$2:$Q$707,'Faturamento NNE'!$E$2:$E$707,'Infos Relatório'!$B$2,'Faturamento NNE'!$F$2:$F$707,'Infos Relatório'!$B4,'Faturamento NNE'!$AA$2:$AA$707,'Infos Relatório'!BK$1,'Faturamento NNE'!$U$2:$U$707,"Sim") -> 0 | BO4: =BN4/BM4 -> #DIV/0! | BP4: =SUMIFS('Faturamento NNE'!$I$2:$I$707,'Faturamento NNE'!$E$2:$E$707,'Infos Relatório'!$B$2,'Faturamento NNE'!$F$2:$F$707,'Infos Relatório'!$B4,'Faturamento NNE'!$AA$2:$AA$707,'Infos Relatório'!BK$1) -> 0 | BQ4: =COUNTIFS('Faturamento NNE'!$E$2:$E$707,'Infos Relatório'!$B$2,'Faturamento NNE'!$F$2:$F$707,'Infos Relatório'!$B4,'Faturamento NNE'!$AA$2:$AA$707,'Infos Relatório'!BQ$1) -> 0 | BR4: =SUMIFS('Faturamento NNE'!$H$2:$H$707,'Faturamento NNE'!$E$2:$E$707,'Infos Relatório'!$B$2,'Faturamento NNE'!$F$2:$F$707,'Infos Relatório'!$B4,'Faturamento NNE'!$AA$2:$AA$707,'Infos Relatório'!BQ$1) -> 0 | BS4: =SUMIFS('Faturamento NNE'!$K$2:$K$707,'Faturamento NNE'!$E$2:$E$707,'Infos Relatório'!$B$2,'Faturamento NNE'!$F$2:$F$707,'Infos Relatório'!$B4,'Faturamento NNE'!$AA$2:$AA$707,'Infos Relatório'!BQ$1) -> 0 | BT4: =SUMIFS('Faturamento NNE'!$P$2:$P$707,'Faturamento NNE'!$E$2:$E$707,'Infos Relatório'!$B$2,'Faturamento NNE'!$F$2:$F$707,'Infos Relatório'!$B4,'Faturamento NNE'!$AA$2:$AA$707,'Infos Relatório'!BQ$1,'Faturamento NNE'!$U$2:$U$707,"Sim")+SUMIFS('Faturamento NNE'!$Q$2:$Q$707,'Faturamento NNE'!$E$2:$E$707,'Infos Relatório'!$B$2,'Faturamento NNE'!$F$2:$F$707,'Infos Relatório'!$B4,'Faturamento NNE'!$AA$2:$AA$707,'Infos Relatório'!BQ$1,'Faturamento NNE'!$U$2:$U$707,"Sim") -> 0 | BU4: =BT4/BS4 -> #DIV/0! | BV4: =SUMIFS('Faturamento NNE'!$I$2:$I$707,'Faturamento NNE'!$E$2:$E$707,'Infos Relatório'!$B$2,'Faturamento NNE'!$F$2:$F$707,'Infos Relatório'!$B4,'Faturamento NNE'!$AA$2:$AA$707,'Infos Relatório'!BQ$1) -> 0
B5: Agro Rio | C5: =COUNTIFS('Faturamento NNE'!$E$2:$E$707,'Infos Relatório'!$B$2,'Faturamento NNE'!$F$2:$F$707,'Infos Relatório'!$B5,'Faturamento NNE'!$AA$2:$AA$707,'Infos Relatório'!C$1) -> 0 | D5: =SUMIFS('Faturamento NNE'!$H$2:$H$707,'Faturamento NNE'!$E$2:$E$707,'Infos Relatório'!$B$2,'Faturamento NNE'!$F$2:$F$707,'Infos Relatório'!$B5,'Faturamento NNE'!$AA$2:$AA$707,'Infos Relatório'!C$1) -> 0 | E5: =SUMIFS('Faturamento NNE'!$K$2:$K$707,'Faturamento NNE'!$E$2:$E$707,'Infos Relatório'!$B$2,'Faturamento NNE'!$F$2:$F$707,'Infos Relatório'!$B5,'Faturamento NNE'!$AA$2:$AA$707,'Infos Relatório'!C$1) -> 0 | F5: =SUMIFS('Faturamento NNE'!$P$2:$P$707,'Faturamento NNE'!$E$2:$E$707,'Infos Relatório'!$B$2,'Faturamento NNE'!$F$2:$F$707,'Infos Relatório'!$B5,'Faturamento NNE'!$AA$2:$AA$707,'Infos Relatório'!C$1,'Faturamento NNE'!$U$2:$U$707,"Sim")+SUMIFS('Faturamento NNE'!$Q$2:$Q$707,'Faturamento NNE'!$E$2:$E$707,'Infos Relatório'!$B$2,'Faturamento NNE'!$F$2:$F$707,'Infos Relatório'!$B5,'Faturamento NNE'!$AA$2:$AA$707,'Infos Relatório'!C$1,'Faturamento NNE'!$U$2:$U$707,"Sim") -> 0 | G5: =F5/E5 -> #DIV/0! | H5: =SUMIFS('Faturamento NNE'!$I$2:$I$707,'Faturamento NNE'!$E$2:$E$707,'Infos Relatório'!$B$2,'Faturamento NNE'!$F$2:$F$707,'Infos Relatório'!$B5,'Faturamento NNE'!$AA$2:$AA$707,'Infos Relatório'!C$1) -> 0 | I5: =COUNTIFS('Faturamento NNE'!$E$2:$E$707,'Infos Relatório'!$B$2,'Faturamento NNE'!$F$2:$F$707,'Infos Relatório'!$B5,'Faturamento NNE'!$AA$2:$AA$707,'Infos Relatório'!I$1) -> 0 | J5: =SUMIFS('Faturamento NNE'!$H$2:$H$707,'Faturamento NNE'!$E$2:$E$707,'Infos Relatório'!$B$2,'Faturamento NNE'!$F$2:$F$707,'Infos Relatório'!$B5,'Faturamento NNE'!$AA$2:$AA$707,'Infos Relatório'!I$1) -> 0 | K5: =SUMIFS('Faturamento NNE'!$K$2:$K$707,'Faturamento NNE'!$E$2:$E$707,'Infos Relatório'!$B$2,'Faturamento NNE'!$F$2:$F$707,'Infos Relatório'!$B5,'Faturamento NNE'!$AA$2:$AA$707,'Infos Relatório'!I$1) -> 0 | L5: =SUMIFS('Faturamento NNE'!$P$2:$P$707,'Faturamento NNE'!$E$2:$E$707,'Infos Relatório'!$B$2,'Faturamento NNE'!$F$2:$F$707,'Infos Relatório'!$B5,'Faturamento NNE'!$AA$2:$AA$707,'Infos Relatório'!I$1,'Faturamento NNE'!$U$2:$U$707,"Sim")+SUMIFS('Faturamento NNE'!$Q$2:$Q$707,'Faturamento NNE'!$E$2:$E$707,'Infos Relatório'!$B$2,'Faturamento NNE'!$F$2:$F$707,'Infos Relatório'!$B5,'Faturamento NNE'!$AA$2:$AA$707,'Infos Relatório'!I$1,'Faturamento NNE'!$U$2:$U$707,"Sim") -> 0 | M5: =L5/K5 -> #DIV/0! | N5: =SUMIFS('Faturamento NNE'!$I$2:$I$707,'Faturamento NNE'!$E$2:$E$707,'Infos Relatório'!$B$2,'Faturamento NNE'!$F$2:$F$707,'Infos Relatório'!$B5,'Faturamento NNE'!$AA$2:$AA$707,'Infos Relatório'!I$1) -> 0 | O5: =COUNTIFS('Faturamento NNE'!$E$2:$E$707,'Infos Relatório'!$B$2,'Faturamento NNE'!$F$2:$F$707,'Infos Relatório'!$B5,'Faturamento NNE'!$AA$2:$AA$707,'Infos Relatório'!O$1) -> 0 | P5: =SUMIFS('Faturamento NNE'!$H$2:$H$707,'Faturamento NNE'!$E$2:$E$707,'Infos Relatório'!$B$2,'Faturamento NNE'!$F$2:$F$707,'Infos Relatório'!$B5,'Faturamento NNE'!$AA$2:$AA$707,'Infos Relatório'!O$1) -> 0 | Q5: =SUMIFS('Faturamento NNE'!$K$2:$K$707,'Faturamento NNE'!$E$2:$E$707,'Infos Relatório'!$B$2,'Faturamento NNE'!$F$2:$F$707,'Infos Relatório'!$B5,'Faturamento NNE'!$AA$2:$AA$707,'Infos Relatório'!O$1) -> 0 | R5: =SUMIFS('Faturamento NNE'!$P$2:$P$707,'Faturamento NNE'!$E$2:$E$707,'Infos Relatório'!$B$2,'Faturamento NNE'!$F$2:$F$707,'Infos Relatório'!$B5,'Faturamento NNE'!$AA$2:$AA$707,'Infos Relatório'!O$1,'Faturamento NNE'!$U$2:$U$707,"Sim")+SUMIFS('Faturamento NNE'!$Q$2:$Q$707,'Faturamento NNE'!$E$2:$E$707,'Infos Relatório'!$B$2,'Faturamento NNE'!$F$2:$F$707,'Infos Relatório'!$B5,'Faturamento NNE'!$AA$2:$AA$707,'Infos Relatório'!O$1,'Faturamento NNE'!$U$2:$U$707,"Sim") -> 0 | S5: =R5/Q5 -> #DIV/0! | T5: =SUMIFS('Faturamento NNE'!$I$2:$I$707,'Faturamento NNE'!$E$2:$E$707,'Infos Relatório'!$B$2,'Faturamento NNE'!$F$2:$F$707,'Infos Relatório'!$B5,'Faturamento NNE'!$AA$2:$AA$707,'Infos Relatório'!O$1) -> 0 | U5: =COUNTIFS('Faturamento NNE'!$E$2:$E$707,'Infos Relatório'!$B$2,'Faturamento NNE'!$F$2:$F$707,'Infos Relatório'!$B5,'Faturamento NNE'!$AA$2:$AA$707,'Infos Relatório'!U$1) -> 0 | V5: =SUMIFS('Faturamento NNE'!$H$2:$H$707,'Faturamento NNE'!$E$2:$E$707,'Infos Relatório'!$B$2,'Faturamento NNE'!$F$2:$F$707,'Infos Relatório'!$B5,'Faturamento NNE'!$AA$2:$AA$707,'Infos Relatório'!U$1) -> 0 | W5: =SUMIFS('Faturamento NNE'!$K$2:$K$707,'Faturamento NNE'!$E$2:$E$707,'Infos Relatório'!$B$2,'Faturamento NNE'!$F$2:$F$707,'Infos Relatório'!$B5,'Faturamento NNE'!$AA$2:$AA$707,'Infos Relatório'!U$1) -> 0 | X5: =SUMIFS('Faturamento NNE'!$P$2:$P$707,'Faturamento NNE'!$E$2:$E$707,'Infos Relatório'!$B$2,'Faturamento NNE'!$F$2:$F$707,'Infos Relatório'!$B5,'Faturamento NNE'!$AA$2:$AA$707,'Infos Relatório'!U$1,'Faturamento NNE'!$U$2:$U$707,"Sim")+SUMIFS('Faturamento NNE'!$Q$2:$Q$707,'Faturamento NNE'!$E$2:$E$707,'Infos Relatório'!$B$2,'Faturamento NNE'!$F$2:$F$707,'Infos Relatório'!$B5,'Faturamento NNE'!$AA$2:$AA$707,'Infos Relatório'!U$1,'Faturamento NNE'!$U$2:$U$707,"Sim") -> 0 | Y5: =X5/W5 -> #DIV/0! | Z5: =SUMIFS('Faturamento NNE'!$I$2:$I$707,'Faturamento NNE'!$E$2:$E$707,'Infos Relatório'!$B$2,'Faturamento NNE'!$F$2:$F$707,'Infos Relatório'!$B5,'Faturamento NNE'!$AA$2:$AA$707,'Infos Relatório'!U$1) -> 0 | AA5: =COUNTIFS('Faturamento NNE'!$E$2:$E$707,'Infos Relatório'!$B$2,'Faturamento NNE'!$F$2:$F$707,'Infos Relatório'!$B5,'Faturamento NNE'!$AA$2:$AA$707,'Infos Relatório'!AA$1) -> 0 | AB5: =SUMIFS('Faturamento NNE'!$H$2:$H$707,'Faturamento NNE'!$E$2:$E$707,'Infos Relatório'!$B$2,'Faturamento NNE'!$F$2:$F$707,'Infos Relatório'!$B5,'Faturamento NNE'!$AA$2:$AA$707,'Infos Relatório'!AA$1) -> 0 | AC5: =SUMIFS('Faturamento NNE'!$K$2:$K$707,'Faturamento NNE'!$E$2:$E$707,'Infos Relatório'!$B$2,'Faturamento NNE'!$F$2:$F$707,'Infos Relatório'!$B5,'Faturamento NNE'!$AA$2:$AA$707,'Infos Relatório'!AA$1) -> 0 | AD5: =SUMIFS('Faturamento NNE'!$P$2:$P$707,'Faturamento NNE'!$E$2:$E$707,'Infos Relatório'!$B$2,'Faturamento NNE'!$F$2:$F$707,'Infos Relatório'!$B5,'Faturamento NNE'!$AA$2:$AA$707,'Infos Relatório'!AA$1,'Faturamento NNE'!$U$2:$U$707,"Sim")+SUMIFS('Faturamento NNE'!$Q$2:$Q$707,'Faturamento NNE'!$E$2:$E$707,'Infos Relatório'!$B$2,'Faturamento NNE'!$F$2:$F$707,'Infos Relatório'!$B5,'Faturamento NNE'!$AA$2:$AA$707,'Infos Relatório'!AA$1,'Faturamento NNE'!$U$2:$U$707,"Sim") -> 0 | AE5: =AD5/AC5 -> #DIV/0! | AF5: =SUMIFS('Faturamento NNE'!$I$2:$I$707,'Faturamento NNE'!$E$2:$E$707,'Infos Relatório'!$B$2,'Faturamento NNE'!$F$2:$F$707,'Infos Relatório'!$B5,'Faturamento NNE'!$AA$2:$AA$707,'Infos Relatório'!AA$1) -> 0 | AG5: =COUNTIFS('Faturamento NNE'!$E$2:$E$707,'Infos Relatório'!$B$2,'Faturamento NNE'!$F$2:$F$707,'Infos Relatório'!$B5,'Faturamento NNE'!$AA$2:$AA$707,'Infos Relatório'!AG$1) -> 0 | AH5: =SUMIFS('Faturamento NNE'!$H$2:$H$707,'Faturamento NNE'!$E$2:$E$707,'Infos Relatório'!$B$2,'Faturamento NNE'!$F$2:$F$707,'Infos Relatório'!$B5,'Faturamento NNE'!$AA$2:$AA$707,'Infos Relatório'!AG$1) -> 0 | AI5: =SUMIFS('Faturamento NNE'!$K$2:$K$707,'Faturamento NNE'!$E$2:$E$707,'Infos Relatório'!$B$2,'Faturamento NNE'!$F$2:$F$707,'Infos Relatório'!$B5,'Faturamento NNE'!$AA$2:$AA$707,'Infos Relatório'!AG$1) -> 0 | AJ5: =SUMIFS('Faturamento NNE'!$P$2:$P$707,'Faturamento NNE'!$E$2:$E$707,'Infos Relatório'!$B$2,'Faturamento NNE'!$F$2:$F$707,'Infos Relatório'!$B5,'Faturamento NNE'!$AA$2:$AA$707,'Infos Relatório'!AG$1,'Faturamento NNE'!$U$2:$U$707,"Sim")+SUMIFS('Faturamento NNE'!$Q$2:$Q$707,'Faturamento NNE'!$E$2:$E$707,'Infos Relatório'!$B$2,'Faturamento NNE'!$F$2:$F$707,'Infos Relatório'!$B5,'Faturamento NNE'!$AA$2:$AA$707,'Infos Relatório'!AG$1,'Faturamento NNE'!$U$2:$U$707,"Sim") -> 0 | AK5: =AJ5/AI5 -> #DIV/0! | AL5: =SUMIFS('Faturamento NNE'!$I$2:$I$707,'Faturamento NNE'!$E$2:$E$707,'Infos Relatório'!$B$2,'Faturamento NNE'!$F$2:$F$707,'Infos Relatório'!$B5,'Faturamento NNE'!$AA$2:$AA$707,'Infos Relatório'!AG$1) -> 0 | AM5: =COUNTIFS('Faturamento NNE'!$E$2:$E$707,'Infos Relatório'!$B$2,'Faturamento NNE'!$F$2:$F$707,'Infos Relatório'!$B5,'Faturamento NNE'!$AA$2:$AA$707,'Infos Relatório'!AM$1) -> 0 | AN5: =SUMIFS('Faturamento NNE'!$H$2:$H$707,'Faturamento NNE'!$E$2:$E$707,'Infos Relatório'!$B$2,'Faturamento NNE'!$F$2:$F$707,'Infos Relatório'!$B5,'Faturamento NNE'!$AA$2:$AA$707,'Infos Relatório'!AM$1) -> 0 | AO5: =SUMIFS('Faturamento NNE'!$K$2:$K$707,'Faturamento NNE'!$E$2:$E$707,'Infos Relatório'!$B$2,'Faturamento NNE'!$F$2:$F$707,'Infos Relatório'!$B5,'Faturamento NNE'!$AA$2:$AA$707,'Infos Relatório'!AM$1) -> 0 | AP5: =SUMIFS('Faturamento NNE'!$P$2:$P$707,'Faturamento NNE'!$E$2:$E$707,'Infos Relatório'!$B$2,'Faturamento NNE'!$F$2:$F$707,'Infos Relatório'!$B5,'Faturamento NNE'!$AA$2:$AA$707,'Infos Relatório'!AM$1,'Faturamento NNE'!$U$2:$U$707,"Sim")+SUMIFS('Faturamento NNE'!$Q$2:$Q$707,'Faturamento NNE'!$E$2:$E$707,'Infos Relatório'!$B$2,'Faturamento NNE'!$F$2:$F$707,'Infos Relatório'!$B5,'Faturamento NNE'!$AA$2:$AA$707,'Infos Relatório'!AM$1,'Faturamento NNE'!$U$2:$U$707,"Sim") -> 0 | AQ5: =AP5/AO5 -> #DIV/0! | AR5: =SUMIFS('Faturamento NNE'!$I$2:$I$707,'Faturamento NNE'!$E$2:$E$707,'Infos Relatório'!$B$2,'Faturamento NNE'!$F$2:$F$707,'Infos Relatório'!$B5,'Faturamento NNE'!$AA$2:$AA$707,'Infos Relatório'!AM$1) -> 0 | AS5: =COUNTIFS('Faturamento NNE'!$E$2:$E$707,'Infos Relatório'!$B$2,'Faturamento NNE'!$F$2:$F$707,'Infos Relatório'!$B5,'Faturamento NNE'!$AA$2:$AA$707,'Infos Relatório'!AS$1) -> 0 | AT5: =SUMIFS('Faturamento NNE'!$H$2:$H$707,'Faturamento NNE'!$E$2:$E$707,'Infos Relatório'!$B$2,'Faturamento NNE'!$F$2:$F$707,'Infos Relatório'!$B5,'Faturamento NNE'!$AA$2:$AA$707,'Infos Relatório'!AS$1) -> 0 | AU5: =SUMIFS('Faturamento NNE'!$K$2:$K$707,'Faturamento NNE'!$E$2:$E$707,'Infos Relatório'!$B$2,'Faturamento NNE'!$F$2:$F$707,'Infos Relatório'!$B5,'Faturamento NNE'!$AA$2:$AA$707,'Infos Relatório'!AS$1) -> 0 | AV5: =SUMIFS('Faturamento NNE'!$P$2:$P$707,'Faturamento NNE'!$E$2:$E$707,'Infos Relatório'!$B$2,'Faturamento NNE'!$F$2:$F$707,'Infos Relatório'!$B5,'Faturamento NNE'!$AA$2:$AA$707,'Infos Relatório'!AS$1,'Faturamento NNE'!$U$2:$U$707,"Sim")+SUMIFS('Faturamento NNE'!$Q$2:$Q$707,'Faturamento NNE'!$E$2:$E$707,'Infos Relatório'!$B$2,'Faturamento NNE'!$F$2:$F$707,'Infos Relatório'!$B5,'Faturamento NNE'!$AA$2:$AA$707,'Infos Relatório'!AS$1,'Faturamento NNE'!$U$2:$U$707,"Sim") -> 0 | AW5: =AV5/AU5 -> #DIV/0! | AX5: =SUMIFS('Faturamento NNE'!$I$2:$I$707,'Faturamento NNE'!$E$2:$E$707,'Infos Relatório'!$B$2,'Faturamento NNE'!$F$2:$F$707,'Infos Relatório'!$B5,'Faturamento NNE'!$AA$2:$AA$707,'Infos Relatório'!AS$1) -> 0 | AY5: =COUNTIFS('Faturamento NNE'!$E$2:$E$707,'Infos Relatório'!$B$2,'Faturamento NNE'!$F$2:$F$707,'Infos Relatório'!$B5,'Faturamento NNE'!$AA$2:$AA$707,'Infos Relatório'!AY$1) -> 0 | AZ5: =SUMIFS('Faturamento NNE'!$H$2:$H$707,'Faturamento NNE'!$E$2:$E$707,'Infos Relatório'!$B$2,'Faturamento NNE'!$F$2:$F$707,'Infos Relatório'!$B5,'Faturamento NNE'!$AA$2:$AA$707,'Infos Relatório'!AY$1) -> 0 | BA5: =SUMIFS('Faturamento NNE'!$K$2:$K$707,'Faturamento NNE'!$E$2:$E$707,'Infos Relatório'!$B$2,'Faturamento NNE'!$F$2:$F$707,'Infos Relatório'!$B5,'Faturamento NNE'!$AA$2:$AA$707,'Infos Relatório'!AY$1) -> 0 | BB5: =SUMIFS('Faturamento NNE'!$P$2:$P$707,'Faturamento NNE'!$E$2:$E$707,'Infos Relatório'!$B$2,'Faturamento NNE'!$F$2:$F$707,'Infos Relatório'!$B5,'Faturamento NNE'!$AA$2:$AA$707,'Infos Relatório'!AY$1,'Faturamento NNE'!$U$2:$U$707,"Sim")+SUMIFS('Faturamento NNE'!$Q$2:$Q$707,'Faturamento NNE'!$E$2:$E$707,'Infos Relatório'!$B$2,'Faturamento NNE'!$F$2:$F$707,'Infos Relatório'!$B5,'Faturamento NNE'!$AA$2:$AA$707,'Infos Relatório'!AY$1,'Faturamento NNE'!$U$2:$U$707,"Sim") -> 0 | BC5: =BB5/BA5 -> #DIV/0! | BD5: =SUMIFS('Faturamento NNE'!$I$2:$I$707,'Faturamento NNE'!$E$2:$E$707,'Infos Relatório'!$B$2,'Faturamento NNE'!$F$2:$F$707,'Infos Relatório'!$B5,'Faturamento NNE'!$AA$2:$AA$707,'Infos Relatório'!AY$1) -> 0 | BE5: =COUNTIFS('Faturamento NNE'!$E$2:$E$707,'Infos Relatório'!$B$2,'Faturamento NNE'!$F$2:$F$707,'Infos Relatório'!$B5,'Faturamento NNE'!$AA$2:$AA$707,'Infos Relatório'!BE$1) -> 0 | BF5: =SUMIFS('Faturamento NNE'!$H$2:$H$707,'Faturamento NNE'!$E$2:$E$707,'Infos Relatório'!$B$2,'Faturamento NNE'!$F$2:$F$707,'Infos Relatório'!$B5,'Faturamento NNE'!$AA$2:$AA$707,'Infos Relatório'!BE$1) -> 0 | BG5: =SUMIFS('Faturamento NNE'!$K$2:$K$707,'Faturamento NNE'!$E$2:$E$707,'Infos Relatório'!$B$2,'Faturamento NNE'!$F$2:$F$707,'Infos Relatório'!$B5,'Faturamento NNE'!$AA$2:$AA$707,'Infos Relatório'!BE$1) -> 0 | BH5: =SUMIFS('Faturamento NNE'!$P$2:$P$707,'Faturamento NNE'!$E$2:$E$707,'Infos Relatório'!$B$2,'Faturamento NNE'!$F$2:$F$707,'Infos Relatório'!$B5,'Faturamento NNE'!$AA$2:$AA$707,'Infos Relatório'!BE$1,'Faturamento NNE'!$U$2:$U$707,"Sim")+SUMIFS('Faturamento NNE'!$Q$2:$Q$707,'Faturamento NNE'!$E$2:$E$707,'Infos Relatório'!$B$2,'Faturamento NNE'!$F$2:$F$707,'Infos Relatório'!$B5,'Faturamento NNE'!$AA$2:$AA$707,'Infos Relatório'!BE$1,'Faturamento NNE'!$U$2:$U$707,"Sim") -> 0 | BI5: =BH5/BG5 -> #DIV/0! | BJ5: =SUMIFS('Faturamento NNE'!$I$2:$I$707,'Faturamento NNE'!$E$2:$E$707,'Infos Relatório'!$B$2,'Faturamento NNE'!$F$2:$F$707,'Infos Relatório'!$B5,'Faturamento NNE'!$AA$2:$AA$707,'Infos Relatório'!BE$1) -> 0 | BK5: =COUNTIFS('Faturamento NNE'!$E$2:$E$707,'Infos Relatório'!$B$2,'Faturamento NNE'!$F$2:$F$707,'Infos Relatório'!$B5,'Faturamento NNE'!$AA$2:$AA$707,'Infos Relatório'!BK$1) -> 0 | BL5: =SUMIFS('Faturamento NNE'!$H$2:$H$707,'Faturamento NNE'!$E$2:$E$707,'Infos Relatório'!$B$2,'Faturamento NNE'!$F$2:$F$707,'Infos Relatório'!$B5,'Faturamento NNE'!$AA$2:$AA$707,'Infos Relatório'!BK$1) -> 0 | BM5: =SUMIFS('Faturamento NNE'!$K$2:$K$707,'Faturamento NNE'!$E$2:$E$707,'Infos Relatório'!$B$2,'Faturamento NNE'!$F$2:$F$707,'Infos Relatório'!$B5,'Faturamento NNE'!$AA$2:$AA$707,'Infos Relatório'!BK$1) -> 0 | BN5: =SUMIFS('Faturamento NNE'!$P$2:$P$707,'Faturamento NNE'!$E$2:$E$707,'Infos Relatório'!$B$2,'Faturamento NNE'!$F$2:$F$707,'Infos Relatório'!$B5,'Faturamento NNE'!$AA$2:$AA$707,'Infos Relatório'!BK$1,'Faturamento NNE'!$U$2:$U$707,"Sim")+SUMIFS('Faturamento NNE'!$Q$2:$Q$707,'Faturamento NNE'!$E$2:$E$707,'Infos Relatório'!$B$2,'Faturamento NNE'!$F$2:$F$707,'Infos Relatório'!$B5,'Faturamento NNE'!$AA$2:$AA$707,'Infos Relatório'!BK$1,'Faturamento NNE'!$U$2:$U$707,"Sim") -> 0 | BO5: =BN5/BM5 -> #DIV/0! | BP5: =SUMIFS('Faturamento NNE'!$I$2:$I$707,'Faturamento NNE'!$E$2:$E$707,'Infos Relatório'!$B$2,'Faturamento NNE'!$F$2:$F$707,'Infos Relatório'!$B5,'Faturamento NNE'!$AA$2:$AA$707,'Infos Relatório'!BK$1) -> 0 | BQ5: =COUNTIFS('Faturamento NNE'!$E$2:$E$707,'Infos Relatório'!$B$2,'Faturamento NNE'!$F$2:$F$707,'Infos Relatório'!$B5,'Faturamento NNE'!$AA$2:$AA$707,'Infos Relatório'!BQ$1) -> 0 | BR5: =SUMIFS('Faturamento NNE'!$H$2:$H$707,'Faturamento NNE'!$E$2:$E$707,'Infos Relatório'!$B$2,'Faturamento NNE'!$F$2:$F$707,'Infos Relatório'!$B5,'Faturamento NNE'!$AA$2:$AA$707,'Infos Relatório'!BQ$1) -> 0 | BS5: =SUMIFS('Faturamento NNE'!$K$2:$K$707,'Faturamento NNE'!$E$2:$E$707,'Infos Relatório'!$B$2,'Faturamento NNE'!$F$2:$F$707,'Infos Relatório'!$B5,'Faturamento NNE'!$AA$2:$AA$707,'Infos Relatório'!BQ$1) -> 0 | BT5: =SUMIFS('Faturamento NNE'!$P$2:$P$707,'Faturamento NNE'!$E$2:$E$707,'Infos Relatório'!$B$2,'Faturamento NNE'!$F$2:$F$707,'Infos Relatório'!$B5,'Faturamento NNE'!$AA$2:$AA$707,'Infos Relatório'!BQ$1,'Faturamento NNE'!$U$2:$U$707,"Sim")+SUMIFS('Faturamento NNE'!$Q$2:$Q$707,'Faturamento NNE'!$E$2:$E$707,'Infos Relatório'!$B$2,'Faturamento NNE'!$F$2:$F$707,'Infos Relatório'!$B5,'Faturamento NNE'!$AA$2:$AA$707,'Infos Relatório'!BQ$1,'Faturamento NNE'!$U$2:$U$707,"Sim") -> 0 | BU5: =BT5/BS5 -> #DIV/0! | BV5: =SUMIFS('Faturamento NNE'!$I$2:$I$707,'Faturamento NNE'!$E$2:$E$707,'Infos Relatório'!$B$2,'Faturamento NNE'!$F$2:$F$707,'Infos Relatório'!$B5,'Faturamento NNE'!$AA$2:$AA$707,'Infos Relatório'!BQ$1) -> 0
B6: AgroGarden | C6: =COUNTIFS('Faturamento NNE'!$E$2:$E$707,'Infos Relatório'!$B$2,'Faturamento NNE'!$F$2:$F$707,'Infos Relatório'!$B6,'Faturamento NNE'!$AA$2:$AA$707,'Infos Relatório'!C$1) -> 0 | D6: =SUMIFS('Faturamento NNE'!$H$2:$H$707,'Faturamento NNE'!$E$2:$E$707,'Infos Relatório'!$B$2,'Faturamento NNE'!$F$2:$F$707,'Infos Relatório'!$B6,'Faturamento NNE'!$AA$2:$AA$707,'Infos Relatório'!C$1) -> 0 | E6: =SUMIFS('Faturamento NNE'!$K$2:$K$707,'Faturamento NNE'!$E$2:$E$707,'Infos Relatório'!$B$2,'Faturamento NNE'!$F$2:$F$707,'Infos Relatório'!$B6,'Faturamento NNE'!$AA$2:$AA$707,'Infos Relatório'!C$1) -> 0 | F6: =SUMIFS('Faturamento NNE'!$P$2:$P$707,'Faturamento NNE'!$E$2:$E$707,'Infos Relatório'!$B$2,'Faturamento NNE'!$F$2:$F$707,'Infos Relatório'!$B6,'Faturamento NNE'!$AA$2:$AA$707,'Infos Relatório'!C$1,'Faturamento NNE'!$U$2:$U$707,"Sim")+SUMIFS('Faturamento NNE'!$Q$2:$Q$707,'Faturamento NNE'!$E$2:$E$707,'Infos Relatório'!$B$2,'Faturamento NNE'!$F$2:$F$707,'Infos Relatório'!$B6,'Faturamento NNE'!$AA$2:$AA$707,'Infos Relatório'!C$1,'Faturamento NNE'!$U$2:$U$707,"Sim") -> 0 | G6: =F6/E6 -> #DIV/0! | H6: =SUMIFS('Faturamento NNE'!$I$2:$I$707,'Faturamento NNE'!$E$2:$E$707,'Infos Relatório'!$B$2,'Faturamento NNE'!$F$2:$F$707,'Infos Relatório'!$B6,'Faturamento NNE'!$AA$2:$AA$707,'Infos Relatório'!C$1) -> 0 | I6: =COUNTIFS('Faturamento NNE'!$E$2:$E$707,'Infos Relatório'!$B$2,'Faturamento NNE'!$F$2:$F$707,'Infos Relatório'!$B6,'Faturamento NNE'!$AA$2:$AA$707,'Infos Relatório'!I$1) -> 0 | J6: =SUMIFS('Faturamento NNE'!$H$2:$H$707,'Faturamento NNE'!$E$2:$E$707,'Infos Relatório'!$B$2,'Faturamento NNE'!$F$2:$F$707,'Infos Relatório'!$B6,'Faturamento NNE'!$AA$2:$AA$707,'Infos Relatório'!I$1) -> 0 | K6: =SUMIFS('Faturamento NNE'!$K$2:$K$707,'Faturamento NNE'!$E$2:$E$707,'Infos Relatório'!$B$2,'Faturamento NNE'!$F$2:$F$707,'Infos Relatório'!$B6,'Faturamento NNE'!$AA$2:$AA$707,'Infos Relatório'!I$1) -> 0 | L6: =SUMIFS('Faturamento NNE'!$P$2:$P$707,'Faturamento NNE'!$E$2:$E$707,'Infos Relatório'!$B$2,'Faturamento NNE'!$F$2:$F$707,'Infos Relatório'!$B6,'Faturamento NNE'!$AA$2:$AA$707,'Infos Relatório'!I$1,'Faturamento NNE'!$U$2:$U$707,"Sim")+SUMIFS('Faturamento NNE'!$Q$2:$Q$707,'Faturamento NNE'!$E$2:$E$707,'Infos Relatório'!$B$2,'Faturamento NNE'!$F$2:$F$707,'Infos Relatório'!$B6,'Faturamento NNE'!$AA$2:$AA$707,'Infos Relatório'!I$1,'Faturamento NNE'!$U$2:$U$707,"Sim") -> 0 | M6: =L6/K6 -> #DIV/0! | N6: =SUMIFS('Faturamento NNE'!$I$2:$I$707,'Faturamento NNE'!$E$2:$E$707,'Infos Relatório'!$B$2,'Faturamento NNE'!$F$2:$F$707,'Infos Relatório'!$B6,'Faturamento NNE'!$AA$2:$AA$707,'Infos Relatório'!I$1) -> 0 | O6: =COUNTIFS('Faturamento NNE'!$E$2:$E$707,'Infos Relatório'!$B$2,'Faturamento NNE'!$F$2:$F$707,'Infos Relatório'!$B6,'Faturamento NNE'!$AA$2:$AA$707,'Infos Relatório'!O$1) -> 0 | P6: =SUMIFS('Faturamento NNE'!$H$2:$H$707,'Faturamento NNE'!$E$2:$E$707,'Infos Relatório'!$B$2,'Faturamento NNE'!$F$2:$F$707,'Infos Relatório'!$B6,'Faturamento NNE'!$AA$2:$AA$707,'Infos Relatório'!O$1) -> 0 | Q6: =SUMIFS('Faturamento NNE'!$K$2:$K$707,'Faturamento NNE'!$E$2:$E$707,'Infos Relatório'!$B$2,'Faturamento NNE'!$F$2:$F$707,'Infos Relatório'!$B6,'Faturamento NNE'!$AA$2:$AA$707,'Infos Relatório'!O$1) -> 0 | R6: =SUMIFS('Faturamento NNE'!$P$2:$P$707,'Faturamento NNE'!$E$2:$E$707,'Infos Relatório'!$B$2,'Faturamento NNE'!$F$2:$F$707,'Infos Relatório'!$B6,'Faturamento NNE'!$AA$2:$AA$707,'Infos Relatório'!O$1,'Faturamento NNE'!$U$2:$U$707,"Sim")+SUMIFS('Faturamento NNE'!$Q$2:$Q$707,'Faturamento NNE'!$E$2:$E$707,'Infos Relatório'!$B$2,'Faturamento NNE'!$F$2:$F$707,'Infos Relatório'!$B6,'Faturamento NNE'!$AA$2:$AA$707,'Infos Relatório'!O$1,'Faturamento NNE'!$U$2:$U$707,"Sim") -> 0 | S6: =R6/Q6 -> #DIV/0! | T6: =SUMIFS('Faturamento NNE'!$I$2:$I$707,'Faturamento NNE'!$E$2:$E$707,'Infos Relatório'!$B$2,'Faturamento NNE'!$F$2:$F$707,'Infos Relatório'!$B6,'Faturamento NNE'!$AA$2:$AA$707,'Infos Relatório'!O$1) -> 0 | U6: =COUNTIFS('Faturamento NNE'!$E$2:$E$707,'Infos Relatório'!$B$2,'Faturamento NNE'!$F$2:$F$707,'Infos Relatório'!$B6,'Faturamento NNE'!$AA$2:$AA$707,'Infos Relatório'!U$1) -> 0 | V6: =SUMIFS('Faturamento NNE'!$H$2:$H$707,'Faturamento NNE'!$E$2:$E$707,'Infos Relatório'!$B$2,'Faturamento NNE'!$F$2:$F$707,'Infos Relatório'!$B6,'Faturamento NNE'!$AA$2:$AA$707,'Infos Relatório'!U$1) -> 0 | W6: =SUMIFS('Faturamento NNE'!$K$2:$K$707,'Faturamento NNE'!$E$2:$E$707,'Infos Relatório'!$B$2,'Faturamento NNE'!$F$2:$F$707,'Infos Relatório'!$B6,'Faturamento NNE'!$AA$2:$AA$707,'Infos Relatório'!U$1) -> 0 | X6: =SUMIFS('Faturamento NNE'!$P$2:$P$707,'Faturamento NNE'!$E$2:$E$707,'Infos Relatório'!$B$2,'Faturamento NNE'!$F$2:$F$707,'Infos Relatório'!$B6,'Faturamento NNE'!$AA$2:$AA$707,'Infos Relatório'!U$1,'Faturamento NNE'!$U$2:$U$707,"Sim")+SUMIFS('Faturamento NNE'!$Q$2:$Q$707,'Faturamento NNE'!$E$2:$E$707,'Infos Relatório'!$B$2,'Faturamento NNE'!$F$2:$F$707,'Infos Relatório'!$B6,'Faturamento NNE'!$AA$2:$AA$707,'Infos Relatório'!U$1,'Faturamento NNE'!$U$2:$U$707,"Sim") -> 0 | Y6: =X6/W6 -> #DIV/0! | Z6: =SUMIFS('Faturamento NNE'!$I$2:$I$707,'Faturamento NNE'!$E$2:$E$707,'Infos Relatório'!$B$2,'Faturamento NNE'!$F$2:$F$707,'Infos Relatório'!$B6,'Faturamento NNE'!$AA$2:$AA$707,'Infos Relatório'!U$1) -> 0 | AA6: =COUNTIFS('Faturamento NNE'!$E$2:$E$707,'Infos Relatório'!$B$2,'Faturamento NNE'!$F$2:$F$707,'Infos Relatório'!$B6,'Faturamento NNE'!$AA$2:$AA$707,'Infos Relatório'!AA$1) -> 0 | AB6: =SUMIFS('Faturamento NNE'!$H$2:$H$707,'Faturamento NNE'!$E$2:$E$707,'Infos Relatório'!$B$2,'Faturamento NNE'!$F$2:$F$707,'Infos Relatório'!$B6,'Faturamento NNE'!$AA$2:$AA$707,'Infos Relatório'!AA$1) -> 0 | AC6: =SUMIFS('Faturamento NNE'!$K$2:$K$707,'Faturamento NNE'!$E$2:$E$707,'Infos Relatório'!$B$2,'Faturamento NNE'!$F$2:$F$707,'Infos Relatório'!$B6,'Faturamento NNE'!$AA$2:$AA$707,'Infos Relatório'!AA$1) -> 0 | AD6: =SUMIFS('Faturamento NNE'!$P$2:$P$707,'Faturamento NNE'!$E$2:$E$707,'Infos Relatório'!$B$2,'Faturamento NNE'!$F$2:$F$707,'Infos Relatório'!$B6,'Faturamento NNE'!$AA$2:$AA$707,'Infos Relatório'!AA$1,'Faturamento NNE'!$U$2:$U$707,"Sim")+SUMIFS('Faturamento NNE'!$Q$2:$Q$707,'Faturamento NNE'!$E$2:$E$707,'Infos Relatório'!$B$2,'Faturamento NNE'!$F$2:$F$707,'Infos Relatório'!$B6,'Faturamento NNE'!$AA$2:$AA$707,'Infos Relatório'!AA$1,'Faturamento NNE'!$U$2:$U$707,"Sim") -> 0 | AE6: =AD6/AC6 -> #DIV/0! | AF6: =SUMIFS('Faturamento NNE'!$I$2:$I$707,'Faturamento NNE'!$E$2:$E$707,'Infos Relatório'!$B$2,'Faturamento NNE'!$F$2:$F$707,'Infos Relatório'!$B6,'Faturamento NNE'!$AA$2:$AA$707,'Infos Relatório'!AA$1) -> 0 | AG6: =COUNTIFS('Faturamento NNE'!$E$2:$E$707,'Infos Relatório'!$B$2,'Faturamento NNE'!$F$2:$F$707,'Infos Relatório'!$B6,'Faturamento NNE'!$AA$2:$AA$707,'Infos Relatório'!AG$1) -> 0 | AH6: =SUMIFS('Faturamento NNE'!$H$2:$H$707,'Faturamento NNE'!$E$2:$E$707,'Infos Relatório'!$B$2,'Faturamento NNE'!$F$2:$F$707,'Infos Relatório'!$B6,'Faturamento NNE'!$AA$2:$AA$707,'Infos Relatório'!AG$1) -> 0 | AI6: =SUMIFS('Faturamento NNE'!$K$2:$K$707,'Faturamento NNE'!$E$2:$E$707,'Infos Relatório'!$B$2,'Faturamento NNE'!$F$2:$F$707,'Infos Relatório'!$B6,'Faturamento NNE'!$AA$2:$AA$707,'Infos Relatório'!AG$1) -> 0 | AJ6: =SUMIFS('Faturamento NNE'!$P$2:$P$707,'Faturamento NNE'!$E$2:$E$707,'Infos Relatório'!$B$2,'Faturamento NNE'!$F$2:$F$707,'Infos Relatório'!$B6,'Faturamento NNE'!$AA$2:$AA$707,'Infos Relatório'!AG$1,'Faturamento NNE'!$U$2:$U$707,"Sim")+SUMIFS('Faturamento NNE'!$Q$2:$Q$707,'Faturamento NNE'!$E$2:$E$707,'Infos Relatório'!$B$2,'Faturamento NNE'!$F$2:$F$707,'Infos Relatório'!$B6,'Faturamento NNE'!$AA$2:$AA$707,'Infos Relatório'!AG$1,'Faturamento NNE'!$U$2:$U$707,"Sim") -> 0 | AK6: =AJ6/AI6 -> #DIV/0! | AL6: =SUMIFS('Faturamento NNE'!$I$2:$I$707,'Faturamento NNE'!$E$2:$E$707,'Infos Relatório'!$B$2,'Faturamento NNE'!$F$2:$F$707,'Infos Relatório'!$B6,'Faturamento NNE'!$AA$2:$AA$707,'Infos Relatório'!AG$1) -> 0 | AM6: =COUNTIFS('Faturamento NNE'!$E$2:$E$707,'Infos Relatório'!$B$2,'Faturamento NNE'!$F$2:$F$707,'Infos Relatório'!$B6,'Faturamento NNE'!$AA$2:$AA$707,'Infos Relatório'!AM$1) -> 0 | AN6: =SUMIFS('Faturamento NNE'!$H$2:$H$707,'Faturamento NNE'!$E$2:$E$707,'Infos Relatório'!$B$2,'Faturamento NNE'!$F$2:$F$707,'Infos Relatório'!$B6,'Faturamento NNE'!$AA$2:$AA$707,'Infos Relatório'!AM$1) -> 0 | AO6: =SUMIFS('Faturamento NNE'!$K$2:$K$707,'Faturamento NNE'!$E$2:$E$707,'Infos Relatório'!$B$2,'Faturamento NNE'!$F$2:$F$707,'Infos Relatório'!$B6,'Faturamento NNE'!$AA$2:$AA$707,'Infos Relatório'!AM$1) -> 0 | AP6: =SUMIFS('Faturamento NNE'!$P$2:$P$707,'Faturamento NNE'!$E$2:$E$707,'Infos Relatório'!$B$2,'Faturamento NNE'!$F$2:$F$707,'Infos Relatório'!$B6,'Faturamento NNE'!$AA$2:$AA$707,'Infos Relatório'!AM$1,'Faturamento NNE'!$U$2:$U$707,"Sim")+SUMIFS('Faturamento NNE'!$Q$2:$Q$707,'Faturamento NNE'!$E$2:$E$707,'Infos Relatório'!$B$2,'Faturamento NNE'!$F$2:$F$707,'Infos Relatório'!$B6,'Faturamento NNE'!$AA$2:$AA$707,'Infos Relatório'!AM$1,'Faturamento NNE'!$U$2:$U$707,"Sim") -> 0 | AQ6: =AP6/AO6 -> #DIV/0! | AR6: =SUMIFS('Faturamento NNE'!$I$2:$I$707,'Faturamento NNE'!$E$2:$E$707,'Infos Relatório'!$B$2,'Faturamento NNE'!$F$2:$F$707,'Infos Relatório'!$B6,'Faturamento NNE'!$AA$2:$AA$707,'Infos Relatório'!AM$1) -> 0 | AS6: =COUNTIFS('Faturamento NNE'!$E$2:$E$707,'Infos Relatório'!$B$2,'Faturamento NNE'!$F$2:$F$707,'Infos Relatório'!$B6,'Faturamento NNE'!$AA$2:$AA$707,'Infos Relatório'!AS$1) -> 0 | AT6: =SUMIFS('Faturamento NNE'!$H$2:$H$707,'Faturamento NNE'!$E$2:$E$707,'Infos Relatório'!$B$2,'Faturamento NNE'!$F$2:$F$707,'Infos Relatório'!$B6,'Faturamento NNE'!$AA$2:$AA$707,'Infos Relatório'!AS$1) -> 0 | AU6: =SUMIFS('Faturamento NNE'!$K$2:$K$707,'Faturamento NNE'!$E$2:$E$707,'Infos Relatório'!$B$2,'Faturamento NNE'!$F$2:$F$707,'Infos Relatório'!$B6,'Faturamento NNE'!$AA$2:$AA$707,'Infos Relatório'!AS$1) -> 0 | AV6: =SUMIFS('Faturamento NNE'!$P$2:$P$707,'Faturamento NNE'!$E$2:$E$707,'Infos Relatório'!$B$2,'Faturamento NNE'!$F$2:$F$707,'Infos Relatório'!$B6,'Faturamento NNE'!$AA$2:$AA$707,'Infos Relatório'!AS$1,'Faturamento NNE'!$U$2:$U$707,"Sim")+SUMIFS('Faturamento NNE'!$Q$2:$Q$707,'Faturamento NNE'!$E$2:$E$707,'Infos Relatório'!$B$2,'Faturamento NNE'!$F$2:$F$707,'Infos Relatório'!$B6,'Faturamento NNE'!$AA$2:$AA$707,'Infos Relatório'!AS$1,'Faturamento NNE'!$U$2:$U$707,"Sim") -> 0 | AW6: =AV6/AU6 -> #DIV/0! | AX6: =SUMIFS('Faturamento NNE'!$I$2:$I$707,'Faturamento NNE'!$E$2:$E$707,'Infos Relatório'!$B$2,'Faturamento NNE'!$F$2:$F$707,'Infos Relatório'!$B6,'Faturamento NNE'!$AA$2:$AA$707,'Infos Relatório'!AS$1) -> 0 | AY6: =COUNTIFS('Faturamento NNE'!$E$2:$E$707,'Infos Relatório'!$B$2,'Faturamento NNE'!$F$2:$F$707,'Infos Relatório'!$B6,'Faturamento NNE'!$AA$2:$AA$707,'Infos Relatório'!AY$1) -> 0 | AZ6: =SUMIFS('Faturamento NNE'!$H$2:$H$707,'Faturamento NNE'!$E$2:$E$707,'Infos Relatório'!$B$2,'Faturamento NNE'!$F$2:$F$707,'Infos Relatório'!$B6,'Faturamento NNE'!$AA$2:$AA$707,'Infos Relatório'!AY$1) -> 0 | BA6: =SUMIFS('Faturamento NNE'!$K$2:$K$707,'Faturamento NNE'!$E$2:$E$707,'Infos Relatório'!$B$2,'Faturamento NNE'!$F$2:$F$707,'Infos Relatório'!$B6,'Faturamento NNE'!$AA$2:$AA$707,'Infos Relatório'!AY$1) -> 0 | BB6: =SUMIFS('Faturamento NNE'!$P$2:$P$707,'Faturamento NNE'!$E$2:$E$707,'Infos Relatório'!$B$2,'Faturamento NNE'!$F$2:$F$707,'Infos Relatório'!$B6,'Faturamento NNE'!$AA$2:$AA$707,'Infos Relatório'!AY$1,'Faturamento NNE'!$U$2:$U$707,"Sim")+SUMIFS('Faturamento NNE'!$Q$2:$Q$707,'Faturamento NNE'!$E$2:$E$707,'Infos Relatório'!$B$2,'Faturamento NNE'!$F$2:$F$707,'Infos Relatório'!$B6,'Faturamento NNE'!$AA$2:$AA$707,'Infos Relatório'!AY$1,'Faturamento NNE'!$U$2:$U$707,"Sim") -> 0 | BC6: =BB6/BA6 -> #DIV/0! | BD6: =SUMIFS('Faturamento NNE'!$I$2:$I$707,'Faturamento NNE'!$E$2:$E$707,'Infos Relatório'!$B$2,'Faturamento NNE'!$F$2:$F$707,'Infos Relatório'!$B6,'Faturamento NNE'!$AA$2:$AA$707,'Infos Relatório'!AY$1) -> 0 | BE6: =COUNTIFS('Faturamento NNE'!$E$2:$E$707,'Infos Relatório'!$B$2,'Faturamento NNE'!$F$2:$F$707,'Infos Relatório'!$B6,'Faturamento NNE'!$AA$2:$AA$707,'Infos Relatório'!BE$1) -> 0 | BF6: =SUMIFS('Faturamento NNE'!$H$2:$H$707,'Faturamento NNE'!$E$2:$E$707,'Infos Relatório'!$B$2,'Faturamento NNE'!$F$2:$F$707,'Infos Relatório'!$B6,'Faturamento NNE'!$AA$2:$AA$707,'Infos Relatório'!BE$1) -> 0 | BG6: =SUMIFS('Faturamento NNE'!$K$2:$K$707,'Faturamento NNE'!$E$2:$E$707,'Infos Relatório'!$B$2,'Faturamento NNE'!$F$2:$F$707,'Infos Relatório'!$B6,'Faturamento NNE'!$AA$2:$AA$707,'Infos Relatório'!BE$1) -> 0 | BH6: =SUMIFS('Faturamento NNE'!$P$2:$P$707,'Faturamento NNE'!$E$2:$E$707,'Infos Relatório'!$B$2,'Faturamento NNE'!$F$2:$F$707,'Infos Relatório'!$B6,'Faturamento NNE'!$AA$2:$AA$707,'Infos Relatório'!BE$1,'Faturamento NNE'!$U$2:$U$707,"Sim")+SUMIFS('Faturamento NNE'!$Q$2:$Q$707,'Faturamento NNE'!$E$2:$E$707,'Infos Relatório'!$B$2,'Faturamento NNE'!$F$2:$F$707,'Infos Relatório'!$B6,'Faturamento NNE'!$AA$2:$AA$707,'Infos Relatório'!BE$1,'Faturamento NNE'!$U$2:$U$707,"Sim") -> 0 | BI6: =BH6/BG6 -> #DIV/0! | BJ6: =SUMIFS('Faturamento NNE'!$I$2:$I$707,'Faturamento NNE'!$E$2:$E$707,'Infos Relatório'!$B$2,'Faturamento NNE'!$F$2:$F$707,'Infos Relatório'!$B6,'Faturamento NNE'!$AA$2:$AA$707,'Infos Relatório'!BE$1) -> 0 | BK6: =COUNTIFS('Faturamento NNE'!$E$2:$E$707,'Infos Relatório'!$B$2,'Faturamento NNE'!$F$2:$F$707,'Infos Relatório'!$B6,'Faturamento NNE'!$AA$2:$AA$707,'Infos Relatório'!BK$1) -> 0 | BL6: =SUMIFS('Faturamento NNE'!$H$2:$H$707,'Faturamento NNE'!$E$2:$E$707,'Infos Relatório'!$B$2,'Faturamento NNE'!$F$2:$F$707,'Infos Relatório'!$B6,'Faturamento NNE'!$AA$2:$AA$707,'Infos Relatório'!BK$1) -> 0 | BM6: =SUMIFS('Faturamento NNE'!$K$2:$K$707,'Faturamento NNE'!$E$2:$E$707,'Infos Relatório'!$B$2,'Faturamento NNE'!$F$2:$F$707,'Infos Relatório'!$B6,'Faturamento NNE'!$AA$2:$AA$707,'Infos Relatório'!BK$1) -> 0 | BN6: =SUMIFS('Faturamento NNE'!$P$2:$P$707,'Faturamento NNE'!$E$2:$E$707,'Infos Relatório'!$B$2,'Faturamento NNE'!$F$2:$F$707,'Infos Relatório'!$B6,'Faturamento NNE'!$AA$2:$AA$707,'Infos Relatório'!BK$1,'Faturamento NNE'!$U$2:$U$707,"Sim")+SUMIFS('Faturamento NNE'!$Q$2:$Q$707,'Faturamento NNE'!$E$2:$E$707,'Infos Relatório'!$B$2,'Faturamento NNE'!$F$2:$F$707,'Infos Relatório'!$B6,'Faturamento NNE'!$AA$2:$AA$707,'Infos Relatório'!BK$1,'Faturamento NNE'!$U$2:$U$707,"Sim") -> 0 | BO6: =BN6/BM6 -> #DIV/0! | BP6: =SUMIFS('Faturamento NNE'!$I$2:$I$707,'Faturamento NNE'!$E$2:$E$707,'Infos Relatório'!$B$2,'Faturamento NNE'!$F$2:$F$707,'Infos Relatório'!$B6,'Faturamento NNE'!$AA$2:$AA$707,'Infos Relatório'!BK$1) -> 0 | BQ6: =COUNTIFS('Faturamento NNE'!$E$2:$E$707,'Infos Relatório'!$B$2,'Faturamento NNE'!$F$2:$F$707,'Infos Relatório'!$B6,'Faturamento NNE'!$AA$2:$AA$707,'Infos Relatório'!BQ$1) -> 0 | BR6: =SUMIFS('Faturamento NNE'!$H$2:$H$707,'Faturamento NNE'!$E$2:$E$707,'Infos Relatório'!$B$2,'Faturamento NNE'!$F$2:$F$707,'Infos Relatório'!$B6,'Faturamento NNE'!$AA$2:$AA$707,'Infos Relatório'!BQ$1) -> 0 | BS6: =SUMIFS('Faturamento NNE'!$K$2:$K$707,'Faturamento NNE'!$E$2:$E$707,'Infos Relatório'!$B$2,'Faturamento NNE'!$F$2:$F$707,'Infos Relatório'!$B6,'Faturamento NNE'!$AA$2:$AA$707,'Infos Relatório'!BQ$1) -> 0 | BT6: =SUMIFS('Faturamento NNE'!$P$2:$P$707,'Faturamento NNE'!$E$2:$E$707,'Infos Relatório'!$B$2,'Faturamento NNE'!$F$2:$F$707,'Infos Relatório'!$B6,'Faturamento NNE'!$AA$2:$AA$707,'Infos Relatório'!BQ$1,'Faturamento NNE'!$U$2:$U$707,"Sim")+SUMIFS('Faturamento NNE'!$Q$2:$Q$707,'Faturamento NNE'!$E$2:$E$707,'Infos Relatório'!$B$2,'Faturamento NNE'!$F$2:$F$707,'Infos Relatório'!$B6,'Faturamento NNE'!$AA$2:$AA$707,'Infos Relatório'!BQ$1,'Faturamento NNE'!$U$2:$U$707,"Sim") -> 0 | BU6: =BT6/BS6 -> #DIV/0! | BV6: =SUMIFS('Faturamento NNE'!$I$2:$I$707,'Faturamento NNE'!$E$2:$E$707,'Infos Relatório'!$B$2,'Faturamento NNE'!$F$2:$F$707,'Infos Relatório'!$B6,'Faturamento NNE'!$AA$2:$AA$707,'Infos Relatório'!BQ$1) -> 0
